INFO 2022-12-22 23:30:04,502 autoreload 677 Watching for file changes with StatReloader
INFO 2022-12-22 23:33:51,604 autoreload 266 D:\project\python\美多商城\web_app\meiduo_mall\meiduo_mall\urls.py changed, reloading.
INFO 2022-12-22 23:33:52,285 autoreload 677 Watching for file changes with StatReloader
INFO 2022-12-22 23:34:18,575 basehttp 187 "GET /log HTTP/1.1" 301 0
INFO 2022-12-22 23:34:18,585 basehttp 187 "GET /log/ HTTP/1.1" 200 3
WARNING 2022-12-22 23:34:18,691 log 241 Not Found: /favicon.ico
WARNING 2022-12-22 23:34:18,691 basehttp 187 "GET /favicon.ico HTTP/1.1" 404 2219
INFO 2022-12-22 23:38:35,231 autoreload 266 D:\project\python\美多商城\web_app\meiduo_mall\meiduo_mall\urls.py changed, reloading.
INFO 2022-12-22 23:38:36,263 autoreload 677 Watching for file changes with StatReloader
INFO 2022-12-22 23:39:01,944 urls 24 用户登陆了
WARNING 2022-12-22 23:39:01,945 urls 25 redis缓存不足
ERROR 2022-12-22 23:39:01,945 urls 26 该记录不存在
ERROR 2022-12-22 23:39:01,997 log 241 Internal Server Error: /log/
Traceback (most recent call last):
  File "C:\Users\alice\AppData\Local\Programs\Python\Python38\lib\site-packages\django\core\handlers\exception.py", line 55, in inner
    response = get_response(request)
  File "C:\Users\alice\AppData\Local\Programs\Python\Python38\lib\site-packages\django\core\handlers\base.py", line 204, in _get_response
    self.check_response(response, callback)
  File "C:\Users\alice\AppData\Local\Programs\Python\Python38\lib\site-packages\django\core\handlers\base.py", line 332, in check_response
    raise ValueError(
ValueError: The view meiduo_mall.urls.log didn't return an HttpResponse object. It returned None instead.
ERROR 2022-12-22 23:39:01,998 basehttp 187 "GET /log/ HTTP/1.1" 500 79984
INFO 2022-12-22 23:47:55,793 autoreload 266 D:\project\python\美多商城\web_app\meiduo_mall\meiduo_mall\settings.py changed, reloading.
INFO 2022-12-22 23:47:56,439 autoreload 677 Watching for file changes with StatReloader
INFO 2022-12-22 23:48:17,949 autoreload 677 Watching for file changes with StatReloader
INFO 2022-12-22 23:52:37,255 autoreload 677 Watching for file changes with StatReloader
INFO 2022-12-22 23:53:43,215 autoreload 266 D:\project\python\美多商城\web_app\meiduo_mall\meiduo_mall\settings.py changed, reloading.
INFO 2022-12-22 23:53:43,971 autoreload 677 Watching for file changes with StatReloader
INFO 2022-12-22 23:55:43,261 autoreload 266 D:\project\python\美多商城\web_app\meiduo_mall\meiduo_mall\settings.py changed, reloading.
INFO 2022-12-22 23:55:43,857 autoreload 677 Watching for file changes with StatReloader
INFO 2022-12-22 23:56:23,778 autoreload 677 Watching for file changes with StatReloader
INFO 2022-12-22 23:58:09,649 autoreload 266 D:\project\python\美多商城\web_app\meiduo_mall\apps\users\apps.py changed, reloading.
INFO 2022-12-22 23:58:10,291 autoreload 677 Watching for file changes with StatReloader
INFO 2022-12-23 00:00:29,698 autoreload 266 D:\project\python\美多商城\web_app\meiduo_mall\apps\users\apps.py changed, reloading.
INFO 2022-12-23 00:00:30,377 autoreload 677 Watching for file changes with StatReloader
INFO 2022-12-23 00:00:50,145 autoreload 266 D:\project\python\美多商城\web_app\meiduo_mall\apps\users\apps.py changed, reloading.
INFO 2022-12-23 00:00:50,819 autoreload 677 Watching for file changes with StatReloader
INFO 2022-12-23 00:01:02,247 autoreload 266 D:\project\python\美多商城\web_app\meiduo_mall\meiduo_mall\settings.py changed, reloading.
INFO 2022-12-23 00:01:02,795 autoreload 677 Watching for file changes with StatReloader
INFO 2022-12-23 00:01:14,424 autoreload 677 Watching for file changes with StatReloader
INFO 2022-12-23 00:01:26,913 autoreload 266 D:\project\python\美多商城\web_app\meiduo_mall\apps\users\apps.py changed, reloading.
INFO 2022-12-23 00:01:27,707 autoreload 677 Watching for file changes with StatReloader
INFO 2022-12-23 00:42:18,448 autoreload 266 D:\project\python\美多商城\web_app\meiduo_mall\apps\users\models.py changed, reloading.
INFO 2022-12-23 00:42:19,481 autoreload 677 Watching for file changes with StatReloader
INFO 2022-12-23 14:29:49,513 autoreload 677 Watching for file changes with StatReloader
INFO 2022-12-23 14:30:38,912 autoreload 677 Watching for file changes with StatReloader
WARNING 2022-12-23 15:26:56,252 log 241 Not Found: /
WARNING 2022-12-23 15:26:56,253 basehttp 187 "GET / HTTP/1.1" 404 2168
WARNING 2022-12-23 15:26:56,404 log 241 Not Found: /favicon.ico
WARNING 2022-12-23 15:26:56,404 basehttp 187 "GET /favicon.ico HTTP/1.1" 404 2219
INFO 2022-12-23 15:27:02,530 basehttp 187 "GET /admin HTTP/1.1" 301 0
INFO 2022-12-23 15:27:02,549 basehttp 187 "GET /admin/ HTTP/1.1" 302 0
INFO 2022-12-23 15:27:02,635 basehttp 187 "GET /admin/login/?next=/admin/ HTTP/1.1" 200 2218
INFO 2022-12-23 15:27:02,661 basehttp 187 "GET /static/admin/css/dark_mode.css HTTP/1.1" 200 796
INFO 2022-12-23 15:27:02,661 basehttp 187 "GET /static/admin/css/nav_sidebar.css HTTP/1.1" 200 2619
INFO 2022-12-23 15:27:02,661 basehttp 187 "GET /static/admin/css/base.css HTTP/1.1" 200 20344
INFO 2022-12-23 15:27:02,669 basehttp 187 "GET /static/admin/css/login.css HTTP/1.1" 200 958
INFO 2022-12-23 15:27:02,669 basehttp 187 "GET /static/admin/css/responsive.css HTTP/1.1" 200 18854
INFO 2022-12-23 15:27:02,707 basehttp 187 "GET /static/admin/css/fonts.css HTTP/1.1" 200 423
INFO 2022-12-23 15:27:02,713 basehttp 187 "GET /static/admin/js/nav_sidebar.js HTTP/1.1" 200 3763
INFO 2022-12-23 15:27:02,736 basehttp 187 "GET /static/admin/fonts/Roboto-Light-webfont.woff HTTP/1.1" 200 85692
INFO 2022-12-23 15:27:02,736 basehttp 187 "GET /static/admin/fonts/Roboto-Regular-webfont.woff HTTP/1.1" 200 85876
INFO 2022-12-23 15:28:10,671 basehttp 187 "POST /admin/login/?next=/admin/ HTTP/1.1" 200 2379
INFO 2022-12-23 15:28:10,753 basehttp 187 "GET /static/admin/fonts/Roboto-Bold-webfont.woff HTTP/1.1" 200 86184
INFO 2022-12-23 15:56:28,737 autoreload 677 Watching for file changes with StatReloader
WARNING 2022-12-23 15:56:55,730 log 241 Not Found: /
WARNING 2022-12-23 15:56:55,731 basehttp 187 "GET / HTTP/1.1" 404 2168
INFO 2022-12-23 15:58:41,837 autoreload 266 D:\project\python\美多商城\web_app\meiduo_mall\meiduo_mall\urls.py changed, reloading.
INFO 2022-12-23 15:58:41,841 autoreload 266 D:\project\python\美多商城\web_app\meiduo_mall\meiduo_mall\urls.py changed, reloading.
INFO 2022-12-23 15:58:42,583 autoreload 677 Watching for file changes with StatReloader
INFO 2022-12-23 15:58:42,614 autoreload 677 Watching for file changes with StatReloader
INFO 2022-12-23 16:01:59,783 basehttp 187 "GET /log HTTP/1.1" 301 0
INFO 2022-12-23 16:01:59,792 urls 24 用户登陆了
WARNING 2022-12-23 16:01:59,792 urls 25 redis缓存不足
ERROR 2022-12-23 16:01:59,793 urls 26 该记录不存在
ERROR 2022-12-23 16:01:59,839 log 241 Internal Server Error: /log/
Traceback (most recent call last):
  File "C:\Users\alice\AppData\Local\Programs\Python\Python38\lib\site-packages\django\core\handlers\exception.py", line 55, in inner
    response = get_response(request)
  File "C:\Users\alice\AppData\Local\Programs\Python\Python38\lib\site-packages\django\core\handlers\base.py", line 204, in _get_response
    self.check_response(response, callback)
  File "C:\Users\alice\AppData\Local\Programs\Python\Python38\lib\site-packages\django\core\handlers\base.py", line 332, in check_response
    raise ValueError(
ValueError: The view meiduo_mall.urls.log didn't return an HttpResponse object. It returned None instead.
ERROR 2022-12-23 16:01:59,841 basehttp 187 "GET /log/ HTTP/1.1" 500 87349
INFO 2022-12-23 16:02:10,914 basehttp 187 "GET /admin HTTP/1.1" 301 0
INFO 2022-12-23 16:02:10,925 basehttp 187 "GET /admin/ HTTP/1.1" 302 0
INFO 2022-12-23 16:02:10,946 basehttp 187 "GET /admin/login/?next=/admin/ HTTP/1.1" 200 2218
INFO 2022-12-23 16:02:11,015 basehttp 187 "GET /static/admin/css/fonts.css HTTP/1.1" 200 423
INFO 2022-12-23 16:02:11,015 basehttp 187 "GET /static/admin/js/nav_sidebar.js HTTP/1.1" 200 3763
INFO 2022-12-23 16:02:11,037 basehttp 187 "GET /static/admin/fonts/Roboto-Light-webfont.woff HTTP/1.1" 200 85692
INFO 2022-12-23 16:02:11,037 basehttp 187 "GET /static/admin/fonts/Roboto-Regular-webfont.woff HTTP/1.1" 200 85876
INFO 2022-12-23 16:04:30,790 basehttp 187 "GET /usernames/lkdc/count HTTP/1.1" 301 0
ERROR 2022-12-23 16:04:30,828 log 241 Internal Server Error: /usernames/lkdc/count/
Traceback (most recent call last):
  File "C:\Users\alice\AppData\Local\Programs\Python\Python38\lib\site-packages\django\core\handlers\exception.py", line 55, in inner
    response = get_response(request)
  File "C:\Users\alice\AppData\Local\Programs\Python\Python38\lib\site-packages\django\core\handlers\base.py", line 197, in _get_response
    response = wrapped_callback(request, *callback_args, **callback_kwargs)
  File "C:\Users\alice\AppData\Local\Programs\Python\Python38\lib\site-packages\django\views\generic\base.py", line 103, in view
    return self.dispatch(request, *args, **kwargs)
  File "C:\Users\alice\AppData\Local\Programs\Python\Python38\lib\site-packages\django\views\generic\base.py", line 142, in dispatch
    return handler(request, *args, **kwargs)
  File "D:\project\python\美多商城\web_app\meiduo_mall\apps\users\views.py", line 12, in get
    count=User.object.filter(username=username).count()
AttributeError: type object 'User' has no attribute 'object'
ERROR 2022-12-23 16:04:30,831 basehttp 187 "GET /usernames/lkdc/count/ HTTP/1.1" 500 95574
WARNING 2022-12-23 16:05:27,004 log 241 Not Found: /username/alice/count
WARNING 2022-12-23 16:05:27,005 basehttp 187 "GET /username/alice/count HTTP/1.1" 404 2426
INFO 2022-12-23 16:07:42,904 autoreload 266 D:\project\python\美多商城\web_app\meiduo_mall\apps\users\urls.py changed, reloading.
INFO 2022-12-23 16:07:43,316 autoreload 266 D:\project\python\美多商城\web_app\meiduo_mall\apps\users\urls.py changed, reloading.
INFO 2022-12-23 16:07:43,602 autoreload 677 Watching for file changes with StatReloader
INFO 2022-12-23 16:07:44,034 autoreload 677 Watching for file changes with StatReloader
INFO 2022-12-23 16:07:48,451 basehttp 187 "GET /username/alice/count HTTP/1.1" 301 0
ERROR 2022-12-23 16:07:48,487 log 241 Internal Server Error: /username/alice/count/
Traceback (most recent call last):
  File "C:\Users\alice\AppData\Local\Programs\Python\Python38\lib\site-packages\django\core\handlers\exception.py", line 55, in inner
    response = get_response(request)
  File "C:\Users\alice\AppData\Local\Programs\Python\Python38\lib\site-packages\django\core\handlers\base.py", line 197, in _get_response
    response = wrapped_callback(request, *callback_args, **callback_kwargs)
  File "C:\Users\alice\AppData\Local\Programs\Python\Python38\lib\site-packages\django\views\generic\base.py", line 103, in view
    return self.dispatch(request, *args, **kwargs)
  File "C:\Users\alice\AppData\Local\Programs\Python\Python38\lib\site-packages\django\views\generic\base.py", line 142, in dispatch
    return handler(request, *args, **kwargs)
  File "D:\project\python\美多商城\web_app\meiduo_mall\apps\users\views.py", line 12, in get
    count=User.object.filter(username=username).count()
AttributeError: type object 'User' has no attribute 'object'
ERROR 2022-12-23 16:07:48,490 basehttp 187 "GET /username/alice/count/ HTTP/1.1" 500 87325
INFO 2022-12-23 16:13:41,678 autoreload 266 D:\project\python\美多商城\web_app\meiduo_mall\apps\users\urls.py changed, reloading.
INFO 2022-12-23 16:13:41,741 autoreload 266 D:\project\python\美多商城\web_app\meiduo_mall\apps\users\urls.py changed, reloading.
INFO 2022-12-23 16:13:42,529 autoreload 677 Watching for file changes with StatReloader
INFO 2022-12-23 16:13:42,586 autoreload 677 Watching for file changes with StatReloader
INFO 2022-12-23 16:14:35,330 autoreload 677 Watching for file changes with StatReloader
INFO 2022-12-23 16:19:23,511 autoreload 266 D:\project\python\美多商城\web_app\meiduo_mall\apps\users\views.py changed, reloading.
INFO 2022-12-23 16:19:23,842 autoreload 266 D:\project\python\美多商城\web_app\meiduo_mall\apps\users\views.py changed, reloading.
INFO 2022-12-23 16:19:24,361 autoreload 677 Watching for file changes with StatReloader
INFO 2022-12-23 16:19:24,695 autoreload 677 Watching for file changes with StatReloader
INFO 2022-12-23 16:33:15,923 autoreload 266 D:\project\python\美多商城\web_app\meiduo_mall\apps\users\views.py changed, reloading.
INFO 2022-12-23 16:33:16,501 autoreload 266 D:\project\python\美多商城\web_app\meiduo_mall\apps\users\views.py changed, reloading.
INFO 2022-12-23 16:33:16,585 autoreload 677 Watching for file changes with StatReloader
INFO 2022-12-23 16:33:17,177 autoreload 677 Watching for file changes with StatReloader
INFO 2022-12-23 16:33:27,285 autoreload 266 D:\project\python\美多商城\web_app\meiduo_mall\apps\users\views.py changed, reloading.
INFO 2022-12-23 16:33:27,618 autoreload 266 D:\project\python\美多商城\web_app\meiduo_mall\apps\users\views.py changed, reloading.
INFO 2022-12-23 16:33:27,969 autoreload 677 Watching for file changes with StatReloader
INFO 2022-12-23 16:33:28,313 autoreload 677 Watching for file changes with StatReloader
INFO 2022-12-23 16:34:43,198 autoreload 677 Watching for file changes with StatReloader
INFO 2022-12-23 16:34:48,613 basehttp 187 "GET /users HTTP/1.1" 200 14
INFO 2022-12-23 16:35:25,462 autoreload 266 D:\project\python\美多商城\web_app\meiduo_mall\apps\users\urls.py changed, reloading.
INFO 2022-12-23 16:35:26,123 autoreload 677 Watching for file changes with StatReloader
INFO 2022-12-23 16:39:52,150 autoreload 677 Watching for file changes with StatReloader
INFO 2022-12-23 16:46:39,787 autoreload 677 Watching for file changes with StatReloader
INFO 2022-12-23 16:46:52,673 basehttp 187 "GET /usernames/alice/count HTTP/1.1" 301 0
INFO 2022-12-23 16:46:52,683 basehttp 187 "GET /usernames/alice/count/ HTTP/1.1" 200 39
INFO 2022-12-23 17:47:08,876 autoreload 266 D:\project\python\美多商城\web_app\meiduo_mall\meiduo_mall\settings.py changed, reloading.
INFO 2022-12-23 17:47:08,960 autoreload 266 D:\project\python\美多商城\web_app\meiduo_mall\meiduo_mall\settings.py changed, reloading.
INFO 2022-12-23 17:47:09,724 autoreload 677 Watching for file changes with StatReloader
INFO 2022-12-23 17:47:09,729 autoreload 677 Watching for file changes with StatReloader
INFO 2022-12-23 17:47:24,224 autoreload 677 Watching for file changes with StatReloader
INFO 2022-12-23 17:49:40,980 autoreload 266 D:\project\python\美多商城\web_app\meiduo_mall\apps\users\views.py changed, reloading.
INFO 2022-12-23 17:49:41,075 autoreload 266 D:\project\python\美多商城\web_app\meiduo_mall\apps\users\views.py changed, reloading.
INFO 2022-12-23 17:49:41,708 autoreload 677 Watching for file changes with StatReloader
INFO 2022-12-23 17:49:41,809 autoreload 677 Watching for file changes with StatReloader
INFO 2022-12-23 17:49:46,786 autoreload 677 Watching for file changes with StatReloader
INFO 2022-12-23 19:24:53,656 autoreload 677 Watching for file changes with StatReloader
INFO 2022-12-23 19:28:43,080 autoreload 266 D:\project\python\美多商城\web_app\meiduo_mall\apps\users\models.py changed, reloading.
INFO 2022-12-23 19:28:43,809 autoreload 677 Watching for file changes with StatReloader
INFO 2022-12-23 19:31:36,199 autoreload 266 D:\project\python\美多商城\web_app\meiduo_mall\apps\users\models.py changed, reloading.
INFO 2022-12-23 19:31:36,909 autoreload 677 Watching for file changes with StatReloader
INFO 2022-12-23 19:31:56,420 autoreload 266 D:\project\python\美多商城\web_app\meiduo_mall\apps\users\models.py changed, reloading.
INFO 2022-12-23 19:31:57,169 autoreload 677 Watching for file changes with StatReloader
INFO 2022-12-23 19:32:06,517 autoreload 266 D:\project\python\美多商城\web_app\meiduo_mall\apps\users\models.py changed, reloading.
INFO 2022-12-23 19:32:07,207 autoreload 677 Watching for file changes with StatReloader
INFO 2022-12-23 19:33:07,590 autoreload 266 D:\project\python\美多商城\web_app\meiduo_mall\apps\users\models.py changed, reloading.
INFO 2022-12-23 19:33:08,291 autoreload 677 Watching for file changes with StatReloader
INFO 2022-12-23 20:14:05,485 autoreload 677 Watching for file changes with StatReloader
INFO 2022-12-23 20:35:13,884 autoreload 266 D:\project\python\美多商城\web_app\meiduo_mall\meiduo_mall\settings.py changed, reloading.
INFO 2022-12-23 20:35:14,585 autoreload 677 Watching for file changes with StatReloader
INFO 2022-12-23 20:38:39,783 autoreload 266 D:\project\python\美多商城\web_app\meiduo_mall\meiduo_mall\settings.py changed, reloading.
INFO 2022-12-23 20:38:40,613 autoreload 677 Watching for file changes with StatReloader
INFO 2022-12-23 20:38:43,957 autoreload 266 D:\project\python\美多商城\web_app\meiduo_mall\meiduo_mall\settings.py changed, reloading.
INFO 2022-12-23 20:38:44,750 autoreload 677 Watching for file changes with StatReloader
INFO 2022-12-23 20:56:31,634 autoreload 677 Watching for file changes with StatReloader
INFO 2022-12-23 21:01:55,730 autoreload 266 D:\project\python\美多商城\web_app\meiduo_mall\meiduo_mall\settings.py changed, reloading.
INFO 2022-12-23 21:01:56,567 autoreload 677 Watching for file changes with StatReloader
INFO 2022-12-23 21:02:02,925 autoreload 266 D:\project\python\美多商城\web_app\meiduo_mall\meiduo_mall\settings.py changed, reloading.
INFO 2022-12-23 21:02:03,721 autoreload 677 Watching for file changes with StatReloader
INFO 2022-12-23 21:02:12,119 autoreload 266 D:\project\python\美多商城\web_app\meiduo_mall\meiduo_mall\settings.py changed, reloading.
INFO 2022-12-23 21:02:12,906 autoreload 677 Watching for file changes with StatReloader
INFO 2022-12-23 21:02:43,815 autoreload 677 Watching for file changes with StatReloader
INFO 2022-12-23 21:10:44,562 autoreload 266 D:\project\python\美多商城\web_app\meiduo_mall\apps\users\models.py changed, reloading.
INFO 2022-12-23 21:10:45,333 autoreload 677 Watching for file changes with StatReloader
INFO 2022-12-23 21:55:08,661 autoreload 266 D:\project\python\美多商城\web_app\meiduo_mall\apps\users\models.py changed, reloading.
INFO 2022-12-23 21:55:09,454 autoreload 677 Watching for file changes with StatReloader
INFO 2022-12-23 21:56:57,655 autoreload 266 D:\project\python\美多商城\web_app\meiduo_mall\apps\users\models.py changed, reloading.
INFO 2022-12-23 21:56:58,358 autoreload 677 Watching for file changes with StatReloader
INFO 2022-12-23 21:57:04,708 autoreload 266 D:\project\python\美多商城\web_app\meiduo_mall\apps\users\models.py changed, reloading.
INFO 2022-12-23 21:57:05,377 autoreload 677 Watching for file changes with StatReloader
INFO 2022-12-23 22:09:03,513 basehttp 187 "GET /usernames/alice/count HTTP/1.1" 301 0
INFO 2022-12-23 22:09:03,527 basehttp 187 "GET /usernames/alice/count/ HTTP/1.1" 200 39
ERROR 2022-12-23 22:09:27,701 exception 124 Invalid HTTP_HOST header: 'meiduo.site:8000'. You may need to add 'meiduo.site' to ALLOWED_HOSTS.
Traceback (most recent call last):
  File "C:\Users\alice\AppData\Local\Programs\Python\Python38\lib\site-packages\django\core\handlers\exception.py", line 55, in inner
    response = get_response(request)
  File "C:\Users\alice\AppData\Local\Programs\Python\Python38\lib\site-packages\django\utils\deprecation.py", line 135, in __call__
    response = self.process_request(request)
  File "C:\Users\alice\AppData\Local\Programs\Python\Python38\lib\site-packages\django\middleware\common.py", line 48, in process_request
    host = request.get_host()
  File "C:\Users\alice\AppData\Local\Programs\Python\Python38\lib\site-packages\django\http\request.py", line 148, in get_host
    raise DisallowedHost(msg)
django.core.exceptions.DisallowedHost: Invalid HTTP_HOST header: 'meiduo.site:8000'. You may need to add 'meiduo.site' to ALLOWED_HOSTS.
WARNING 2022-12-23 22:09:27,816 log 241 Bad Request: /usernames/alice/count
WARNING 2022-12-23 22:09:27,817 basehttp 187 "GET /usernames/alice/count HTTP/1.1" 400 83235
INFO 2022-12-23 22:12:20,677 autoreload 266 D:\project\python\美多商城\web_app\meiduo_mall\meiduo_mall\settings.py changed, reloading.
INFO 2022-12-23 22:12:21,364 autoreload 677 Watching for file changes with StatReloader
INFO 2022-12-23 22:12:50,229 autoreload 266 D:\project\python\美多商城\web_app\meiduo_mall\meiduo_mall\settings.py changed, reloading.
INFO 2022-12-23 22:12:50,890 autoreload 677 Watching for file changes with StatReloader
INFO 2022-12-23 22:14:01,581 autoreload 266 D:\project\python\美多商城\web_app\meiduo_mall\meiduo_mall\settings.py changed, reloading.
INFO 2022-12-23 22:14:02,304 autoreload 677 Watching for file changes with StatReloader
INFO 2022-12-23 22:15:33,463 autoreload 266 D:\project\python\美多商城\web_app\meiduo_mall\meiduo_mall\settings.py changed, reloading.
INFO 2022-12-23 22:15:34,142 autoreload 677 Watching for file changes with StatReloader
INFO 2022-12-23 22:16:21,971 basehttp 187 "GET /usernames/alice/count HTTP/1.1" 301 0
INFO 2022-12-23 22:16:21,982 basehttp 187 "GET /usernames/alice/count/ HTTP/1.1" 200 39
ERROR 2022-12-23 22:16:39,639 exception 124 Invalid HTTP_HOST header: 'meiduo.site:8000'. You may need to add 'meiduo.site' to ALLOWED_HOSTS.
Traceback (most recent call last):
  File "C:\Users\alice\AppData\Local\Programs\Python\Python38\lib\site-packages\django\core\handlers\exception.py", line 55, in inner
    response = get_response(request)
  File "C:\Users\alice\AppData\Local\Programs\Python\Python38\lib\site-packages\django\utils\deprecation.py", line 135, in __call__
    response = self.process_request(request)
  File "C:\Users\alice\AppData\Local\Programs\Python\Python38\lib\site-packages\django\middleware\common.py", line 48, in process_request
    host = request.get_host()
  File "C:\Users\alice\AppData\Local\Programs\Python\Python38\lib\site-packages\django\http\request.py", line 148, in get_host
    raise DisallowedHost(msg)
django.core.exceptions.DisallowedHost: Invalid HTTP_HOST header: 'meiduo.site:8000'. You may need to add 'meiduo.site' to ALLOWED_HOSTS.
WARNING 2022-12-23 22:16:39,673 log 241 Bad Request: /usernames/alice/count
WARNING 2022-12-23 22:16:39,674 basehttp 187 "GET /usernames/alice/count HTTP/1.1" 400 83956
INFO 2022-12-23 22:38:00,628 autoreload 677 Watching for file changes with StatReloader
ERROR 2022-12-23 22:38:42,935 exception 124 Invalid HTTP_HOST header: 'localhost:8000'. You may need to add 'localhost' to ALLOWED_HOSTS.
Traceback (most recent call last):
  File "C:\Users\alice\AppData\Local\Programs\Python\Python38\lib\site-packages\django\core\handlers\exception.py", line 55, in inner
    response = get_response(request)
  File "C:\Users\alice\AppData\Local\Programs\Python\Python38\lib\site-packages\django\utils\deprecation.py", line 135, in __call__
    response = self.process_request(request)
  File "C:\Users\alice\AppData\Local\Programs\Python\Python38\lib\site-packages\django\middleware\common.py", line 48, in process_request
    host = request.get_host()
  File "C:\Users\alice\AppData\Local\Programs\Python\Python38\lib\site-packages\django\http\request.py", line 148, in get_host
    raise DisallowedHost(msg)
django.core.exceptions.DisallowedHost: Invalid HTTP_HOST header: 'localhost:8000'. You may need to add 'localhost' to ALLOWED_HOSTS.
WARNING 2022-12-23 22:38:42,976 log 241 Bad Request: /register.html
WARNING 2022-12-23 22:38:42,977 basehttp 187 "GET /register.html HTTP/1.1" 400 92506
ERROR 2022-12-23 23:17:47,868 exception 124 Invalid HTTP_HOST header: 'meiduo.site:8000'. You may need to add 'meiduo.site' to ALLOWED_HOSTS.
Traceback (most recent call last):
  File "C:\Users\alice\AppData\Local\Programs\Python\Python38\lib\site-packages\django\core\handlers\exception.py", line 55, in inner
    response = get_response(request)
  File "C:\Users\alice\AppData\Local\Programs\Python\Python38\lib\site-packages\django\utils\deprecation.py", line 135, in __call__
    response = self.process_request(request)
  File "C:\Users\alice\AppData\Local\Programs\Python\Python38\lib\site-packages\django\middleware\common.py", line 48, in process_request
    host = request.get_host()
  File "C:\Users\alice\AppData\Local\Programs\Python\Python38\lib\site-packages\django\http\request.py", line 148, in get_host
    raise DisallowedHost(msg)
django.core.exceptions.DisallowedHost: Invalid HTTP_HOST header: 'meiduo.site:8000'. You may need to add 'meiduo.site' to ALLOWED_HOSTS.
WARNING 2022-12-23 23:17:47,890 log 241 Bad Request: /usernames/alice/count
WARNING 2022-12-23 23:17:47,891 basehttp 187 "GET /usernames/alice/count HTTP/1.1" 400 83956
INFO 2022-12-23 23:18:19,587 basehttp 187 "GET /usernames/alice/count HTTP/1.1" 301 0
INFO 2022-12-23 23:18:19,599 basehttp 187 "GET /usernames/alice/count/ HTTP/1.1" 200 39
ERROR 2022-12-23 23:18:37,218 exception 124 Invalid HTTP_HOST header: 'meiduo.site:8000'. You may need to add 'meiduo.site' to ALLOWED_HOSTS.
Traceback (most recent call last):
  File "C:\Users\alice\AppData\Local\Programs\Python\Python38\lib\site-packages\django\core\handlers\exception.py", line 55, in inner
    response = get_response(request)
  File "C:\Users\alice\AppData\Local\Programs\Python\Python38\lib\site-packages\django\utils\deprecation.py", line 135, in __call__
    response = self.process_request(request)
  File "C:\Users\alice\AppData\Local\Programs\Python\Python38\lib\site-packages\django\middleware\common.py", line 48, in process_request
    host = request.get_host()
  File "C:\Users\alice\AppData\Local\Programs\Python\Python38\lib\site-packages\django\http\request.py", line 148, in get_host
    raise DisallowedHost(msg)
django.core.exceptions.DisallowedHost: Invalid HTTP_HOST header: 'meiduo.site:8000'. You may need to add 'meiduo.site' to ALLOWED_HOSTS.
WARNING 2022-12-23 23:18:37,241 log 241 Bad Request: /usernames/alice/count
WARNING 2022-12-23 23:18:37,241 basehttp 187 "GET /usernames/alice/count HTTP/1.1" 400 83956
INFO 2022-12-23 23:19:48,140 autoreload 677 Watching for file changes with StatReloader
INFO 2022-12-24 22:46:33,121 autoreload 677 Watching for file changes with StatReloader
INFO 2022-12-24 22:47:52,697 autoreload 677 Watching for file changes with StatReloader
INFO 2022-12-25 12:41:57,073 autoreload 677 Watching for file changes with StatReloader
INFO 2022-12-25 13:08:15,867 autoreload 266 D:\project\python\美多商城\web_app\meiduo_mall\meiduo_mall\settings.py changed, reloading.
INFO 2022-12-25 13:08:16,701 autoreload 677 Watching for file changes with StatReloader
ERROR 2022-12-25 13:26:26,154 exception 124 Invalid HTTP_HOST header: 'localhost:8000'. You may need to add 'localhost' to ALLOWED_HOSTS.
Traceback (most recent call last):
  File "C:\Users\alice\AppData\Local\Programs\Python\Python38\lib\site-packages\django\core\handlers\exception.py", line 55, in inner
    response = get_response(request)
  File "C:\Users\alice\AppData\Local\Programs\Python\Python38\lib\site-packages\django\utils\deprecation.py", line 135, in __call__
    response = self.process_request(request)
  File "C:\Users\alice\AppData\Local\Programs\Python\Python38\lib\site-packages\django\middleware\common.py", line 48, in process_request
    host = request.get_host()
  File "C:\Users\alice\AppData\Local\Programs\Python\Python38\lib\site-packages\django\http\request.py", line 148, in get_host
    raise DisallowedHost(msg)
django.core.exceptions.DisallowedHost: Invalid HTTP_HOST header: 'localhost:8000'. You may need to add 'localhost' to ALLOWED_HOSTS.
WARNING 2022-12-25 13:26:26,280 log 241 Bad Request: /usernames/alice/count
WARNING 2022-12-25 13:26:26,281 basehttp 187 "GET /usernames/alice/count HTTP/1.1" 400 84295
INFO 2022-12-25 13:26:35,593 basehttp 187 "GET /usernames/alice/count HTTP/1.1" 301 0
INFO 2022-12-25 13:26:35,667 basehttp 187 "GET /usernames/alice/count/ HTTP/1.1" 200 39
INFO 2022-12-25 13:56:55,358 autoreload 266 D:\project\python\美多商城\web_app\meiduo_mall\meiduo_mall\settings.py changed, reloading.
INFO 2022-12-25 13:56:56,171 autoreload 677 Watching for file changes with StatReloader
INFO 2022-12-25 13:57:03,389 basehttp 187 "GET /usernames/alice/count HTTP/1.1" 301 0
INFO 2022-12-25 13:57:03,403 basehttp 187 "GET /usernames/alice/count/ HTTP/1.1" 200 39
INFO 2022-12-25 14:02:01,824 basehttp 187 "GET /usernames/alice/count HTTP/1.1" 301 0
INFO 2022-12-25 14:02:01,834 basehttp 187 "GET /usernames/alice/count/ HTTP/1.1" 200 39
INFO 2022-12-25 14:03:05,957 autoreload 677 Watching for file changes with StatReloader
INFO 2022-12-25 14:03:38,154 autoreload 266 D:\project\python\美多商城\web_app\meiduo_mall\meiduo_mall\settings.py changed, reloading.
INFO 2022-12-25 14:03:38,849 autoreload 677 Watching for file changes with StatReloader
WARNING 2022-12-25 14:06:38,145 log 241 Not Found: /ostusernames/alice/count
WARNING 2022-12-25 14:06:38,146 basehttp 187 "GET /ostusernames/alice/count HTTP/1.1" 404 2590
INFO 2022-12-25 14:06:49,608 basehttp 187 "GET /usernames/alice/count HTTP/1.1" 301 0
INFO 2022-12-25 14:06:49,620 basehttp 187 "GET /usernames/alice/count/ HTTP/1.1" 200 39
INFO 2022-12-25 14:07:04,870 basehttp 187 "GET /usernames/alice/count/ HTTP/1.1" 200 39
INFO 2022-12-25 14:09:09,246 basehttp 187 "GET /usernames/alice/count/ HTTP/1.1" 200 39
INFO 2022-12-25 14:09:11,814 basehttp 187 "GET /usernames/alice/count/ HTTP/1.1" 200 39
WARNING 2022-12-25 14:14:09,299 log 241 Not Found: /image_codes/800adea4-92e5-42f9-be7e-841a2c3ad916/
WARNING 2022-12-25 14:14:09,300 basehttp 187 "GET /image_codes/800adea4-92e5-42f9-be7e-841a2c3ad916/ HTTP/1.1" 404 2671
INFO 2022-12-25 14:41:53,006 autoreload 677 Watching for file changes with StatReloader
INFO 2022-12-25 14:42:38,443 autoreload 677 Watching for file changes with StatReloader
INFO 2022-12-25 14:44:05,792 autoreload 677 Watching for file changes with StatReloader
INFO 2022-12-25 14:46:04,909 autoreload 677 Watching for file changes with StatReloader
WARNING 2022-12-25 14:47:01,781 log 241 Not Found: /image_codes/e37c2ab6-fbd2-487c-b7e4-da5835061d92/
WARNING 2022-12-25 14:47:01,781 basehttp 187 "GET /image_codes/e37c2ab6-fbd2-487c-b7e4-da5835061d92/ HTTP/1.1" 404 2671
INFO 2022-12-25 14:54:14,544 basehttp 187 "GET /usernames/ll/count HTTP/1.1" 301 0
INFO 2022-12-25 14:54:14,552 basehttp 187 "GET /usernames/ll/count/ HTTP/1.1" 200 39
INFO 2022-12-25 14:57:30,757 basehttp 187 "GET /usernames/jj/count HTTP/1.1" 301 0
INFO 2022-12-25 14:57:30,767 basehttp 187 "GET /usernames/jj/count/ HTTP/1.1" 200 39
INFO 2022-12-25 14:59:09,351 basehttp 187 "GET /usernames/jj/count/ HTTP/1.1" 200 39
INFO 2022-12-25 15:00:23,398 autoreload 266 D:\project\python\美多商城\web_app\meiduo_mall\meiduo_mall\settings.py changed, reloading.
INFO 2022-12-25 15:00:24,179 autoreload 677 Watching for file changes with StatReloader
INFO 2022-12-25 15:34:31,593 basehttp 187 "GET /usernames/ll/count HTTP/1.1" 301 0
INFO 2022-12-25 15:34:31,604 basehttp 187 "GET /usernames/ll/count/ HTTP/1.1" 200 39
INFO 2022-12-25 15:34:44,114 basehttp 187 "GET /usernames/alice/count HTTP/1.1" 301 0
INFO 2022-12-25 15:34:44,119 basehttp 187 "GET /usernames/alice/count/ HTTP/1.1" 200 39
INFO 2022-12-25 16:00:07,576 basehttp 187 "GET /usernames/alice/count HTTP/1.1" 301 0
INFO 2022-12-25 16:00:07,581 basehttp 187 "GET /usernames/alice/count/ HTTP/1.1" 200 39
WARNING 2022-12-25 16:10:40,925 log 241 Not Found: /
WARNING 2022-12-25 16:10:40,925 basehttp 187 "GET / HTTP/1.1" 404 2502
WARNING 2022-12-25 16:10:40,959 log 241 Not Found: /favicon.ico
WARNING 2022-12-25 16:10:40,959 basehttp 187 "GET /favicon.ico HTTP/1.1" 404 2553
INFO 2022-12-25 17:01:09,974 autoreload 266 D:\project\python\美多商城\web_app\meiduo_mall\meiduo_mall\settings.py changed, reloading.
INFO 2022-12-25 17:01:10,771 autoreload 677 Watching for file changes with StatReloader
INFO 2022-12-25 17:07:09,378 autoreload 266 D:\project\python\美多商城\web_app\meiduo_mall\meiduo_mall\settings.py changed, reloading.
INFO 2022-12-25 17:07:10,058 autoreload 677 Watching for file changes with StatReloader
WARNING 2022-12-25 17:32:12,407 log 241 Not Found: /image_codes/f0ffdf04-700e-4520-8579-c814dedc1b78/
WARNING 2022-12-25 17:32:12,408 basehttp 187 "GET /image_codes/f0ffdf04-700e-4520-8579-c814dedc1b78/ HTTP/1.1" 404 2671
INFO 2022-12-25 17:32:21,063 basehttp 187 "GET /usernames/iiiii/count/ HTTP/1.1" 200 39
WARNING 2022-12-25 17:32:35,817 log 241 Not Found: /mobiles/18888888888/count/
WARNING 2022-12-25 17:32:35,817 basehttp 187 "GET /mobiles/18888888888/count/ HTTP/1.1" 404 2602
INFO 2022-12-25 17:32:44,473 basehttp 187 "GET /usernames/iiiii/count/ HTTP/1.1" 200 39
INFO 2022-12-25 17:32:44,473 basehttp 187 "OPTIONS /register/ HTTP/1.1" 200 0
WARNING 2022-12-25 17:32:44,475 log 241 Not Found: /mobiles/18888888888/count/
WARNING 2022-12-25 17:32:44,475 basehttp 187 "GET /mobiles/18888888888/count/ HTTP/1.1" 404 2602
WARNING 2022-12-25 17:32:44,485 log 241 Not Found: /register/
WARNING 2022-12-25 17:32:44,486 basehttp 187 "POST /register/ HTTP/1.1" 404 2552
WARNING 2022-12-25 18:04:59,751 log 241 Not Found: /image_codes/08f6c950-51f2-40b4-8401-088574220353/
WARNING 2022-12-25 18:04:59,752 basehttp 187 "GET /image_codes/08f6c950-51f2-40b4-8401-088574220353/ HTTP/1.1" 404 2671
INFO 2022-12-25 18:05:08,777 basehttp 187 "GET /usernames/rferer/count/ HTTP/1.1" 200 39
WARNING 2022-12-25 18:05:28,239 log 241 Not Found: /mobiles/15300000000/count/
WARNING 2022-12-25 18:05:28,239 basehttp 187 "GET /mobiles/15300000000/count/ HTTP/1.1" 404 2602
INFO 2022-12-25 18:05:36,797 basehttp 187 "OPTIONS /register/ HTTP/1.1" 200 0
INFO 2022-12-25 18:05:36,799 basehttp 187 "GET /usernames/rferer/count/ HTTP/1.1" 200 39
WARNING 2022-12-25 18:05:36,802 log 241 Not Found: /mobiles/15300000000/count/
WARNING 2022-12-25 18:05:36,802 basehttp 187 "GET /mobiles/15300000000/count/ HTTP/1.1" 404 2602
WARNING 2022-12-25 18:05:36,803 log 241 Not Found: /register/
WARNING 2022-12-25 18:05:36,803 basehttp 187 "POST /register/ HTTP/1.1" 404 2552
INFO 2022-12-25 18:06:15,228 basehttp 187 "GET /usernames/rferer/count/ HTTP/1.1" 200 39
INFO 2022-12-25 18:07:03,463 basehttp 187 "GET /usernames/kkkk/count HTTP/1.1" 301 0
INFO 2022-12-25 18:07:03,469 basehttp 187 "GET /usernames/kkkk/count/ HTTP/1.1" 200 39
WARNING 2022-12-25 18:07:03,571 log 241 Not Found: /favicon.ico
WARNING 2022-12-25 18:07:03,571 basehttp 187 "GET /favicon.ico HTTP/1.1" 404 2557
INFO 2022-12-25 20:25:04,750 autoreload 266 D:\project\python\美多商城\web_app\meiduo_mall\apps\users\views.py changed, reloading.
INFO 2022-12-25 20:25:05,581 autoreload 677 Watching for file changes with StatReloader
INFO 2022-12-25 20:25:22,305 autoreload 266 D:\project\python\美多商城\web_app\meiduo_mall\apps\users\views.py changed, reloading.
INFO 2022-12-25 20:25:23,036 autoreload 677 Watching for file changes with StatReloader
INFO 2022-12-25 20:25:34,624 autoreload 266 D:\project\python\美多商城\web_app\meiduo_mall\apps\users\urls.py changed, reloading.
INFO 2022-12-25 20:25:35,324 autoreload 677 Watching for file changes with StatReloader
INFO 2022-12-25 20:26:09,587 autoreload 266 D:\project\python\美多商城\web_app\meiduo_mall\apps\users\urls.py changed, reloading.
INFO 2022-12-25 20:26:10,321 autoreload 677 Watching for file changes with StatReloader
INFO 2022-12-25 20:29:06,081 autoreload 266 D:\project\python\美多商城\web_app\meiduo_mall\apps\users\views.py changed, reloading.
INFO 2022-12-25 20:29:06,841 autoreload 677 Watching for file changes with StatReloader
INFO 2022-12-25 20:29:21,552 autoreload 266 D:\project\python\美多商城\web_app\meiduo_mall\apps\users\views.py changed, reloading.
INFO 2022-12-25 20:29:22,463 autoreload 677 Watching for file changes with StatReloader
INFO 2022-12-25 20:29:28,931 autoreload 266 D:\project\python\美多商城\web_app\meiduo_mall\apps\users\views.py changed, reloading.
INFO 2022-12-25 20:29:29,676 autoreload 677 Watching for file changes with StatReloader
INFO 2022-12-25 20:30:37,027 autoreload 266 D:\project\python\美多商城\web_app\meiduo_mall\apps\users\views.py changed, reloading.
INFO 2022-12-25 20:30:37,788 autoreload 677 Watching for file changes with StatReloader
INFO 2022-12-25 20:34:32,321 autoreload 266 D:\project\python\美多商城\web_app\meiduo_mall\apps\users\views.py changed, reloading.
INFO 2022-12-25 20:34:33,087 autoreload 677 Watching for file changes with StatReloader
INFO 2022-12-25 20:40:08,022 autoreload 266 D:\project\python\美多商城\web_app\meiduo_mall\apps\users\urls.py changed, reloading.
INFO 2022-12-25 20:40:08,809 autoreload 677 Watching for file changes with StatReloader
INFO 2022-12-25 20:57:04,156 autoreload 266 D:\project\python\美多商城\web_app\meiduo_mall\apps\users\views.py changed, reloading.
INFO 2022-12-25 20:57:04,918 autoreload 677 Watching for file changes with StatReloader
INFO 2022-12-25 21:19:58,791 basehttp 187 "POST /register/ HTTP/1.1" 200 51
INFO 2022-12-25 21:22:39,001 autoreload 266 D:\project\python\美多商城\web_app\meiduo_mall\apps\users\views.py changed, reloading.
INFO 2022-12-25 21:22:39,785 autoreload 677 Watching for file changes with StatReloader
INFO 2022-12-25 21:23:06,244 basehttp 187 "POST /register/ HTTP/1.1" 200 51
ERROR 2022-12-25 21:23:13,513 log 241 Internal Server Error: /register/
Traceback (most recent call last):
  File "C:\Users\alice\AppData\Local\Programs\Python\Python38\lib\site-packages\django\core\handlers\exception.py", line 55, in inner
    response = get_response(request)
  File "C:\Users\alice\AppData\Local\Programs\Python\Python38\lib\site-packages\django\core\handlers\base.py", line 197, in _get_response
    response = wrapped_callback(request, *callback_args, **callback_kwargs)
  File "C:\Users\alice\AppData\Local\Programs\Python\Python38\lib\site-packages\django\views\generic\base.py", line 103, in view
    return self.dispatch(request, *args, **kwargs)
  File "C:\Users\alice\AppData\Local\Programs\Python\Python38\lib\site-packages\django\views\generic\base.py", line 142, in dispatch
    return handler(request, *args, **kwargs)
  File "D:\project\python\美多商城\web_app\meiduo_mall\apps\users\views.py", line 24, in post
    body_dict = json.loads(body_str)
  File "C:\Users\alice\AppData\Local\Programs\Python\Python38\lib\json\__init__.py", line 357, in loads
    return _default_decoder.decode(s)
  File "C:\Users\alice\AppData\Local\Programs\Python\Python38\lib\json\decoder.py", line 337, in decode
    obj, end = self.raw_decode(s, idx=_w(s, 0).end())
  File "C:\Users\alice\AppData\Local\Programs\Python\Python38\lib\json\decoder.py", line 353, in raw_decode
    obj, end = self.scan_once(s, idx)
json.decoder.JSONDecodeError: Expecting property name enclosed in double quotes: line 7 column 1 (char 133)
ERROR 2022-12-25 21:23:13,517 basehttp 187 "POST /register/ HTTP/1.1" 500 103032
INFO 2022-12-25 21:23:20,549 basehttp 187 "POST /register/ HTTP/1.1" 200 51
INFO 2022-12-25 21:24:16,936 autoreload 266 D:\project\python\美多商城\web_app\meiduo_mall\apps\users\views.py changed, reloading.
INFO 2022-12-25 21:24:17,766 autoreload 677 Watching for file changes with StatReloader
ERROR 2022-12-25 21:24:33,012 log 241 Internal Server Error: /register/
Traceback (most recent call last):
  File "C:\Users\alice\AppData\Local\Programs\Python\Python38\lib\site-packages\django\core\handlers\exception.py", line 55, in inner
    response = get_response(request)
  File "C:\Users\alice\AppData\Local\Programs\Python\Python38\lib\site-packages\django\core\handlers\base.py", line 197, in _get_response
    response = wrapped_callback(request, *callback_args, **callback_kwargs)
  File "C:\Users\alice\AppData\Local\Programs\Python\Python38\lib\site-packages\django\views\generic\base.py", line 103, in view
    return self.dispatch(request, *args, **kwargs)
  File "C:\Users\alice\AppData\Local\Programs\Python\Python38\lib\site-packages\django\views\generic\base.py", line 142, in dispatch
    return handler(request, *args, **kwargs)
  File "D:\project\python\美多商城\web_app\meiduo_mall\apps\users\views.py", line 37, in post
    if not re.match('[a-zA-Z_-]{5,20}'):
TypeError: match() missing 1 required positional argument: 'string'
ERROR 2022-12-25 21:24:33,015 basehttp 187 "POST /register/ HTTP/1.1" 500 91296
ERROR 2022-12-25 21:27:35,497 log 241 Internal Server Error: /register/
Traceback (most recent call last):
  File "C:\Users\alice\AppData\Local\Programs\Python\Python38\lib\site-packages\django\core\handlers\exception.py", line 55, in inner
    response = get_response(request)
  File "C:\Users\alice\AppData\Local\Programs\Python\Python38\lib\site-packages\django\core\handlers\base.py", line 197, in _get_response
    response = wrapped_callback(request, *callback_args, **callback_kwargs)
  File "C:\Users\alice\AppData\Local\Programs\Python\Python38\lib\site-packages\django\views\generic\base.py", line 103, in view
    return self.dispatch(request, *args, **kwargs)
  File "C:\Users\alice\AppData\Local\Programs\Python\Python38\lib\site-packages\django\views\generic\base.py", line 142, in dispatch
    return handler(request, *args, **kwargs)
  File "D:\project\python\美多商城\web_app\meiduo_mall\apps\users\views.py", line 37, in post
    if not re.match('[a-zA-Z_-]{5,20}'):
TypeError: match() missing 1 required positional argument: 'string'
ERROR 2022-12-25 21:27:35,500 basehttp 187 "POST /register/ HTTP/1.1" 500 91296
INFO 2022-12-25 21:28:49,190 autoreload 266 D:\project\python\美多商城\web_app\meiduo_mall\apps\users\views.py changed, reloading.
INFO 2022-12-25 21:28:50,071 autoreload 677 Watching for file changes with StatReloader
ERROR 2022-12-25 21:28:58,073 log 241 Internal Server Error: /register/
Traceback (most recent call last):
  File "C:\Users\alice\AppData\Local\Programs\Python\Python38\lib\site-packages\django\core\handlers\exception.py", line 55, in inner
    response = get_response(request)
  File "C:\Users\alice\AppData\Local\Programs\Python\Python38\lib\site-packages\django\core\handlers\base.py", line 197, in _get_response
    response = wrapped_callback(request, *callback_args, **callback_kwargs)
  File "C:\Users\alice\AppData\Local\Programs\Python\Python38\lib\site-packages\django\views\generic\base.py", line 103, in view
    return self.dispatch(request, *args, **kwargs)
  File "C:\Users\alice\AppData\Local\Programs\Python\Python38\lib\site-packages\django\views\generic\base.py", line 142, in dispatch
    return handler(request, *args, **kwargs)
  File "D:\project\python\美多商城\web_app\meiduo_mall\apps\users\views.py", line 37, in post
    if not re.match('[a-zA-Z_-]{5,20}'):
TypeError: match() missing 1 required positional argument: 'string'
ERROR 2022-12-25 21:28:58,076 basehttp 187 "POST /register/ HTTP/1.1" 500 91296
INFO 2022-12-25 21:33:50,673 autoreload 266 D:\project\python\美多商城\web_app\meiduo_mall\apps\users\views.py changed, reloading.
INFO 2022-12-25 21:33:51,565 autoreload 677 Watching for file changes with StatReloader
ERROR 2022-12-25 21:33:56,297 log 241 Internal Server Error: /register/
Traceback (most recent call last):
  File "C:\Users\alice\AppData\Local\Programs\Python\Python38\lib\site-packages\django\db\backends\utils.py", line 89, in _execute
    return self.cursor.execute(sql, params)
  File "C:\Users\alice\AppData\Local\Programs\Python\Python38\lib\site-packages\django\db\backends\mysql\base.py", line 75, in execute
    return self.cursor.execute(query, args)
  File "C:\Users\alice\AppData\Local\Programs\Python\Python38\lib\site-packages\MySQLdb\cursors.py", line 206, in execute
    res = self._query(query)
  File "C:\Users\alice\AppData\Local\Programs\Python\Python38\lib\site-packages\MySQLdb\cursors.py", line 319, in _query
    db.query(q)
  File "C:\Users\alice\AppData\Local\Programs\Python\Python38\lib\site-packages\MySQLdb\connections.py", line 254, in query
    _mysql.connection.query(self, query)
MySQLdb.IntegrityError: (1062, "Duplicate entry 'alice' for key 'username'")

The above exception was the direct cause of the following exception:

Traceback (most recent call last):
  File "C:\Users\alice\AppData\Local\Programs\Python\Python38\lib\site-packages\django\core\handlers\exception.py", line 55, in inner
    response = get_response(request)
  File "C:\Users\alice\AppData\Local\Programs\Python\Python38\lib\site-packages\django\core\handlers\base.py", line 197, in _get_response
    response = wrapped_callback(request, *callback_args, **callback_kwargs)
  File "C:\Users\alice\AppData\Local\Programs\Python\Python38\lib\site-packages\django\views\generic\base.py", line 103, in view
    return self.dispatch(request, *args, **kwargs)
  File "C:\Users\alice\AppData\Local\Programs\Python\Python38\lib\site-packages\django\views\generic\base.py", line 142, in dispatch
    return handler(request, *args, **kwargs)
  File "D:\project\python\美多商城\web_app\meiduo_mall\apps\users\views.py", line 43, in post
    User.objects.create(username=username,password=password,mobile=mobile)
  File "C:\Users\alice\AppData\Local\Programs\Python\Python38\lib\site-packages\django\db\models\manager.py", line 85, in manager_method
    return getattr(self.get_queryset(), name)(*args, **kwargs)
  File "C:\Users\alice\AppData\Local\Programs\Python\Python38\lib\site-packages\django\db\models\query.py", line 671, in create
    obj.save(force_insert=True, using=self.db)
  File "C:\Users\alice\AppData\Local\Programs\Python\Python38\lib\site-packages\django\contrib\auth\base_user.py", line 68, in save
    super().save(*args, **kwargs)
  File "C:\Users\alice\AppData\Local\Programs\Python\Python38\lib\site-packages\django\db\models\base.py", line 812, in save
    self.save_base(
  File "C:\Users\alice\AppData\Local\Programs\Python\Python38\lib\site-packages\django\db\models\base.py", line 863, in save_base
    updated = self._save_table(
  File "C:\Users\alice\AppData\Local\Programs\Python\Python38\lib\site-packages\django\db\models\base.py", line 1006, in _save_table
    results = self._do_insert(
  File "C:\Users\alice\AppData\Local\Programs\Python\Python38\lib\site-packages\django\db\models\base.py", line 1047, in _do_insert
    return manager._insert(
  File "C:\Users\alice\AppData\Local\Programs\Python\Python38\lib\site-packages\django\db\models\manager.py", line 85, in manager_method
    return getattr(self.get_queryset(), name)(*args, **kwargs)
  File "C:\Users\alice\AppData\Local\Programs\Python\Python38\lib\site-packages\django\db\models\query.py", line 1791, in _insert
    return query.get_compiler(using=using).execute_sql(returning_fields)
  File "C:\Users\alice\AppData\Local\Programs\Python\Python38\lib\site-packages\django\db\models\sql\compiler.py", line 1660, in execute_sql
    cursor.execute(sql, params)
  File "C:\Users\alice\AppData\Local\Programs\Python\Python38\lib\site-packages\django\db\backends\utils.py", line 103, in execute
    return super().execute(sql, params)
  File "C:\Users\alice\AppData\Local\Programs\Python\Python38\lib\site-packages\django\db\backends\utils.py", line 67, in execute
    return self._execute_with_wrappers(
  File "C:\Users\alice\AppData\Local\Programs\Python\Python38\lib\site-packages\django\db\backends\utils.py", line 80, in _execute_with_wrappers
    return executor(sql, params, many, context)
  File "C:\Users\alice\AppData\Local\Programs\Python\Python38\lib\site-packages\django\db\backends\utils.py", line 89, in _execute
    return self.cursor.execute(sql, params)
  File "C:\Users\alice\AppData\Local\Programs\Python\Python38\lib\site-packages\django\db\utils.py", line 91, in __exit__
    raise dj_exc_value.with_traceback(traceback) from exc_value
  File "C:\Users\alice\AppData\Local\Programs\Python\Python38\lib\site-packages\django\db\backends\utils.py", line 89, in _execute
    return self.cursor.execute(sql, params)
  File "C:\Users\alice\AppData\Local\Programs\Python\Python38\lib\site-packages\django\db\backends\mysql\base.py", line 75, in execute
    return self.cursor.execute(query, args)
  File "C:\Users\alice\AppData\Local\Programs\Python\Python38\lib\site-packages\MySQLdb\cursors.py", line 206, in execute
    res = self._query(query)
  File "C:\Users\alice\AppData\Local\Programs\Python\Python38\lib\site-packages\MySQLdb\cursors.py", line 319, in _query
    db.query(q)
  File "C:\Users\alice\AppData\Local\Programs\Python\Python38\lib\site-packages\MySQLdb\connections.py", line 254, in query
    _mysql.connection.query(self, query)
django.db.utils.IntegrityError: (1062, "Duplicate entry 'alice' for key 'username'")
ERROR 2022-12-25 21:33:56,309 basehttp 187 "POST /register/ HTTP/1.1" 500 212173
ERROR 2022-12-25 21:34:19,821 log 241 Internal Server Error: /register/
Traceback (most recent call last):
  File "C:\Users\alice\AppData\Local\Programs\Python\Python38\lib\site-packages\django\db\backends\utils.py", line 89, in _execute
    return self.cursor.execute(sql, params)
  File "C:\Users\alice\AppData\Local\Programs\Python\Python38\lib\site-packages\django\db\backends\mysql\base.py", line 75, in execute
    return self.cursor.execute(query, args)
  File "C:\Users\alice\AppData\Local\Programs\Python\Python38\lib\site-packages\MySQLdb\cursors.py", line 206, in execute
    res = self._query(query)
  File "C:\Users\alice\AppData\Local\Programs\Python\Python38\lib\site-packages\MySQLdb\cursors.py", line 319, in _query
    db.query(q)
  File "C:\Users\alice\AppData\Local\Programs\Python\Python38\lib\site-packages\MySQLdb\connections.py", line 254, in query
    _mysql.connection.query(self, query)
MySQLdb.IntegrityError: (1062, "Duplicate entry '13312341234' for key 'mobile'")

The above exception was the direct cause of the following exception:

Traceback (most recent call last):
  File "C:\Users\alice\AppData\Local\Programs\Python\Python38\lib\site-packages\django\core\handlers\exception.py", line 55, in inner
    response = get_response(request)
  File "C:\Users\alice\AppData\Local\Programs\Python\Python38\lib\site-packages\django\core\handlers\base.py", line 197, in _get_response
    response = wrapped_callback(request, *callback_args, **callback_kwargs)
  File "C:\Users\alice\AppData\Local\Programs\Python\Python38\lib\site-packages\django\views\generic\base.py", line 103, in view
    return self.dispatch(request, *args, **kwargs)
  File "C:\Users\alice\AppData\Local\Programs\Python\Python38\lib\site-packages\django\views\generic\base.py", line 142, in dispatch
    return handler(request, *args, **kwargs)
  File "D:\project\python\美多商城\web_app\meiduo_mall\apps\users\views.py", line 41, in post
    user.save()
  File "C:\Users\alice\AppData\Local\Programs\Python\Python38\lib\site-packages\django\contrib\auth\base_user.py", line 68, in save
    super().save(*args, **kwargs)
  File "C:\Users\alice\AppData\Local\Programs\Python\Python38\lib\site-packages\django\db\models\base.py", line 812, in save
    self.save_base(
  File "C:\Users\alice\AppData\Local\Programs\Python\Python38\lib\site-packages\django\db\models\base.py", line 863, in save_base
    updated = self._save_table(
  File "C:\Users\alice\AppData\Local\Programs\Python\Python38\lib\site-packages\django\db\models\base.py", line 1006, in _save_table
    results = self._do_insert(
  File "C:\Users\alice\AppData\Local\Programs\Python\Python38\lib\site-packages\django\db\models\base.py", line 1047, in _do_insert
    return manager._insert(
  File "C:\Users\alice\AppData\Local\Programs\Python\Python38\lib\site-packages\django\db\models\manager.py", line 85, in manager_method
    return getattr(self.get_queryset(), name)(*args, **kwargs)
  File "C:\Users\alice\AppData\Local\Programs\Python\Python38\lib\site-packages\django\db\models\query.py", line 1791, in _insert
    return query.get_compiler(using=using).execute_sql(returning_fields)
  File "C:\Users\alice\AppData\Local\Programs\Python\Python38\lib\site-packages\django\db\models\sql\compiler.py", line 1660, in execute_sql
    cursor.execute(sql, params)
  File "C:\Users\alice\AppData\Local\Programs\Python\Python38\lib\site-packages\django\db\backends\utils.py", line 103, in execute
    return super().execute(sql, params)
  File "C:\Users\alice\AppData\Local\Programs\Python\Python38\lib\site-packages\django\db\backends\utils.py", line 67, in execute
    return self._execute_with_wrappers(
  File "C:\Users\alice\AppData\Local\Programs\Python\Python38\lib\site-packages\django\db\backends\utils.py", line 80, in _execute_with_wrappers
    return executor(sql, params, many, context)
  File "C:\Users\alice\AppData\Local\Programs\Python\Python38\lib\site-packages\django\db\backends\utils.py", line 89, in _execute
    return self.cursor.execute(sql, params)
  File "C:\Users\alice\AppData\Local\Programs\Python\Python38\lib\site-packages\django\db\utils.py", line 91, in __exit__
    raise dj_exc_value.with_traceback(traceback) from exc_value
  File "C:\Users\alice\AppData\Local\Programs\Python\Python38\lib\site-packages\django\db\backends\utils.py", line 89, in _execute
    return self.cursor.execute(sql, params)
  File "C:\Users\alice\AppData\Local\Programs\Python\Python38\lib\site-packages\django\db\backends\mysql\base.py", line 75, in execute
    return self.cursor.execute(query, args)
  File "C:\Users\alice\AppData\Local\Programs\Python\Python38\lib\site-packages\MySQLdb\cursors.py", line 206, in execute
    res = self._query(query)
  File "C:\Users\alice\AppData\Local\Programs\Python\Python38\lib\site-packages\MySQLdb\cursors.py", line 319, in _query
    db.query(q)
  File "C:\Users\alice\AppData\Local\Programs\Python\Python38\lib\site-packages\MySQLdb\connections.py", line 254, in query
    _mysql.connection.query(self, query)
django.db.utils.IntegrityError: (1062, "Duplicate entry '13312341234' for key 'mobile'")
ERROR 2022-12-25 21:34:19,829 basehttp 187 "POST /register/ HTTP/1.1" 500 204295
ERROR 2022-12-25 21:34:48,473 log 241 Internal Server Error: /register/
Traceback (most recent call last):
  File "C:\Users\alice\AppData\Local\Programs\Python\Python38\lib\site-packages\django\db\backends\utils.py", line 89, in _execute
    return self.cursor.execute(sql, params)
  File "C:\Users\alice\AppData\Local\Programs\Python\Python38\lib\site-packages\django\db\backends\mysql\base.py", line 75, in execute
    return self.cursor.execute(query, args)
  File "C:\Users\alice\AppData\Local\Programs\Python\Python38\lib\site-packages\MySQLdb\cursors.py", line 206, in execute
    res = self._query(query)
  File "C:\Users\alice\AppData\Local\Programs\Python\Python38\lib\site-packages\MySQLdb\cursors.py", line 319, in _query
    db.query(q)
  File "C:\Users\alice\AppData\Local\Programs\Python\Python38\lib\site-packages\MySQLdb\connections.py", line 254, in query
    _mysql.connection.query(self, query)
MySQLdb.IntegrityError: (1062, "Duplicate entry 'elithbath' for key 'username'")

The above exception was the direct cause of the following exception:

Traceback (most recent call last):
  File "C:\Users\alice\AppData\Local\Programs\Python\Python38\lib\site-packages\django\core\handlers\exception.py", line 55, in inner
    response = get_response(request)
  File "C:\Users\alice\AppData\Local\Programs\Python\Python38\lib\site-packages\django\core\handlers\base.py", line 197, in _get_response
    response = wrapped_callback(request, *callback_args, **callback_kwargs)
  File "C:\Users\alice\AppData\Local\Programs\Python\Python38\lib\site-packages\django\views\generic\base.py", line 103, in view
    return self.dispatch(request, *args, **kwargs)
  File "C:\Users\alice\AppData\Local\Programs\Python\Python38\lib\site-packages\django\views\generic\base.py", line 142, in dispatch
    return handler(request, *args, **kwargs)
  File "D:\project\python\美多商城\web_app\meiduo_mall\apps\users\views.py", line 43, in post
    User.objects.create(username=username,password=password,mobile=mobile)
  File "C:\Users\alice\AppData\Local\Programs\Python\Python38\lib\site-packages\django\db\models\manager.py", line 85, in manager_method
    return getattr(self.get_queryset(), name)(*args, **kwargs)
  File "C:\Users\alice\AppData\Local\Programs\Python\Python38\lib\site-packages\django\db\models\query.py", line 671, in create
    obj.save(force_insert=True, using=self.db)
  File "C:\Users\alice\AppData\Local\Programs\Python\Python38\lib\site-packages\django\contrib\auth\base_user.py", line 68, in save
    super().save(*args, **kwargs)
  File "C:\Users\alice\AppData\Local\Programs\Python\Python38\lib\site-packages\django\db\models\base.py", line 812, in save
    self.save_base(
  File "C:\Users\alice\AppData\Local\Programs\Python\Python38\lib\site-packages\django\db\models\base.py", line 863, in save_base
    updated = self._save_table(
  File "C:\Users\alice\AppData\Local\Programs\Python\Python38\lib\site-packages\django\db\models\base.py", line 1006, in _save_table
    results = self._do_insert(
  File "C:\Users\alice\AppData\Local\Programs\Python\Python38\lib\site-packages\django\db\models\base.py", line 1047, in _do_insert
    return manager._insert(
  File "C:\Users\alice\AppData\Local\Programs\Python\Python38\lib\site-packages\django\db\models\manager.py", line 85, in manager_method
    return getattr(self.get_queryset(), name)(*args, **kwargs)
  File "C:\Users\alice\AppData\Local\Programs\Python\Python38\lib\site-packages\django\db\models\query.py", line 1791, in _insert
    return query.get_compiler(using=using).execute_sql(returning_fields)
  File "C:\Users\alice\AppData\Local\Programs\Python\Python38\lib\site-packages\django\db\models\sql\compiler.py", line 1660, in execute_sql
    cursor.execute(sql, params)
  File "C:\Users\alice\AppData\Local\Programs\Python\Python38\lib\site-packages\django\db\backends\utils.py", line 103, in execute
    return super().execute(sql, params)
  File "C:\Users\alice\AppData\Local\Programs\Python\Python38\lib\site-packages\django\db\backends\utils.py", line 67, in execute
    return self._execute_with_wrappers(
  File "C:\Users\alice\AppData\Local\Programs\Python\Python38\lib\site-packages\django\db\backends\utils.py", line 80, in _execute_with_wrappers
    return executor(sql, params, many, context)
  File "C:\Users\alice\AppData\Local\Programs\Python\Python38\lib\site-packages\django\db\backends\utils.py", line 89, in _execute
    return self.cursor.execute(sql, params)
  File "C:\Users\alice\AppData\Local\Programs\Python\Python38\lib\site-packages\django\db\utils.py", line 91, in __exit__
    raise dj_exc_value.with_traceback(traceback) from exc_value
  File "C:\Users\alice\AppData\Local\Programs\Python\Python38\lib\site-packages\django\db\backends\utils.py", line 89, in _execute
    return self.cursor.execute(sql, params)
  File "C:\Users\alice\AppData\Local\Programs\Python\Python38\lib\site-packages\django\db\backends\mysql\base.py", line 75, in execute
    return self.cursor.execute(query, args)
  File "C:\Users\alice\AppData\Local\Programs\Python\Python38\lib\site-packages\MySQLdb\cursors.py", line 206, in execute
    res = self._query(query)
  File "C:\Users\alice\AppData\Local\Programs\Python\Python38\lib\site-packages\MySQLdb\cursors.py", line 319, in _query
    db.query(q)
  File "C:\Users\alice\AppData\Local\Programs\Python\Python38\lib\site-packages\MySQLdb\connections.py", line 254, in query
    _mysql.connection.query(self, query)
django.db.utils.IntegrityError: (1062, "Duplicate entry 'elithbath' for key 'username'")
ERROR 2022-12-25 21:34:48,481 basehttp 187 "POST /register/ HTTP/1.1" 500 212383
ERROR 2022-12-25 21:34:59,468 log 241 Internal Server Error: /register/
Traceback (most recent call last):
  File "C:\Users\alice\AppData\Local\Programs\Python\Python38\lib\site-packages\django\db\backends\utils.py", line 89, in _execute
    return self.cursor.execute(sql, params)
  File "C:\Users\alice\AppData\Local\Programs\Python\Python38\lib\site-packages\django\db\backends\mysql\base.py", line 75, in execute
    return self.cursor.execute(query, args)
  File "C:\Users\alice\AppData\Local\Programs\Python\Python38\lib\site-packages\MySQLdb\cursors.py", line 206, in execute
    res = self._query(query)
  File "C:\Users\alice\AppData\Local\Programs\Python\Python38\lib\site-packages\MySQLdb\cursors.py", line 319, in _query
    db.query(q)
  File "C:\Users\alice\AppData\Local\Programs\Python\Python38\lib\site-packages\MySQLdb\connections.py", line 254, in query
    _mysql.connection.query(self, query)
MySQLdb.IntegrityError: (1062, "Duplicate entry 'elithbat' for key 'username'")

The above exception was the direct cause of the following exception:

Traceback (most recent call last):
  File "C:\Users\alice\AppData\Local\Programs\Python\Python38\lib\site-packages\django\core\handlers\exception.py", line 55, in inner
    response = get_response(request)
  File "C:\Users\alice\AppData\Local\Programs\Python\Python38\lib\site-packages\django\core\handlers\base.py", line 197, in _get_response
    response = wrapped_callback(request, *callback_args, **callback_kwargs)
  File "C:\Users\alice\AppData\Local\Programs\Python\Python38\lib\site-packages\django\views\generic\base.py", line 103, in view
    return self.dispatch(request, *args, **kwargs)
  File "C:\Users\alice\AppData\Local\Programs\Python\Python38\lib\site-packages\django\views\generic\base.py", line 142, in dispatch
    return handler(request, *args, **kwargs)
  File "D:\project\python\美多商城\web_app\meiduo_mall\apps\users\views.py", line 43, in post
    User.objects.create(username=username,password=password,mobile=mobile)
  File "C:\Users\alice\AppData\Local\Programs\Python\Python38\lib\site-packages\django\db\models\manager.py", line 85, in manager_method
    return getattr(self.get_queryset(), name)(*args, **kwargs)
  File "C:\Users\alice\AppData\Local\Programs\Python\Python38\lib\site-packages\django\db\models\query.py", line 671, in create
    obj.save(force_insert=True, using=self.db)
  File "C:\Users\alice\AppData\Local\Programs\Python\Python38\lib\site-packages\django\contrib\auth\base_user.py", line 68, in save
    super().save(*args, **kwargs)
  File "C:\Users\alice\AppData\Local\Programs\Python\Python38\lib\site-packages\django\db\models\base.py", line 812, in save
    self.save_base(
  File "C:\Users\alice\AppData\Local\Programs\Python\Python38\lib\site-packages\django\db\models\base.py", line 863, in save_base
    updated = self._save_table(
  File "C:\Users\alice\AppData\Local\Programs\Python\Python38\lib\site-packages\django\db\models\base.py", line 1006, in _save_table
    results = self._do_insert(
  File "C:\Users\alice\AppData\Local\Programs\Python\Python38\lib\site-packages\django\db\models\base.py", line 1047, in _do_insert
    return manager._insert(
  File "C:\Users\alice\AppData\Local\Programs\Python\Python38\lib\site-packages\django\db\models\manager.py", line 85, in manager_method
    return getattr(self.get_queryset(), name)(*args, **kwargs)
  File "C:\Users\alice\AppData\Local\Programs\Python\Python38\lib\site-packages\django\db\models\query.py", line 1791, in _insert
    return query.get_compiler(using=using).execute_sql(returning_fields)
  File "C:\Users\alice\AppData\Local\Programs\Python\Python38\lib\site-packages\django\db\models\sql\compiler.py", line 1660, in execute_sql
    cursor.execute(sql, params)
  File "C:\Users\alice\AppData\Local\Programs\Python\Python38\lib\site-packages\django\db\backends\utils.py", line 103, in execute
    return super().execute(sql, params)
  File "C:\Users\alice\AppData\Local\Programs\Python\Python38\lib\site-packages\django\db\backends\utils.py", line 67, in execute
    return self._execute_with_wrappers(
  File "C:\Users\alice\AppData\Local\Programs\Python\Python38\lib\site-packages\django\db\backends\utils.py", line 80, in _execute_with_wrappers
    return executor(sql, params, many, context)
  File "C:\Users\alice\AppData\Local\Programs\Python\Python38\lib\site-packages\django\db\backends\utils.py", line 89, in _execute
    return self.cursor.execute(sql, params)
  File "C:\Users\alice\AppData\Local\Programs\Python\Python38\lib\site-packages\django\db\utils.py", line 91, in __exit__
    raise dj_exc_value.with_traceback(traceback) from exc_value
  File "C:\Users\alice\AppData\Local\Programs\Python\Python38\lib\site-packages\django\db\backends\utils.py", line 89, in _execute
    return self.cursor.execute(sql, params)
  File "C:\Users\alice\AppData\Local\Programs\Python\Python38\lib\site-packages\django\db\backends\mysql\base.py", line 75, in execute
    return self.cursor.execute(query, args)
  File "C:\Users\alice\AppData\Local\Programs\Python\Python38\lib\site-packages\MySQLdb\cursors.py", line 206, in execute
    res = self._query(query)
  File "C:\Users\alice\AppData\Local\Programs\Python\Python38\lib\site-packages\MySQLdb\cursors.py", line 319, in _query
    db.query(q)
  File "C:\Users\alice\AppData\Local\Programs\Python\Python38\lib\site-packages\MySQLdb\connections.py", line 254, in query
    _mysql.connection.query(self, query)
django.db.utils.IntegrityError: (1062, "Duplicate entry 'elithbat' for key 'username'")
ERROR 2022-12-25 21:34:59,475 basehttp 187 "POST /register/ HTTP/1.1" 500 212391
INFO 2022-12-25 21:35:36,262 autoreload 266 D:\project\python\美多商城\web_app\meiduo_mall\apps\users\views.py changed, reloading.
INFO 2022-12-25 21:35:37,166 autoreload 677 Watching for file changes with StatReloader
INFO 2022-12-25 21:35:50,160 basehttp 187 "POST /register/ HTTP/1.1" 200 27
INFO 2022-12-25 22:33:23,371 autoreload 677 Watching for file changes with StatReloader
INFO 2022-12-25 22:34:07,531 autoreload 677 Watching for file changes with StatReloader
INFO 2022-12-25 22:34:57,549 basehttp 187 "POST /register/ HTTP/1.1" 200 27
INFO 2022-12-25 22:43:56,313 basehttp 187 "POST /register/ HTTP/1.1" 200 27
INFO 2022-12-26 13:59:57,103 basehttp 187 "POST /register/ HTTP/1.1" 200 27
INFO 2022-12-26 14:03:38,026 autoreload 266 D:\project\python\美多商城\web_app\meiduo_mall\apps\users\views.py changed, reloading.
INFO 2022-12-26 14:03:38,841 autoreload 677 Watching for file changes with StatReloader
INFO 2022-12-26 14:04:35,677 basehttp 187 "POST /register/ HTTP/1.1" 200 27
WARNING 2022-12-26 14:11:32,528 log 241 Not Found: /carts/simple/
WARNING 2022-12-26 14:11:32,528 basehttp 187 "GET /carts/simple/ HTTP/1.1" 404 2567
WARNING 2022-12-26 14:11:40,473 log 241 Not Found: /image_codes/544a6629-c9df-40f8-8e90-c8e89d86db95/
WARNING 2022-12-26 14:11:40,474 basehttp 187 "GET /image_codes/544a6629-c9df-40f8-8e90-c8e89d86db95/ HTTP/1.1" 404 2675
INFO 2022-12-26 14:11:46,927 basehttp 187 "GET /usernames/hjnhi/count/ HTTP/1.1" 200 39
WARNING 2022-12-26 14:12:09,534 log 241 Not Found: /mobiles/14356567787/count/
WARNING 2022-12-26 14:12:09,535 basehttp 187 "GET /mobiles/14356567787/count/ HTTP/1.1" 404 2606
WARNING 2022-12-26 14:12:19,805 log 241 Not Found: /mobiles/14356567787/count/
INFO 2022-12-26 14:12:19,805 basehttp 187 "GET /usernames/hjnhi/count/ HTTP/1.1" 200 39
WARNING 2022-12-26 14:12:19,806 basehttp 187 "GET /mobiles/14356567787/count/ HTTP/1.1" 404 2606
INFO 2022-12-26 14:12:19,813 basehttp 187 "OPTIONS /register/ HTTP/1.1" 200 0
INFO 2022-12-26 14:17:30,313 autoreload 266 D:\project\python\美多商城\web_app\meiduo_mall\meiduo_mall\settings.py changed, reloading.
INFO 2022-12-26 14:17:31,053 autoreload 677 Watching for file changes with StatReloader
INFO 2022-12-26 14:17:45,969 basehttp 187 "GET /usernames/hjnhi/count/ HTTP/1.1" 200 39
WARNING 2022-12-26 14:17:45,973 log 241 Not Found: /mobiles/14356567787/count/
WARNING 2022-12-26 14:17:45,973 basehttp 187 "GET /mobiles/14356567787/count/ HTTP/1.1" 404 2606
INFO 2022-12-26 14:17:46,143 basehttp 187 "OPTIONS /register/ HTTP/1.1" 200 0
INFO 2022-12-26 14:17:56,674 basehttp 187 "OPTIONS /register/ HTTP/1.1" 200 0
INFO 2022-12-26 14:17:56,676 basehttp 187 "GET /usernames/hjnhi/count/ HTTP/1.1" 200 39
WARNING 2022-12-26 14:17:56,676 log 241 Not Found: /mobiles/14356567787/count/
WARNING 2022-12-26 14:17:56,677 basehttp 187 "GET /mobiles/14356567787/count/ HTTP/1.1" 404 2606
INFO 2022-12-26 14:17:58,060 basehttp 187 "OPTIONS /register/ HTTP/1.1" 200 0
INFO 2022-12-26 14:17:58,061 basehttp 187 "GET /usernames/hjnhi/count/ HTTP/1.1" 200 39
WARNING 2022-12-26 14:17:58,062 log 241 Not Found: /mobiles/14356567787/count/
WARNING 2022-12-26 14:17:58,063 basehttp 187 "GET /mobiles/14356567787/count/ HTTP/1.1" 404 2606
INFO 2022-12-26 14:17:59,188 basehttp 187 "OPTIONS /register/ HTTP/1.1" 200 0
INFO 2022-12-26 14:17:59,189 basehttp 187 "GET /usernames/hjnhi/count/ HTTP/1.1" 200 39
WARNING 2022-12-26 14:17:59,190 log 241 Not Found: /mobiles/14356567787/count/
WARNING 2022-12-26 14:17:59,190 basehttp 187 "GET /mobiles/14356567787/count/ HTTP/1.1" 404 2606
INFO 2022-12-26 14:17:59,952 basehttp 187 "OPTIONS /register/ HTTP/1.1" 200 0
INFO 2022-12-26 14:17:59,953 basehttp 187 "GET /usernames/hjnhi/count/ HTTP/1.1" 200 39
WARNING 2022-12-26 14:17:59,954 log 241 Not Found: /mobiles/14356567787/count/
WARNING 2022-12-26 14:17:59,954 basehttp 187 "GET /mobiles/14356567787/count/ HTTP/1.1" 404 2606
INFO 2022-12-26 14:18:01,230 basehttp 187 "OPTIONS /register/ HTTP/1.1" 200 0
INFO 2022-12-26 14:18:01,231 basehttp 187 "GET /usernames/hjnhi/count/ HTTP/1.1" 200 39
WARNING 2022-12-26 14:18:01,232 log 241 Not Found: /mobiles/14356567787/count/
WARNING 2022-12-26 14:18:01,232 basehttp 187 "GET /mobiles/14356567787/count/ HTTP/1.1" 404 2606
INFO 2022-12-26 14:18:12,938 basehttp 187 "OPTIONS /register/ HTTP/1.1" 200 0
INFO 2022-12-26 14:18:12,939 basehttp 187 "GET /usernames/hjnhi/count/ HTTP/1.1" 200 39
WARNING 2022-12-26 14:18:12,940 log 241 Not Found: /mobiles/14356567787/count/
WARNING 2022-12-26 14:18:12,940 basehttp 187 "GET /mobiles/14356567787/count/ HTTP/1.1" 404 2606
WARNING 2022-12-26 14:29:50,839 log 241 Not Found: /mobiles/14356567787/count/
WARNING 2022-12-26 14:29:50,840 basehttp 187 "GET /mobiles/14356567787/count/ HTTP/1.1" 404 2606
INFO 2022-12-26 14:29:50,841 basehttp 187 "GET /usernames/hjnhi/count/ HTTP/1.1" 200 39
INFO 2022-12-26 14:29:50,845 basehttp 187 "OPTIONS /register/ HTTP/1.1" 200 0
INFO 2022-12-26 14:30:22,331 basehttp 187 "GET /usernames/hjnhi/count/ HTTP/1.1" 200 39
INFO 2022-12-26 14:39:15,940 autoreload 266 D:\project\python\美多商城\web_app\meiduo_mall\meiduo_mall\settings.py changed, reloading.
INFO 2022-12-26 14:39:16,694 autoreload 677 Watching for file changes with StatReloader
INFO 2022-12-26 14:39:22,115 autoreload 266 D:\project\python\美多商城\web_app\meiduo_mall\meiduo_mall\settings.py changed, reloading.
INFO 2022-12-26 14:39:22,859 autoreload 677 Watching for file changes with StatReloader
INFO 2022-12-26 14:44:54,303 autoreload 266 D:\project\python\美多商城\web_app\meiduo_mall\meiduo_mall\settings.py changed, reloading.
INFO 2022-12-26 14:44:55,121 autoreload 677 Watching for file changes with StatReloader
INFO 2022-12-26 14:45:01,864 basehttp 187 "GET /usernames/alice/count/ HTTP/1.1" 200 39
WARNING 2022-12-26 14:45:19,851 log 241 Not Found: /mobiles/15898989988/count/
WARNING 2022-12-26 14:45:19,851 basehttp 187 "GET /mobiles/15898989988/count/ HTTP/1.1" 404 2606
INFO 2022-12-26 14:45:28,105 basehttp 187 "GET /usernames/alice/count/ HTTP/1.1" 200 39
WARNING 2022-12-26 14:45:28,106 log 241 Not Found: /mobiles/15898989988/count/
WARNING 2022-12-26 14:45:28,107 basehttp 187 "GET /mobiles/15898989988/count/ HTTP/1.1" 404 2606
INFO 2022-12-26 14:45:28,116 basehttp 187 "OPTIONS /register/ HTTP/1.1" 200 0
INFO 2022-12-26 14:45:28,227 basehttp 187 "POST /register/ HTTP/1.1" 200 27
WARNING 2022-12-26 14:45:28,928 log 241 Not Found: /carts/simple/
WARNING 2022-12-26 14:45:28,929 basehttp 187 "GET /carts/simple/ HTTP/1.1" 404 2567
WARNING 2022-12-26 15:03:49,131 log 241 Not Found: /image_codes/9de8bc3f-0cb7-4728-8784-3f02d48f32e5/
WARNING 2022-12-26 15:03:49,132 basehttp 187 "GET /image_codes/9de8bc3f-0cb7-4728-8784-3f02d48f32e5/ HTTP/1.1" 404 2675
INFO 2022-12-26 15:03:56,341 basehttp 187 "GET /usernames/kkkkk/count/ HTTP/1.1" 200 39
WARNING 2022-12-26 15:04:11,497 log 241 Not Found: /mobiles/18888888888/count/
WARNING 2022-12-26 15:04:11,497 basehttp 187 "GET /mobiles/18888888888/count/ HTTP/1.1" 404 2606
INFO 2022-12-26 15:04:18,604 basehttp 187 "GET /usernames/kkkkk/count/ HTTP/1.1" 200 39
WARNING 2022-12-26 15:04:18,606 log 241 Not Found: /mobiles/18888888888/count/
WARNING 2022-12-26 15:04:18,607 basehttp 187 "GET /mobiles/18888888888/count/ HTTP/1.1" 404 2606
INFO 2022-12-26 15:04:18,712 basehttp 187 "POST /register/ HTTP/1.1" 200 27
WARNING 2022-12-26 15:04:18,915 log 241 Not Found: /carts/simple/
WARNING 2022-12-26 15:04:18,916 basehttp 187 "GET /carts/simple/ HTTP/1.1" 404 2567
WARNING 2022-12-26 15:13:38,508 log 241 Not Found: /image_codes/34b163d4-169d-4b31-b790-94f47a21ce7a/
WARNING 2022-12-26 15:13:38,509 basehttp 187 "GET /image_codes/34b163d4-169d-4b31-b790-94f47a21ce7a/ HTTP/1.1" 404 2675
INFO 2022-12-26 15:13:51,223 basehttp 187 "GET /usernames/llllll/count/ HTTP/1.1" 200 39
WARNING 2022-12-26 15:14:19,743 log 241 Not Found: /mobiles/19999999999/count/
WARNING 2022-12-26 15:14:19,744 basehttp 187 "GET /mobiles/19999999999/count/ HTTP/1.1" 404 2606
INFO 2022-12-26 15:14:26,055 basehttp 187 "OPTIONS /register/ HTTP/1.1" 200 0
INFO 2022-12-26 15:14:26,058 basehttp 187 "GET /usernames/llllll/count/ HTTP/1.1" 200 39
WARNING 2022-12-26 15:14:26,060 log 241 Not Found: /mobiles/19999999999/count/
WARNING 2022-12-26 15:14:26,060 basehttp 187 "GET /mobiles/19999999999/count/ HTTP/1.1" 404 2606
INFO 2022-12-26 15:14:26,172 basehttp 187 "POST /register/ HTTP/1.1" 200 27
WARNING 2022-12-26 15:14:26,328 log 241 Not Found: /carts/simple/
WARNING 2022-12-26 15:14:26,329 basehttp 187 "GET /carts/simple/ HTTP/1.1" 404 2567
WARNING 2022-12-26 15:46:42,247 log 241 Not Found: /list/173/skus/
WARNING 2022-12-26 15:46:42,248 log 241 Not Found: /carts/simple/
WARNING 2022-12-26 15:46:42,249 log 241 Not Found: /hot/173/
WARNING 2022-12-26 15:46:42,249 basehttp 187 "GET /list/173/skus/?page=1&page_size=5&ordering=-create_time HTTP/1.1" 404 2619
WARNING 2022-12-26 15:46:42,250 basehttp 187 "GET /carts/simple/ HTTP/1.1" 404 2567
WARNING 2022-12-26 15:46:42,250 basehttp 187 "GET /hot/173/ HTTP/1.1" 404 2552
INFO 2022-12-26 16:44:42,554 autoreload 266 D:\project\python\美多商城\web_app\meiduo_mall\meiduo_mall\settings.py changed, reloading.
INFO 2022-12-26 16:44:43,312 autoreload 677 Watching for file changes with StatReloader
INFO 2022-12-26 16:46:06,033 autoreload 637 Watching for file changes with StatReloader
INFO 2022-12-26 16:47:54,147 autoreload 637 Watching for file changes with StatReloader
INFO 2022-12-26 17:45:14,944 autoreload 251 D:\project\python\美多商城\web_app\meiduo_mall\meiduo_mall\settings.py changed, reloading.
INFO 2022-12-26 17:45:15,622 autoreload 637 Watching for file changes with StatReloader
INFO 2022-12-26 17:45:41,988 autoreload 637 Watching for file changes with StatReloader
INFO 2022-12-26 18:49:24,603 autoreload 251 D:\project\python\美多商城\web_app\meiduo_mall\meiduo_mall\settings.py changed, reloading.
INFO 2022-12-26 18:49:25,394 autoreload 637 Watching for file changes with StatReloader
INFO 2022-12-26 19:09:46,222 autoreload 251 D:\project\python\美多商城\web_app\meiduo_mall\meiduo_mall\urls.py changed, reloading.
INFO 2022-12-26 19:09:46,998 autoreload 637 Watching for file changes with StatReloader
INFO 2022-12-26 19:09:57,598 autoreload 251 D:\project\python\美多商城\web_app\meiduo_mall\meiduo_mall\urls.py changed, reloading.
INFO 2022-12-26 19:09:58,350 autoreload 637 Watching for file changes with StatReloader
INFO 2022-12-26 19:10:19,122 autoreload 251 D:\project\python\美多商城\web_app\meiduo_mall\apps\verifications\urls.py changed, reloading.
INFO 2022-12-26 19:10:19,946 autoreload 637 Watching for file changes with StatReloader
WARNING 2022-12-26 19:10:46,942 log 224 Not Found: /images/999
WARNING 2022-12-26 19:10:46,943 basehttp 161 "POST /images/999 HTTP/1.1" 404 2731
WARNING 2022-12-26 19:11:00,628 log 224 Not Found: /images/999
WARNING 2022-12-26 19:11:00,628 basehttp 161 "GET /images/999 HTTP/1.1" 404 2730
WARNING 2022-12-26 19:11:05,898 log 224 Not Found: /images/999
WARNING 2022-12-26 19:11:05,898 basehttp 161 "GET /images/999 HTTP/1.1" 404 2730
WARNING 2022-12-26 19:11:13,065 log 224 Not Found: /images/999
WARNING 2022-12-26 19:11:13,065 basehttp 161 "POST /images/999 HTTP/1.1" 404 2731
WARNING 2022-12-26 19:33:05,405 log 224 Not Found: /image_code/999
WARNING 2022-12-26 19:33:05,406 basehttp 161 "POST /image_code/999 HTTP/1.1" 404 2743
WARNING 2022-12-26 19:33:14,267 log 224 Not Found: /image_code/999
WARNING 2022-12-26 19:33:14,268 basehttp 161 "GET /image_code/999 HTTP/1.1" 404 2742
WARNING 2022-12-26 19:33:39,552 log 224 Not Found: /image_code/999
WARNING 2022-12-26 19:33:39,553 basehttp 161 "GET /image_code/999 HTTP/1.1" 404 2742
WARNING 2022-12-26 19:33:39,651 log 224 Not Found: /favicon.ico
WARNING 2022-12-26 19:33:39,652 basehttp 161 "GET /favicon.ico HTTP/1.1" 404 2733
INFO 2022-12-26 19:33:58,203 basehttp 161 "GET /image_codes/999 HTTP/1.1" 301 0
ERROR 2022-12-26 19:33:58,657 log 224 Internal Server Error: /image_codes/999/
Traceback (most recent call last):
  File "C:\Users\alice\AppData\Local\Programs\Python\Python38\lib\site-packages\django\core\handlers\exception.py", line 47, in inner
    response = get_response(request)
  File "C:\Users\alice\AppData\Local\Programs\Python\Python38\lib\site-packages\django\core\handlers\base.py", line 181, in _get_response
    response = wrapped_callback(request, *callback_args, **callback_kwargs)
  File "C:\Users\alice\AppData\Local\Programs\Python\Python38\lib\site-packages\django\views\generic\base.py", line 70, in view
    return self.dispatch(request, *args, **kwargs)
  File "C:\Users\alice\AppData\Local\Programs\Python\Python38\lib\site-packages\django\views\generic\base.py", line 98, in dispatch
    return handler(request, *args, **kwargs)
  File "D:\project\python\美多商城\web_app\meiduo_mall\apps\verifications\views.py", line 17, in get
    redis_cli.selex(uuid,100,text)
AttributeError: 'Redis' object has no attribute 'selex'
ERROR 2022-12-26 19:33:58,659 basehttp 161 "GET /image_codes/999/ HTTP/1.1" 500 95704
INFO 2022-12-26 19:35:03,427 autoreload 251 D:\project\python\美多商城\web_app\meiduo_mall\apps\verifications\views.py changed, reloading.
INFO 2022-12-26 19:35:04,253 autoreload 637 Watching for file changes with StatReloader
INFO 2022-12-26 19:35:15,514 basehttp 161 "GET /image_codes/999/ HTTP/1.1" 200 2875
INFO 2022-12-26 19:35:22,195 basehttp 161 "GET /image_codes/999/ HTTP/1.1" 200 3418
INFO 2022-12-26 19:35:23,390 basehttp 161 "GET /image_codes/999/ HTTP/1.1" 200 3545
INFO 2022-12-26 19:35:24,225 basehttp 161 "GET /image_codes/999/ HTTP/1.1" 200 3108
INFO 2022-12-26 19:35:25,047 basehttp 161 "GET /image_codes/999/ HTTP/1.1" 200 2943
WARNING 2022-12-26 19:35:51,118 log 224 Not Found: /register.html
WARNING 2022-12-26 19:35:51,119 basehttp 161 "GET /register.html HTTP/1.1" 404 2739
INFO 2022-12-26 19:36:00,401 basehttp 161 "GET /image_codes/16a9dc7c-aa03-4c3f-808a-774559abdec0/ HTTP/1.1" 200 3177
INFO 2022-12-26 19:55:22,999 basehttp 161 "GET /image_codes/3fad17e0-4832-4a0c-9b1a-f2bc7d7f9f44/ HTTP/1.1" 200 3212
INFO 2022-12-26 19:55:23,878 basehttp 161 "GET /image_codes/06f771c1-177a-4cfb-87c3-0e85f8761a6d/ HTTP/1.1" 200 2780
INFO 2022-12-26 19:55:24,659 basehttp 161 "GET /image_codes/f8aaf971-072e-4a8d-a736-35f292557160/ HTTP/1.1" 200 3225
INFO 2022-12-26 19:55:25,378 basehttp 161 "GET /image_codes/d8c9f1fd-6f91-4817-b151-2d789bd60d60/ HTTP/1.1" 200 3080
INFO 2022-12-26 19:55:26,113 basehttp 161 "GET /image_codes/61a10d69-58ff-45cf-a9ac-0be3cc4fa87c/ HTTP/1.1" 200 3334
INFO 2022-12-26 19:55:26,860 basehttp 161 "GET /image_codes/8db6f23b-de52-4479-96c4-2a782de3e906/ HTTP/1.1" 200 3298
INFO 2022-12-26 19:55:27,753 basehttp 161 "GET /image_codes/0679e2c8-f455-4414-9e53-2614847b6a0f/ HTTP/1.1" 200 3421
INFO 2022-12-26 21:21:28,908 basehttp 161 "GET /image_codes/999 HTTP/1.1" 301 0
INFO 2022-12-26 21:21:28,918 basehttp 161 "GET /image_codes/999/ HTTP/1.1" 200 3139
INFO 2022-12-26 21:21:35,897 basehttp 161 "GET /image_codes/999 HTTP/1.1" 301 0
INFO 2022-12-26 21:21:35,905 basehttp 161 "GET /image_codes/999/ HTTP/1.1" 200 3253
INFO 2022-12-26 21:21:37,477 basehttp 161 "GET /image_codes/999 HTTP/1.1" 301 0
INFO 2022-12-26 21:21:37,484 basehttp 161 "GET /image_codes/999/ HTTP/1.1" 200 3385
INFO 2022-12-26 21:21:39,042 basehttp 161 "GET /image_codes/999 HTTP/1.1" 301 0
INFO 2022-12-26 21:21:39,048 basehttp 161 "GET /image_codes/999/ HTTP/1.1" 200 3255
INFO 2022-12-26 21:21:40,386 basehttp 161 "GET /image_codes/999 HTTP/1.1" 301 0
INFO 2022-12-26 21:21:40,392 basehttp 161 "GET /image_codes/999/ HTTP/1.1" 200 3018
INFO 2022-12-26 21:21:41,679 basehttp 161 "GET /image_codes/999 HTTP/1.1" 301 0
INFO 2022-12-26 21:21:41,688 basehttp 161 "GET /image_codes/999/ HTTP/1.1" 200 3352
INFO 2022-12-26 21:21:43,037 basehttp 161 "GET /image_codes/999 HTTP/1.1" 301 0
INFO 2022-12-26 21:21:43,045 basehttp 161 "GET /image_codes/999/ HTTP/1.1" 200 3162
INFO 2022-12-26 21:21:44,324 basehttp 161 "GET /image_codes/999 HTTP/1.1" 301 0
INFO 2022-12-26 21:21:44,330 basehttp 161 "GET /image_codes/999/ HTTP/1.1" 200 2990
INFO 2022-12-26 21:21:46,203 basehttp 161 "GET /image_codes/999 HTTP/1.1" 301 0
INFO 2022-12-26 21:21:46,211 basehttp 161 "GET /image_codes/999/ HTTP/1.1" 200 3103
INFO 2022-12-26 21:21:47,427 basehttp 161 "GET /image_codes/999 HTTP/1.1" 301 0
INFO 2022-12-26 21:21:47,434 basehttp 161 "GET /image_codes/999/ HTTP/1.1" 200 3293
INFO 2022-12-26 21:21:48,515 basehttp 161 "GET /image_codes/999 HTTP/1.1" 301 0
INFO 2022-12-26 21:21:48,522 basehttp 161 "GET /image_codes/999/ HTTP/1.1" 200 3655
INFO 2022-12-26 21:21:49,524 basehttp 161 "GET /image_codes/999 HTTP/1.1" 301 0
INFO 2022-12-26 21:21:49,532 basehttp 161 "GET /image_codes/999/ HTTP/1.1" 200 3218
INFO 2022-12-26 21:40:03,685 basehttp 161 "GET /usernames/sssss/count/ HTTP/1.1" 200 39
WARNING 2022-12-26 21:40:32,554 log 224 Not Found: /mobiles/15360606636/count/
WARNING 2022-12-26 21:40:32,554 basehttp 161 "GET /mobiles/15360606636/count/ HTTP/1.1" 404 2778
WARNING 2022-12-26 21:40:33,544 log 224 Not Found: /mobiles/15360606636/count/
WARNING 2022-12-26 21:40:33,544 basehttp 161 "GET /mobiles/15360606636/count/ HTTP/1.1" 404 2778
WARNING 2022-12-26 21:40:45,115 log 224 Not Found: /mobiles/15360606636/count/
WARNING 2022-12-26 21:40:45,116 log 224 Not Found: /sms_codes/15360606636/
WARNING 2022-12-26 21:40:45,117 basehttp 161 "GET /mobiles/15360606636/count/ HTTP/1.1" 404 2778
WARNING 2022-12-26 21:40:45,117 basehttp 161 "GET /sms_codes/15360606636/?image_code=NH3A&image_code_id=0679e2c8-f455-4414-9e53-2614847b6a0f HTTP/1.1" 404 2837
INFO 2022-12-26 21:40:55,416 basehttp 161 "GET /image_codes/d818d165-48c9-4985-ae3d-fc01d49b559a/ HTTP/1.1" 200 3211
INFO 2022-12-26 21:41:15,704 basehttp 161 "GET /usernames/jjjjjj/count/ HTTP/1.1" 200 39
WARNING 2022-12-26 21:42:01,232 log 224 Not Found: /mobiles/15360606636/count/
WARNING 2022-12-26 21:42:01,232 basehttp 161 "GET /mobiles/15360606636/count/ HTTP/1.1" 404 2778
WARNING 2022-12-26 21:42:01,454 log 224 Not Found: /mobiles/15360606636/count/
WARNING 2022-12-26 21:42:01,455 log 224 Not Found: /sms_codes/15360606636/
WARNING 2022-12-26 21:42:01,455 basehttp 161 "GET /mobiles/15360606636/count/ HTTP/1.1" 404 2778
WARNING 2022-12-26 21:42:01,455 basehttp 161 "GET /sms_codes/15360606636/?image_code=QDMT&image_code_id=d818d165-48c9-4985-ae3d-fc01d49b559a HTTP/1.1" 404 2837
WARNING 2022-12-26 22:10:08,004 log 224 Not Found: /mobiles/15360606636/count/
WARNING 2022-12-26 22:10:08,005 log 224 Not Found: /sms_codes/15360606636/
WARNING 2022-12-26 22:10:08,005 basehttp 161 "GET /mobiles/15360606636/count/ HTTP/1.1" 404 2778
WARNING 2022-12-26 22:10:08,006 basehttp 161 "GET /sms_codes/15360606636/?image_code=QDMT&image_code_id=d818d165-48c9-4985-ae3d-fc01d49b559a HTTP/1.1" 404 2837
WARNING 2022-12-26 22:10:12,199 log 224 Not Found: /mobiles/15360606636/count/
WARNING 2022-12-26 22:10:12,200 log 224 Not Found: /sms_codes/15360606636/
WARNING 2022-12-26 22:10:12,201 basehttp 161 "GET /mobiles/15360606636/count/ HTTP/1.1" 404 2778
WARNING 2022-12-26 22:10:12,201 basehttp 161 "GET /sms_codes/15360606636/?image_code=QDMT&image_code_id=d818d165-48c9-4985-ae3d-fc01d49b559a HTTP/1.1" 404 2837
WARNING 2022-12-26 22:10:17,974 log 224 Not Found: /mobiles/15360606636/count/
WARNING 2022-12-26 22:10:17,975 log 224 Not Found: /sms_codes/15360606636/
WARNING 2022-12-26 22:10:17,975 basehttp 161 "GET /mobiles/15360606636/count/ HTTP/1.1" 404 2778
WARNING 2022-12-26 22:10:17,975 basehttp 161 "GET /sms_codes/15360606636/?image_code=QDMT&image_code_id=d818d165-48c9-4985-ae3d-fc01d49b559a HTTP/1.1" 404 2837
INFO 2022-12-26 22:32:27,272 autoreload 251 D:\project\python\美多商城\web_app\meiduo_mall\apps\verifications\views.py changed, reloading.
INFO 2022-12-26 22:32:27,999 autoreload 637 Watching for file changes with StatReloader
INFO 2022-12-26 22:33:00,217 autoreload 251 D:\project\python\美多商城\web_app\meiduo_mall\apps\verifications\views.py changed, reloading.
INFO 2022-12-26 22:33:00,923 autoreload 637 Watching for file changes with StatReloader
INFO 2022-12-26 23:11:29,177 autoreload 251 D:\project\python\美多商城\web_app\meiduo_mall\apps\verifications\urls.py changed, reloading.
INFO 2022-12-26 23:11:29,967 autoreload 637 Watching for file changes with StatReloader
INFO 2022-12-26 23:11:53,887 autoreload 251 D:\project\python\美多商城\web_app\meiduo_mall\apps\verifications\urls.py changed, reloading.
INFO 2022-12-26 23:11:54,646 autoreload 637 Watching for file changes with StatReloader
INFO 2022-12-26 23:22:18,954 autoreload 251 D:\project\python\美多商城\web_app\meiduo_mall\apps\verifications\views.py changed, reloading.
INFO 2022-12-26 23:22:19,720 autoreload 637 Watching for file changes with StatReloader
INFO 2022-12-26 23:23:01,149 basehttp 161 "GET /image_codes/ae7fd07c-8106-45d1-8167-d5398d67bdff/ HTTP/1.1" 200 3280
INFO 2022-12-26 23:23:07,295 basehttp 161 "GET /usernames/jjjjj/count/ HTTP/1.1" 200 39
WARNING 2022-12-26 23:23:36,801 log 224 Not Found: /mobiles/15360606636/count/
WARNING 2022-12-26 23:23:36,802 basehttp 161 "GET /mobiles/15360606636/count/ HTTP/1.1" 404 2950
WARNING 2022-12-26 23:23:50,824 log 224 Not Found: /mobiles/15360606636/count/
WARNING 2022-12-26 23:23:50,824 basehttp 161 "GET /mobiles/15360606636/count/ HTTP/1.1" 404 2950
ERROR 2022-12-26 23:23:50,863 log 224 Internal Server Error: /sms_codes/15360606636/
Traceback (most recent call last):
  File "C:\Users\alice\AppData\Local\Programs\Python\Python38\lib\site-packages\django\core\handlers\exception.py", line 47, in inner
    response = get_response(request)
  File "C:\Users\alice\AppData\Local\Programs\Python\Python38\lib\site-packages\django\core\handlers\base.py", line 181, in _get_response
    response = wrapped_callback(request, *callback_args, **callback_kwargs)
  File "C:\Users\alice\AppData\Local\Programs\Python\Python38\lib\site-packages\django\views\generic\base.py", line 70, in view
    return self.dispatch(request, *args, **kwargs)
  File "C:\Users\alice\AppData\Local\Programs\Python\Python38\lib\site-packages\django\views\generic\base.py", line 98, in dispatch
    return handler(request, *args, **kwargs)
  File "D:\project\python\美多商城\web_app\meiduo_mall\apps\verifications\views.py", line 25, in get
    image_code = request.Get.get('image_code')
AttributeError: 'WSGIRequest' object has no attribute 'Get'
ERROR 2022-12-26 23:23:50,866 basehttp 161 "GET /sms_codes/15360606636/?image_code=qujx&image_code_id=ae7fd07c-8106-45d1-8167-d5398d67bdff HTTP/1.1" 500 91546
INFO 2022-12-26 23:24:01,912 basehttp 161 "GET /image_codes/7f750dcd-ee21-4076-a970-b6726f3b044f/ HTTP/1.1" 200 3165
WARNING 2022-12-26 23:24:13,111 log 224 Not Found: /mobiles/15360606636/count/
WARNING 2022-12-26 23:24:13,112 basehttp 161 "GET /mobiles/15360606636/count/ HTTP/1.1" 404 2950
ERROR 2022-12-26 23:24:13,127 log 224 Internal Server Error: /sms_codes/15360606636/
Traceback (most recent call last):
  File "C:\Users\alice\AppData\Local\Programs\Python\Python38\lib\site-packages\django\core\handlers\exception.py", line 47, in inner
    response = get_response(request)
  File "C:\Users\alice\AppData\Local\Programs\Python\Python38\lib\site-packages\django\core\handlers\base.py", line 181, in _get_response
    response = wrapped_callback(request, *callback_args, **callback_kwargs)
  File "C:\Users\alice\AppData\Local\Programs\Python\Python38\lib\site-packages\django\views\generic\base.py", line 70, in view
    return self.dispatch(request, *args, **kwargs)
  File "C:\Users\alice\AppData\Local\Programs\Python\Python38\lib\site-packages\django\views\generic\base.py", line 98, in dispatch
    return handler(request, *args, **kwargs)
  File "D:\project\python\美多商城\web_app\meiduo_mall\apps\verifications\views.py", line 25, in get
    image_code = request.Get.get('image_code')
AttributeError: 'WSGIRequest' object has no attribute 'Get'
ERROR 2022-12-26 23:24:13,129 basehttp 161 "GET /sms_codes/15360606636/?image_code=tvnv&image_code_id=7f750dcd-ee21-4076-a970-b6726f3b044f HTTP/1.1" 500 91546
WARNING 2022-12-26 23:24:25,041 log 224 Not Found: /mobiles/15360606636/count/
WARNING 2022-12-26 23:24:25,041 basehttp 161 "GET /mobiles/15360606636/count/ HTTP/1.1" 404 2950
INFO 2022-12-26 23:31:12,725 autoreload 251 D:\project\python\美多商城\web_app\meiduo_mall\apps\verifications\views.py changed, reloading.
INFO 2022-12-26 23:31:13,484 autoreload 637 Watching for file changes with StatReloader
INFO 2022-12-26 23:31:25,093 autoreload 251 D:\project\python\美多商城\web_app\meiduo_mall\apps\verifications\views.py changed, reloading.
INFO 2022-12-26 23:31:25,843 autoreload 637 Watching for file changes with StatReloader
INFO 2022-12-26 23:36:06,650 autoreload 637 Watching for file changes with StatReloader
INFO 2022-12-27 19:30:06,512 autoreload 637 Watching for file changes with StatReloader
INFO 2022-12-27 19:31:41,469 autoreload 637 Watching for file changes with StatReloader
INFO 2022-12-27 19:52:51,994 autoreload 251 D:\project\python\美多商城\web_app\meiduo_mall\meiduo_mall\settings.py changed, reloading.
INFO 2022-12-27 19:52:52,781 autoreload 637 Watching for file changes with StatReloader
INFO 2022-12-27 20:02:32,672 autoreload 251 D:\project\python\美多商城\web_app\meiduo_mall\apps\verifications\views.py changed, reloading.
INFO 2022-12-27 20:02:33,507 autoreload 637 Watching for file changes with StatReloader
INFO 2022-12-27 20:48:52,588 autoreload 637 Watching for file changes with StatReloader
INFO 2022-12-27 20:56:14,870 autoreload 637 Watching for file changes with StatReloader
INFO 2022-12-27 20:56:32,459 autoreload 251 D:\project\python\美多商城\web_app\meiduo_mall\apps\verifications\views.py changed, reloading.
INFO 2022-12-27 20:56:33,167 autoreload 637 Watching for file changes with StatReloader
INFO 2022-12-27 21:33:15,949 autoreload 637 Watching for file changes with StatReloader
INFO 2022-12-27 21:41:14,842 basehttp 161 "GET /image_codes/23308f49-5d20-4b5a-97e2-c13f759ae92e/ HTTP/1.1" 200 3104
INFO 2022-12-27 21:41:24,573 basehttp 161 "GET /usernames/oincer/count/ HTTP/1.1" 200 39
WARNING 2022-12-27 21:41:43,148 log 224 Not Found: /mobiles/15300000009/count/
WARNING 2022-12-27 21:41:43,149 basehttp 161 "GET /mobiles/15300000009/count/ HTTP/1.1" 404 2950
INFO 2022-12-27 21:42:04,501 basehttp 161 "GET /usernames/oincer/count/ HTTP/1.1" 200 39
WARNING 2022-12-27 21:42:04,501 log 224 Not Found: /mobiles/15300000009/count/
WARNING 2022-12-27 21:42:04,502 basehttp 161 "GET /mobiles/15300000009/count/ HTTP/1.1" 404 2950
WARNING 2022-12-27 21:42:08,042 log 224 Not Found: /mobiles/15300000009/count/
WARNING 2022-12-27 21:42:08,042 basehttp 161 "GET /mobiles/15300000009/count/ HTTP/1.1" 404 2950
ERROR 2022-12-27 21:42:08,080 log 224 Internal Server Error: /sms_codes/15300000009/
Traceback (most recent call last):
  File "C:\Users\alice\AppData\Local\Programs\Python\Python38\lib\site-packages\django\core\handlers\exception.py", line 47, in inner
    response = get_response(request)
  File "C:\Users\alice\AppData\Local\Programs\Python\Python38\lib\site-packages\django\core\handlers\base.py", line 181, in _get_response
    response = wrapped_callback(request, *callback_args, **callback_kwargs)
  File "C:\Users\alice\AppData\Local\Programs\Python\Python38\lib\site-packages\django\views\generic\base.py", line 70, in view
    return self.dispatch(request, *args, **kwargs)
  File "C:\Users\alice\AppData\Local\Programs\Python\Python38\lib\site-packages\django\views\generic\base.py", line 98, in dispatch
    return handler(request, *args, **kwargs)
  File "D:\project\python\美多商城\web_app\meiduo_mall\apps\verifications\views.py", line 25, in get
    image_code = request.Get.get('image_code')
AttributeError: 'WSGIRequest' object has no attribute 'Get'
ERROR 2022-12-27 21:42:08,082 basehttp 161 "GET /sms_codes/15300000009/?image_code=dchc&image_code_id=23308f49-5d20-4b5a-97e2-c13f759ae92e HTTP/1.1" 500 90651
INFO 2022-12-27 21:48:50,398 autoreload 637 Watching for file changes with StatReloader
INFO 2022-12-28 22:01:55,523 autoreload 637 Watching for file changes with StatReloader
INFO 2022-12-28 22:03:37,446 autoreload 637 Watching for file changes with StatReloader
INFO 2022-12-28 22:17:08,624 basehttp 161 "GET /image_codes/f76761d4-8c06-47b7-9dcf-be3e270e2842/ HTTP/1.1" 200 3275
INFO 2022-12-28 22:36:10,440 basehttp 161 "GET /usernames/liuhaobin/count/ HTTP/1.1" 200 39
WARNING 2022-12-28 22:36:26,732 log 224 Not Found: /mobiles/15360606636/count/
WARNING 2022-12-28 22:36:26,733 basehttp 161 "GET /mobiles/15360606636/count/ HTTP/1.1" 404 2950
INFO 2022-12-28 22:40:57,437 autoreload 251 D:\project\python\美多商城\web_app\meiduo_mall\apps\users\views.py changed, reloading.
INFO 2022-12-28 22:40:58,237 autoreload 637 Watching for file changes with StatReloader
INFO 2022-12-28 22:41:18,076 autoreload 251 D:\project\python\美多商城\web_app\meiduo_mall\apps\users\views.py changed, reloading.
INFO 2022-12-28 22:41:18,840 autoreload 637 Watching for file changes with StatReloader
INFO 2022-12-28 22:42:14,641 autoreload 251 D:\project\python\美多商城\web_app\meiduo_mall\apps\users\urls.py changed, reloading.
INFO 2022-12-28 22:42:15,395 autoreload 637 Watching for file changes with StatReloader
INFO 2022-12-28 22:49:39,278 basehttp 161 "GET /image_codes/d98029ff-0042-4c47-a7bb-a5c767b128ff/ HTTP/1.1" 200 3168
INFO 2022-12-28 22:49:46,886 basehttp 161 "GET /usernames/liuhaobin/count/ HTTP/1.1" 200 39
INFO 2022-12-28 22:50:15,310 basehttp 161 "GET /usernames/alice/count/ HTTP/1.1" 200 39
INFO 2022-12-28 22:50:40,932 basehttp 161 "GET /mobiles/15360606636/count/ HTTP/1.1" 200 39
INFO 2022-12-28 22:50:43,069 basehttp 161 "GET /image_codes/394a28f3-06e7-4bfd-9364-737a82faa1ad/ HTTP/1.1" 200 3162
INFO 2022-12-28 22:50:54,830 basehttp 161 "GET /mobiles/15360606636/count/ HTTP/1.1" 200 39
ERROR 2022-12-28 22:50:54,869 log 224 Internal Server Error: /sms_codes/15360606636/
Traceback (most recent call last):
  File "C:\Users\alice\AppData\Local\Programs\Python\Python38\lib\site-packages\django\core\handlers\exception.py", line 47, in inner
    response = get_response(request)
  File "C:\Users\alice\AppData\Local\Programs\Python\Python38\lib\site-packages\django\core\handlers\base.py", line 181, in _get_response
    response = wrapped_callback(request, *callback_args, **callback_kwargs)
  File "C:\Users\alice\AppData\Local\Programs\Python\Python38\lib\site-packages\django\views\generic\base.py", line 70, in view
    return self.dispatch(request, *args, **kwargs)
  File "C:\Users\alice\AppData\Local\Programs\Python\Python38\lib\site-packages\django\views\generic\base.py", line 98, in dispatch
    return handler(request, *args, **kwargs)
  File "D:\project\python\美多商城\web_app\meiduo_mall\apps\verifications\views.py", line 25, in get
    image_code = request.Get.get('image_code')
AttributeError: 'WSGIRequest' object has no attribute 'Get'
ERROR 2022-12-28 22:50:54,872 basehttp 161 "GET /sms_codes/15360606636/?image_code=IPQS&image_code_id=394a28f3-06e7-4bfd-9364-737a82faa1ad HTTP/1.1" 500 91979
INFO 2022-12-28 22:53:22,209 autoreload 251 D:\project\python\美多商城\web_app\meiduo_mall\apps\verifications\views.py changed, reloading.
INFO 2022-12-28 22:53:22,901 autoreload 637 Watching for file changes with StatReloader
INFO 2022-12-28 22:53:29,400 basehttp 161 "GET /mobiles/15360606636/count/ HTTP/1.1" 200 39
INFO 2022-12-28 22:53:29,404 basehttp 161 "GET /sms_codes/15360606636/?image_code=IPQS&image_code_id=394a28f3-06e7-4bfd-9364-737a82faa1ad HTTP/1.1" 200 75
INFO 2022-12-28 23:04:08,918 autoreload 637 Watching for file changes with StatReloader
INFO 2022-12-28 23:04:57,221 basehttp 161 "GET /mobiles/15360606636/count/ HTTP/1.1" 200 39
INFO 2022-12-28 23:04:57,225 basehttp 161 "GET /sms_codes/15360606636/?image_code=IPQS&image_code_id=394a28f3-06e7-4bfd-9364-737a82faa1ad HTTP/1.1" 200 75
INFO 2022-12-28 23:59:03,100 autoreload 637 Watching for file changes with StatReloader
INFO 2022-12-29 00:01:03,465 basehttp 161 "GET /image_codes/2ffea080-bb67-4ea0-b05d-5c5d1901222c/ HTTP/1.1" 200 2973
INFO 2022-12-29 00:01:09,195 basehttp 161 "GET /usernames/allice/count/ HTTP/1.1" 200 39
INFO 2022-12-29 00:01:25,237 basehttp 161 "GET /mobiles/15360606636/count/ HTTP/1.1" 200 39
INFO 2022-12-29 00:01:32,150 basehttp 161 "GET /mobiles/15360606636/count/ HTTP/1.1" 200 39
INFO 2022-12-29 00:01:32,315 basehttp 161 "GET /sms_codes/15360606636/?image_code=5vsh&image_code_id=2ffea080-bb67-4ea0-b05d-5c5d1901222c HTTP/1.1" 200 27
INFO 2022-12-29 02:34:55,291 autoreload 251 D:\project\python\美多商城\web_app\meiduo_mall\apps\users\views.py changed, reloading.
INFO 2022-12-29 02:34:56,082 autoreload 637 Watching for file changes with StatReloader
INFO 2022-12-29 02:35:28,013 autoreload 251 D:\project\python\美多商城\web_app\meiduo_mall\apps\users\views.py changed, reloading.
INFO 2022-12-29 02:35:28,716 autoreload 637 Watching for file changes with StatReloader
INFO 2022-12-29 17:14:52,528 autoreload 637 Watching for file changes with StatReloader
INFO 2022-12-29 17:15:08,221 basehttp 161 "GET /image_codes/6ff89fbf-b5ef-413d-804e-daa0fa714149/ HTTP/1.1" 200 3398
INFO 2022-12-29 17:15:28,335 basehttp 161 "GET /usernames/alice/count/ HTTP/1.1" 200 39
INFO 2022-12-29 17:15:46,751 basehttp 161 "GET /mobiles/15360606636/count/ HTTP/1.1" 200 39
INFO 2022-12-29 17:15:56,588 basehttp 161 "GET /mobiles/15360606636/count/ HTTP/1.1" 200 39
INFO 2022-12-29 17:15:56,747 basehttp 161 "GET /sms_codes/15360606636/?image_code=6LUQ&image_code_id=6ff89fbf-b5ef-413d-804e-daa0fa714149 HTTP/1.1" 200 27
INFO 2022-12-29 17:17:14,809 basehttp 161 "OPTIONS /register/ HTTP/1.1" 200 0
INFO 2022-12-29 17:17:14,810 basehttp 161 "GET /mobiles/15360606636/count/ HTTP/1.1" 200 39
INFO 2022-12-29 17:17:14,815 basehttp 161 "GET /usernames/alice/count/ HTTP/1.1" 200 39
ERROR 2022-12-29 17:17:14,977 log 224 Internal Server Error: /register/
Traceback (most recent call last):
  File "C:\Users\alice\AppData\Local\Programs\Python\Python38\lib\site-packages\django\core\handlers\exception.py", line 47, in inner
    response = get_response(request)
  File "C:\Users\alice\AppData\Local\Programs\Python\Python38\lib\site-packages\django\core\handlers\base.py", line 181, in _get_response
    response = wrapped_callback(request, *callback_args, **callback_kwargs)
  File "C:\Users\alice\AppData\Local\Programs\Python\Python38\lib\site-packages\django\views\generic\base.py", line 70, in view
    return self.dispatch(request, *args, **kwargs)
  File "C:\Users\alice\AppData\Local\Programs\Python\Python38\lib\site-packages\django\views\generic\base.py", line 98, in dispatch
    return handler(request, *args, **kwargs)
  File "D:\project\python\美多商城\web_app\meiduo_mall\apps\users\views.py", line 57, in post
    login(request.user)
TypeError: login() missing 1 required positional argument: 'user'
ERROR 2022-12-29 17:17:14,980 basehttp 161 "POST /register/ HTTP/1.1" 500 92625
INFO 2022-12-29 17:17:31,356 basehttp 161 "GET /usernames/alice/count/ HTTP/1.1" 200 39
INFO 2022-12-29 17:17:31,356 basehttp 161 "GET /mobiles/15360606636/count/ HTTP/1.1" 200 39
ERROR 2022-12-29 17:17:31,511 log 224 Internal Server Error: /register/
Traceback (most recent call last):
  File "C:\Users\alice\AppData\Local\Programs\Python\Python38\lib\site-packages\django\db\backends\utils.py", line 84, in _execute
    return self.cursor.execute(sql, params)
  File "C:\Users\alice\AppData\Local\Programs\Python\Python38\lib\site-packages\django\db\backends\mysql\base.py", line 73, in execute
    return self.cursor.execute(query, args)
  File "C:\Users\alice\AppData\Local\Programs\Python\Python38\lib\site-packages\MySQLdb\cursors.py", line 206, in execute
    res = self._query(query)
  File "C:\Users\alice\AppData\Local\Programs\Python\Python38\lib\site-packages\MySQLdb\cursors.py", line 319, in _query
    db.query(q)
  File "C:\Users\alice\AppData\Local\Programs\Python\Python38\lib\site-packages\MySQLdb\connections.py", line 254, in query
    _mysql.connection.query(self, query)
MySQLdb.IntegrityError: (1062, "Duplicate entry 'alice' for key 'username'")

The above exception was the direct cause of the following exception:

Traceback (most recent call last):
  File "C:\Users\alice\AppData\Local\Programs\Python\Python38\lib\site-packages\django\core\handlers\exception.py", line 47, in inner
    response = get_response(request)
  File "C:\Users\alice\AppData\Local\Programs\Python\Python38\lib\site-packages\django\core\handlers\base.py", line 181, in _get_response
    response = wrapped_callback(request, *callback_args, **callback_kwargs)
  File "C:\Users\alice\AppData\Local\Programs\Python\Python38\lib\site-packages\django\views\generic\base.py", line 70, in view
    return self.dispatch(request, *args, **kwargs)
  File "C:\Users\alice\AppData\Local\Programs\Python\Python38\lib\site-packages\django\views\generic\base.py", line 98, in dispatch
    return handler(request, *args, **kwargs)
  File "D:\project\python\美多商城\web_app\meiduo_mall\apps\users\views.py", line 52, in post
    User.objects.create_user(username=username,password=password,mobile=mobile)
  File "C:\Users\alice\AppData\Local\Programs\Python\Python38\lib\site-packages\django\contrib\auth\models.py", line 152, in create_user
    return self._create_user(username, email, password, **extra_fields)
  File "C:\Users\alice\AppData\Local\Programs\Python\Python38\lib\site-packages\django\contrib\auth\models.py", line 146, in _create_user
    user.save(using=self._db)
  File "C:\Users\alice\AppData\Local\Programs\Python\Python38\lib\site-packages\django\contrib\auth\base_user.py", line 67, in save
    super().save(*args, **kwargs)
  File "C:\Users\alice\AppData\Local\Programs\Python\Python38\lib\site-packages\django\db\models\base.py", line 739, in save
    self.save_base(using=using, force_insert=force_insert,
  File "C:\Users\alice\AppData\Local\Programs\Python\Python38\lib\site-packages\django\db\models\base.py", line 776, in save_base
    updated = self._save_table(
  File "C:\Users\alice\AppData\Local\Programs\Python\Python38\lib\site-packages\django\db\models\base.py", line 881, in _save_table
    results = self._do_insert(cls._base_manager, using, fields, returning_fields, raw)
  File "C:\Users\alice\AppData\Local\Programs\Python\Python38\lib\site-packages\django\db\models\base.py", line 919, in _do_insert
    return manager._insert(
  File "C:\Users\alice\AppData\Local\Programs\Python\Python38\lib\site-packages\django\db\models\manager.py", line 85, in manager_method
    return getattr(self.get_queryset(), name)(*args, **kwargs)
  File "C:\Users\alice\AppData\Local\Programs\Python\Python38\lib\site-packages\django\db\models\query.py", line 1270, in _insert
    return query.get_compiler(using=using).execute_sql(returning_fields)
  File "C:\Users\alice\AppData\Local\Programs\Python\Python38\lib\site-packages\django\db\models\sql\compiler.py", line 1416, in execute_sql
    cursor.execute(sql, params)
  File "C:\Users\alice\AppData\Local\Programs\Python\Python38\lib\site-packages\django\db\backends\utils.py", line 98, in execute
    return super().execute(sql, params)
  File "C:\Users\alice\AppData\Local\Programs\Python\Python38\lib\site-packages\django\db\backends\utils.py", line 66, in execute
    return self._execute_with_wrappers(sql, params, many=False, executor=self._execute)
  File "C:\Users\alice\AppData\Local\Programs\Python\Python38\lib\site-packages\django\db\backends\utils.py", line 75, in _execute_with_wrappers
    return executor(sql, params, many, context)
  File "C:\Users\alice\AppData\Local\Programs\Python\Python38\lib\site-packages\django\db\backends\utils.py", line 84, in _execute
    return self.cursor.execute(sql, params)
  File "C:\Users\alice\AppData\Local\Programs\Python\Python38\lib\site-packages\django\db\utils.py", line 90, in __exit__
    raise dj_exc_value.with_traceback(traceback) from exc_value
  File "C:\Users\alice\AppData\Local\Programs\Python\Python38\lib\site-packages\django\db\backends\utils.py", line 84, in _execute
    return self.cursor.execute(sql, params)
  File "C:\Users\alice\AppData\Local\Programs\Python\Python38\lib\site-packages\django\db\backends\mysql\base.py", line 73, in execute
    return self.cursor.execute(query, args)
  File "C:\Users\alice\AppData\Local\Programs\Python\Python38\lib\site-packages\MySQLdb\cursors.py", line 206, in execute
    res = self._query(query)
  File "C:\Users\alice\AppData\Local\Programs\Python\Python38\lib\site-packages\MySQLdb\cursors.py", line 319, in _query
    db.query(q)
  File "C:\Users\alice\AppData\Local\Programs\Python\Python38\lib\site-packages\MySQLdb\connections.py", line 254, in query
    _mysql.connection.query(self, query)
django.db.utils.IntegrityError: (1062, "Duplicate entry 'alice' for key 'username'")
ERROR 2022-12-29 17:17:31,524 basehttp 161 "POST /register/ HTTP/1.1" 500 219197
INFO 2022-12-29 17:18:15,994 basehttp 161 "OPTIONS /login/ HTTP/1.1" 200 0
WARNING 2022-12-29 17:18:16,002 log 224 Not Found: /login/
WARNING 2022-12-29 17:18:16,003 basehttp 161 "POST /login/ HTTP/1.1" 404 3067
WARNING 2022-12-29 17:18:31,059 log 224 Not Found: /login/
WARNING 2022-12-29 17:18:31,060 basehttp 161 "POST /login/ HTTP/1.1" 404 3067
INFO 2022-12-29 17:20:56,604 autoreload 251 D:\project\python\美多商城\web_app\meiduo_mall\apps\users\urls.py changed, reloading.
INFO 2022-12-29 17:20:57,302 autoreload 637 Watching for file changes with StatReloader
INFO 2022-12-29 17:21:08,403 basehttp 161 "POST /login/ HTTP/1.1" 200 75
INFO 2022-12-29 17:21:19,130 basehttp 161 "POST /login/ HTTP/1.1" 200 75
INFO 2022-12-29 17:22:29,619 basehttp 161 "GET /image_codes/5c362d21-3953-4fb9-872d-911c2ac8b782/ HTTP/1.1" 200 3195
INFO 2022-12-29 17:22:34,991 basehttp 161 "GET /usernames/alice/count/ HTTP/1.1" 200 39
INFO 2022-12-29 17:22:52,810 basehttp 161 "GET /mobiles/15360606636/count/ HTTP/1.1" 200 39
INFO 2022-12-29 17:23:02,452 basehttp 161 "GET /mobiles/15360606636/count/ HTTP/1.1" 200 39
INFO 2022-12-29 17:23:02,571 basehttp 161 "GET /sms_codes/15360606636/?image_code=s6ek&image_code_id=5c362d21-3953-4fb9-872d-911c2ac8b782 HTTP/1.1" 200 27
INFO 2022-12-29 17:23:33,622 basehttp 161 "GET /usernames/alice/count/ HTTP/1.1" 200 39
INFO 2022-12-29 17:23:33,627 basehttp 161 "GET /mobiles/15360606636/count/ HTTP/1.1" 200 39
ERROR 2022-12-29 17:23:33,720 log 224 Internal Server Error: /register/
Traceback (most recent call last):
  File "C:\Users\alice\AppData\Local\Programs\Python\Python38\lib\site-packages\django\core\handlers\exception.py", line 47, in inner
    response = get_response(request)
  File "C:\Users\alice\AppData\Local\Programs\Python\Python38\lib\site-packages\django\core\handlers\base.py", line 181, in _get_response
    response = wrapped_callback(request, *callback_args, **callback_kwargs)
  File "C:\Users\alice\AppData\Local\Programs\Python\Python38\lib\site-packages\django\views\generic\base.py", line 70, in view
    return self.dispatch(request, *args, **kwargs)
  File "C:\Users\alice\AppData\Local\Programs\Python\Python38\lib\site-packages\django\views\generic\base.py", line 98, in dispatch
    return handler(request, *args, **kwargs)
  File "D:\project\python\美多商城\web_app\meiduo_mall\apps\users\views.py", line 57, in post
    login(request.user)
TypeError: login() missing 1 required positional argument: 'user'
ERROR 2022-12-29 17:23:33,723 basehttp 161 "POST /register/ HTTP/1.1" 500 92631
INFO 2022-12-29 17:39:51,063 autoreload 251 D:\project\python\美多商城\web_app\meiduo_mall\apps\users\views.py changed, reloading.
INFO 2022-12-29 17:39:51,776 autoreload 637 Watching for file changes with StatReloader
INFO 2022-12-29 17:40:10,140 basehttp 161 "GET /usernames/alice/count/ HTTP/1.1" 200 39
INFO 2022-12-29 17:40:10,142 basehttp 161 "GET /mobiles/15360606636/count/ HTTP/1.1" 200 39
ERROR 2022-12-29 17:40:10,235 log 224 Internal Server Error: /register/
Traceback (most recent call last):
  File "C:\Users\alice\AppData\Local\Programs\Python\Python38\lib\site-packages\django\core\handlers\exception.py", line 47, in inner
    response = get_response(request)
  File "C:\Users\alice\AppData\Local\Programs\Python\Python38\lib\site-packages\django\core\handlers\base.py", line 181, in _get_response
    response = wrapped_callback(request, *callback_args, **callback_kwargs)
  File "C:\Users\alice\AppData\Local\Programs\Python\Python38\lib\site-packages\django\views\generic\base.py", line 70, in view
    return self.dispatch(request, *args, **kwargs)
  File "C:\Users\alice\AppData\Local\Programs\Python\Python38\lib\site-packages\django\views\generic\base.py", line 98, in dispatch
    return handler(request, *args, **kwargs)
  File "D:\project\python\美多商城\web_app\meiduo_mall\apps\users\views.py", line 57, in post
    login(request.user)
TypeError: login() missing 1 required positional argument: 'user'
ERROR 2022-12-29 17:40:10,238 basehttp 161 "POST /register/ HTTP/1.1" 500 92561
INFO 2022-12-29 17:40:49,712 autoreload 251 D:\project\python\美多商城\web_app\meiduo_mall\apps\users\views.py changed, reloading.
INFO 2022-12-29 17:40:50,365 autoreload 637 Watching for file changes with StatReloader
INFO 2022-12-29 17:43:52,510 autoreload 637 Watching for file changes with StatReloader
INFO 2022-12-29 17:44:22,231 autoreload 637 Watching for file changes with StatReloader
INFO 2022-12-29 17:45:05,242 autoreload 637 Watching for file changes with StatReloader
INFO 2022-12-29 20:22:14,022 autoreload 251 D:\project\python\美多商城\web_app\meiduo_mall\apps\users\models.py changed, reloading.
INFO 2022-12-29 20:22:14,919 autoreload 637 Watching for file changes with StatReloader
INFO 2022-12-29 20:33:38,884 autoreload 251 D:\project\python\美多商城\web_app\meiduo_mall\utils\models.py changed, reloading.
INFO 2022-12-29 20:33:39,582 autoreload 637 Watching for file changes with StatReloader
INFO 2022-12-29 20:41:05,028 autoreload 251 D:\project\python\美多商城\web_app\meiduo_mall\apps\users\views.py changed, reloading.
INFO 2022-12-29 20:41:05,670 autoreload 637 Watching for file changes with StatReloader
INFO 2022-12-29 20:41:15,375 autoreload 637 Watching for file changes with StatReloader
INFO 2022-12-29 20:42:38,528 autoreload 251 D:\project\python\美多商城\web_app\meiduo_mall\apps\users\views.py changed, reloading.
INFO 2022-12-29 20:42:39,210 autoreload 637 Watching for file changes with StatReloader
INFO 2022-12-29 20:43:19,499 autoreload 251 D:\project\python\美多商城\web_app\meiduo_mall\apps\users\views.py changed, reloading.
INFO 2022-12-29 20:43:20,230 autoreload 637 Watching for file changes with StatReloader
INFO 2022-12-29 21:06:54,999 autoreload 251 D:\project\python\美多商城\web_app\meiduo_mall\apps\users\views.py changed, reloading.
INFO 2022-12-29 21:06:55,775 autoreload 637 Watching for file changes with StatReloader
INFO 2022-12-29 21:07:36,116 autoreload 251 D:\project\python\美多商城\web_app\meiduo_mall\apps\users\models.py changed, reloading.
INFO 2022-12-29 21:07:36,868 autoreload 637 Watching for file changes with StatReloader
INFO 2022-12-29 21:08:10,710 basehttp 161 "OPTIONS /login/ HTTP/1.1" 200 0
INFO 2022-12-29 21:08:10,802 basehttp 161 "POST /login/ HTTP/1.1" 200 27
WARNING 2022-12-29 21:08:11,155 log 224 Not Found: /carts/simple/
WARNING 2022-12-29 21:08:11,156 basehttp 161 "GET /carts/simple/ HTTP/1.1" 404 3240
INFO 2022-12-30 12:34:46,430 autoreload 637 Watching for file changes with StatReloader
INFO 2022-12-30 12:35:24,758 autoreload 637 Watching for file changes with StatReloader
INFO 2022-12-30 12:39:14,801 basehttp 161 "OPTIONS /login/ HTTP/1.1" 200 0
INFO 2022-12-30 12:39:14,892 basehttp 161 "POST /login/ HTTP/1.1" 200 27
WARNING 2022-12-30 12:39:15,222 log 224 Not Found: /carts/simple/
WARNING 2022-12-30 12:39:15,223 basehttp 161 "GET /carts/simple/ HTTP/1.1" 404 3240
INFO 2022-12-30 13:00:39,170 autoreload 251 D:\project\python\美多商城\web_app\meiduo_mall\apps\users\views.py changed, reloading.
INFO 2022-12-30 13:00:39,963 autoreload 637 Watching for file changes with StatReloader
INFO 2022-12-30 13:10:52,290 basehttp 161 "OPTIONS /logout/ HTTP/1.1" 200 0
WARNING 2022-12-30 13:10:52,302 log 224 Not Found: /logout/
WARNING 2022-12-30 13:10:52,303 basehttp 161 "DELETE /logout/ HTTP/1.1" 404 3225
WARNING 2022-12-30 13:10:55,130 log 224 Not Found: /logout/
WARNING 2022-12-30 13:10:55,130 basehttp 161 "DELETE /logout/ HTTP/1.1" 404 3225
INFO 2022-12-30 13:11:47,586 autoreload 251 D:\project\python\美多商城\web_app\meiduo_mall\apps\users\urls.py changed, reloading.
INFO 2022-12-30 13:11:48,359 autoreload 637 Watching for file changes with StatReloader
INFO 2022-12-30 13:11:54,236 basehttp 161 "DELETE /logout/ HTTP/1.1" 200 27
INFO 2022-12-30 13:33:02,625 autoreload 251 D:\project\python\美多商城\web_app\meiduo_mall\apps\users\views.py changed, reloading.
INFO 2022-12-30 13:33:03,459 autoreload 637 Watching for file changes with StatReloader
INFO 2022-12-30 13:35:02,698 autoreload 637 Watching for file changes with StatReloader
INFO 2022-12-30 13:39:14,325 autoreload 251 D:\project\python\美多商城\web_app\meiduo_mall\apps\users\views.py changed, reloading.
INFO 2022-12-30 13:39:15,094 autoreload 637 Watching for file changes with StatReloader
INFO 2022-12-30 14:22:41,069 autoreload 251 D:\project\python\美多商城\web_app\meiduo_mall\apps\users\views.py changed, reloading.
INFO 2022-12-30 14:22:41,916 autoreload 637 Watching for file changes with StatReloader
INFO 2022-12-30 15:06:08,486 autoreload 251 D:\project\python\美多商城\web_app\meiduo_mall\meiduo_mall\settings.py changed, reloading.
INFO 2022-12-30 15:06:09,402 autoreload 637 Watching for file changes with StatReloader
INFO 2022-12-30 15:13:59,769 autoreload 251 D:\project\python\美多商城\web_app\meiduo_mall\apps\oauth\models.py changed, reloading.
INFO 2022-12-30 15:14:00,586 autoreload 637 Watching for file changes with StatReloader
INFO 2022-12-30 15:30:58,696 autoreload 251 D:\project\python\美多商城\web_app\meiduo_mall\apps\users\models.py changed, reloading.
INFO 2022-12-30 15:30:59,537 autoreload 637 Watching for file changes with StatReloader
INFO 2022-12-31 18:15:34,231 autoreload 637 Watching for file changes with StatReloader
INFO 2022-12-31 18:16:15,523 autoreload 637 Watching for file changes with StatReloader
INFO 2022-12-31 19:02:44,817 autoreload 251 D:\project\python\美多商城\web_app\meiduo_mall\meiduo_mall\urls.py changed, reloading.
INFO 2022-12-31 19:02:45,580 autoreload 637 Watching for file changes with StatReloader
INFO 2022-12-31 19:02:59,062 basehttp 161 "GET /image_codes/7a70369c-2ded-45c9-9868-ae2f65b46220/ HTTP/1.1" 200 3313
ERROR 2022-12-31 19:03:12,554 log 224 Internal Server Error: /qq/authorization/
Traceback (most recent call last):
  File "C:\Users\alice\AppData\Local\Programs\Python\Python38\lib\site-packages\django\core\handlers\exception.py", line 47, in inner
    response = get_response(request)
  File "C:\Users\alice\AppData\Local\Programs\Python\Python38\lib\site-packages\django\core\handlers\base.py", line 181, in _get_response
    response = wrapped_callback(request, *callback_args, **callback_kwargs)
  File "C:\Users\alice\AppData\Local\Programs\Python\Python38\lib\site-packages\django\views\generic\base.py", line 70, in view
    return self.dispatch(request, *args, **kwargs)
  File "C:\Users\alice\AppData\Local\Programs\Python\Python38\lib\site-packages\django\views\generic\base.py", line 98, in dispatch
    return handler(request, *args, **kwargs)
  File "D:\project\python\美多商城\web_app\meiduo_mall\apps\oauth\views.py", line 12, in get
    qq = OAuthQQ(client_id = settings.QQ_CLIENT_ID,
TypeError: __init__() got an unexpected keyword argument 'redirect_url'
ERROR 2022-12-31 19:03:12,557 basehttp 161 "GET /qq/authorization/?next=/ HTTP/1.1" 500 91420
INFO 2022-12-31 19:05:52,892 autoreload 251 D:\project\python\美多商城\web_app\meiduo_mall\apps\oauth\views.py changed, reloading.
INFO 2022-12-31 19:05:53,714 autoreload 637 Watching for file changes with StatReloader
INFO 2022-12-31 19:05:58,066 basehttp 161 "GET /qq/authorization/?next=/ HTTP/1.1" 200 205
WARNING 2022-12-31 19:14:28,927 log 224 Not Found: /oauth_callback/
WARNING 2022-12-31 19:14:28,928 basehttp 161 "GET /oauth_callback/?code=FE5D26470E1CC77E5161824F88CB01DA HTTP/1.1" 404 3756
INFO 2022-12-31 19:57:08,664 autoreload 251 D:\project\python\美多商城\web_app\meiduo_mall\apps\oauth\views.py changed, reloading.
INFO 2022-12-31 19:57:09,559 autoreload 637 Watching for file changes with StatReloader
INFO 2022-12-31 19:59:55,327 autoreload 251 D:\project\python\美多商城\web_app\meiduo_mall\apps\oauth\views.py changed, reloading.
INFO 2022-12-31 19:59:56,125 autoreload 637 Watching for file changes with StatReloader
INFO 2022-12-31 20:01:00,094 autoreload 251 D:\project\python\美多商城\web_app\meiduo_mall\apps\oauth\views.py changed, reloading.
INFO 2022-12-31 20:01:00,878 autoreload 637 Watching for file changes with StatReloader
INFO 2022-12-31 20:01:33,058 autoreload 251 D:\project\python\美多商城\web_app\meiduo_mall\apps\oauth\views.py changed, reloading.
INFO 2022-12-31 20:01:33,843 autoreload 637 Watching for file changes with StatReloader
INFO 2022-12-31 20:17:34,628 autoreload 251 D:\project\python\美多商城\web_app\meiduo_mall\apps\oauth\views.py changed, reloading.
INFO 2022-12-31 20:17:35,316 autoreload 637 Watching for file changes with StatReloader
INFO 2022-12-31 20:29:36,775 autoreload 637 Watching for file changes with StatReloader
INFO 2023-01-01 21:07:14,105 autoreload 637 Watching for file changes with StatReloader
INFO 2023-01-01 21:08:06,506 autoreload 251 D:\project\python\美多商城\web_app\meiduo_mall\apps\oauth\views.py changed, reloading.
INFO 2023-01-01 21:08:07,181 autoreload 637 Watching for file changes with StatReloader
INFO 2023-01-01 21:09:24,896 autoreload 251 D:\project\python\美多商城\web_app\meiduo_mall\apps\oauth\views.py changed, reloading.
INFO 2023-01-01 21:09:25,553 autoreload 637 Watching for file changes with StatReloader
INFO 2023-01-01 21:14:19,205 autoreload 251 C:\Users\alice\AppData\Local\Programs\Python\Python38\Lib\site-packages\itsdangerous\serializer.py changed, reloading.
INFO 2023-01-01 21:14:19,850 autoreload 637 Watching for file changes with StatReloader
INFO 2023-01-01 21:14:33,676 autoreload 637 Watching for file changes with StatReloader
INFO 2023-01-01 21:14:55,156 autoreload 637 Watching for file changes with StatReloader
INFO 2023-01-01 21:15:18,124 autoreload 637 Watching for file changes with StatReloader
INFO 2023-01-01 21:29:34,906 autoreload 637 Watching for file changes with StatReloader
INFO 2023-01-01 21:57:39,594 autoreload 251 D:\project\python\美多商城\web_app\meiduo_mall\apps\oauth\views.py changed, reloading.
INFO 2023-01-01 21:57:40,401 autoreload 637 Watching for file changes with StatReloader
INFO 2023-01-01 22:02:28,014 autoreload 251 C:\Users\alice\AppData\Local\Programs\Python\Python38\Lib\site-packages\itsdangerous\_json.py changed, reloading.
INFO 2023-01-01 22:02:28,650 autoreload 637 Watching for file changes with StatReloader
INFO 2023-01-01 22:08:20,820 basehttp 161 "GET /image_codes/15398780-b137-408b-abd1-8af2ecba40f4/ HTTP/1.1" 200 3276
INFO 2023-01-01 22:08:40,551 basehttp 161 "OPTIONS /login/ HTTP/1.1" 200 0
INFO 2023-01-01 22:08:40,949 basehttp 161 "POST /login/ HTTP/1.1" 200 27
WARNING 2023-01-01 22:08:41,311 log 224 Not Found: /carts/simple/
WARNING 2023-01-01 22:08:41,312 basehttp 161 "GET /carts/simple/ HTTP/1.1" 404 3712
WARNING 2023-01-01 22:08:45,070 log 224 Not Found: /info/
WARNING 2023-01-01 22:08:45,071 log 224 Not Found: /browse_histories/
WARNING 2023-01-01 22:08:45,071 basehttp 161 "GET /info/ HTTP/1.1" 404 3688
WARNING 2023-01-01 22:08:45,072 basehttp 161 "GET /browse_histories/ HTTP/1.1" 404 3724
INFO 2023-01-01 22:08:51,457 basehttp 161 "GET /qq/authorization/?next=/ HTTP/1.1" 200 205
WARNING 2023-01-01 22:09:06,102 log 224 Not Found: /oauth_callback/
WARNING 2023-01-01 22:09:06,103 basehttp 161 "GET /oauth_callback/?code=1D933B499174808CC7355440130915C5 HTTP/1.1" 404 3756
INFO 2023-01-01 22:10:34,120 autoreload 251 D:\project\python\美多商城\web_app\meiduo_mall\apps\oauth\urls.py changed, reloading.
INFO 2023-01-01 22:10:34,843 autoreload 637 Watching for file changes with StatReloader
INFO 2023-01-01 22:10:41,562 basehttp 161 "GET /oauth_callback/?code=1D933B499174808CC7355440130915C5 HTTP/1.1" 200 247
INFO 2023-01-01 22:10:41,601 basehttp 161 "GET /image_codes/c72db894-0672-4f02-b64f-46a6bcdb9e20/ HTTP/1.1" 200 3380
INFO 2023-01-01 22:10:55,529 basehttp 161 "GET /qq/authorization/?next=/ HTTP/1.1" 200 205
INFO 2023-01-01 22:11:02,246 basehttp 161 "GET /oauth_callback/?code=8562AE40D631FF9BEC36B8A5A12D9246 HTTP/1.1" 200 247
INFO 2023-01-01 22:11:02,258 basehttp 161 "GET /image_codes/2927a0aa-2c4d-47de-8b09-2fae856d1267/ HTTP/1.1" 200 2795
INFO 2023-01-01 22:11:29,194 basehttp 161 "GET /sms_codes/15360606636/?image_code=8DVO&image_code_id=2927a0aa-2c4d-47de-8b09-2fae856d1267 HTTP/1.1" 200 27
INFO 2023-01-01 22:11:42,144 basehttp 161 "OPTIONS /oauth_callback/ HTTP/1.1" 200 0
INFO 2023-01-01 22:11:42,262 basehttp 161 "POST /oauth_callback/ HTTP/1.1" 200 27
WARNING 2023-01-01 22:11:42,535 log 224 Not Found: /carts/simple/
WARNING 2023-01-01 22:11:42,536 basehttp 161 "GET /carts/simple/ HTTP/1.1" 404 3874
WARNING 2023-01-01 22:11:47,002 log 224 Not Found: /info/
WARNING 2023-01-01 22:11:47,003 log 224 Not Found: /browse_histories/
WARNING 2023-01-01 22:11:47,003 basehttp 161 "GET /info/ HTTP/1.1" 404 3850
WARNING 2023-01-01 22:11:47,003 basehttp 161 "GET /browse_histories/ HTTP/1.1" 404 3886
INFO 2023-01-01 22:11:51,975 basehttp 161 "GET /qq/authorization/?next=/ HTTP/1.1" 200 205
INFO 2023-01-01 22:11:58,481 basehttp 161 "GET /oauth_callback/?code=F80DA3C45D58AD29D9C25C3BE4711265 HTTP/1.1" 200 27
WARNING 2023-01-01 22:11:58,627 log 224 Not Found: /carts/simple/
WARNING 2023-01-01 22:11:58,627 basehttp 161 "GET /carts/simple/ HTTP/1.1" 404 3874
WARNING 2023-01-01 22:12:00,950 log 224 Not Found: /browse_histories/
WARNING 2023-01-01 22:12:00,951 log 224 Not Found: /info/
WARNING 2023-01-01 22:12:00,952 basehttp 161 "GET /browse_histories/ HTTP/1.1" 404 3886
WARNING 2023-01-01 22:12:00,952 basehttp 161 "GET /info/ HTTP/1.1" 404 3850
INFO 2023-01-04 00:47:17,993 autoreload 637 Watching for file changes with StatReloader
INFO 2023-01-04 00:50:37,499 basehttp 161 "OPTIONS /login/ HTTP/1.1" 200 0
INFO 2023-01-04 00:50:37,594 basehttp 161 "POST /login/ HTTP/1.1" 200 69
INFO 2023-01-04 00:51:13,038 basehttp 161 "POST /login/ HTTP/1.1" 200 27
WARNING 2023-01-04 00:51:13,489 log 224 Not Found: /carts/simple/
WARNING 2023-01-04 00:51:13,490 basehttp 161 "GET /carts/simple/ HTTP/1.1" 404 3874
WARNING 2023-01-04 00:51:18,502 log 224 Not Found: /info/
WARNING 2023-01-04 00:51:18,503 log 224 Not Found: /browse_histories/
WARNING 2023-01-04 00:51:18,503 basehttp 161 "GET /info/ HTTP/1.1" 404 3850
WARNING 2023-01-04 00:51:18,503 basehttp 161 "GET /browse_histories/ HTTP/1.1" 404 3886
INFO 2023-01-04 00:51:59,983 basehttp 161 "POST /login/ HTTP/1.1" 200 69
INFO 2023-01-04 00:52:08,966 basehttp 161 "POST /login/ HTTP/1.1" 200 27
WARNING 2023-01-04 00:52:09,138 log 224 Not Found: /carts/simple/
WARNING 2023-01-04 00:52:09,138 basehttp 161 "GET /carts/simple/ HTTP/1.1" 404 3874
WARNING 2023-01-04 00:53:33,300 log 224 Not Found: /info/
WARNING 2023-01-04 00:53:33,301 log 224 Not Found: /browse_histories/
WARNING 2023-01-04 00:53:33,302 basehttp 161 "GET /info/ HTTP/1.1" 404 3850
WARNING 2023-01-04 00:53:33,302 basehttp 161 "GET /browse_histories/ HTTP/1.1" 404 3886
INFO 2023-01-04 00:54:15,862 autoreload 637 Watching for file changes with StatReloader
INFO 2023-01-04 00:54:36,067 basehttp 161 "OPTIONS /login/ HTTP/1.1" 200 0
INFO 2023-01-04 00:54:39,548 basehttp 161 "OPTIONS /login/ HTTP/1.1" 200 0
INFO 2023-01-04 00:54:46,670 basehttp 161 "OPTIONS /login/ HTTP/1.1" 200 0
INFO 2023-01-04 00:55:09,198 basehttp 161 "POST /login/ HTTP/1.1" 200 27
WARNING 2023-01-04 00:55:09,438 log 224 Not Found: /carts/simple/
WARNING 2023-01-04 00:55:09,438 basehttp 161 "GET /carts/simple/ HTTP/1.1" 404 3874
WARNING 2023-01-04 00:55:20,106 log 224 Not Found: /info/
WARNING 2023-01-04 00:55:20,108 basehttp 161 "GET /info/ HTTP/1.1" 404 3850
WARNING 2023-01-04 00:55:20,111 log 224 Not Found: /browse_histories/
WARNING 2023-01-04 00:55:20,112 basehttp 161 "GET /browse_histories/ HTTP/1.1" 404 3886
INFO 2023-01-04 00:56:52,620 autoreload 251 D:\project\python\美多商城\web_app\meiduo_mall\apps\users\urls.py changed, reloading.
INFO 2023-01-04 00:56:53,394 autoreload 637 Watching for file changes with StatReloader
INFO 2023-01-04 00:57:14,281 basehttp 161 "POST /login/ HTTP/1.1" 200 27
WARNING 2023-01-04 00:57:14,458 log 224 Not Found: /carts/simple/
WARNING 2023-01-04 00:57:14,458 basehttp 161 "GET /carts/simple/ HTTP/1.1" 404 3872
WARNING 2023-01-04 00:57:18,523 log 224 Not Found: /browse_histories/
WARNING 2023-01-04 00:57:18,524 basehttp 161 "GET /browse_histories/ HTTP/1.1" 404 3884
INFO 2023-01-04 00:57:18,526 basehttp 161 "GET /info/ HTTP/1.1" 200 124
INFO 2023-01-04 01:01:29,467 autoreload 251 D:\project\python\美多商城\web_app\meiduo_mall\apps\users\urls.py changed, reloading.
INFO 2023-01-04 01:01:30,367 autoreload 637 Watching for file changes with StatReloader
INFO 2023-01-04 01:11:35,527 autoreload 251 D:\project\python\美多商城\web_app\meiduo_mall\apps\users\urls.py changed, reloading.
INFO 2023-01-04 01:11:36,366 autoreload 637 Watching for file changes with StatReloader
INFO 2023-01-04 01:11:45,424 basehttp 161 "OPTIONS /emails/ HTTP/1.1" 200 0
ERROR 2023-01-04 01:11:45,491 log 224 Internal Server Error: /emails/
Traceback (most recent call last):
  File "C:\Users\alice\AppData\Local\Programs\Python\Python38\lib\site-packages\django\core\handlers\exception.py", line 47, in inner
    response = get_response(request)
  File "C:\Users\alice\AppData\Local\Programs\Python\Python38\lib\site-packages\django\core\handlers\base.py", line 181, in _get_response
    response = wrapped_callback(request, *callback_args, **callback_kwargs)
  File "C:\Users\alice\AppData\Local\Programs\Python\Python38\lib\site-packages\django\views\generic\base.py", line 70, in view
    return self.dispatch(request, *args, **kwargs)
  File "C:\Users\alice\AppData\Local\Programs\Python\Python38\lib\site-packages\django\contrib\auth\mixins.py", line 71, in dispatch
    return super().dispatch(request, *args, **kwargs)
  File "C:\Users\alice\AppData\Local\Programs\Python\Python38\lib\site-packages\django\views\generic\base.py", line 98, in dispatch
    return handler(request, *args, **kwargs)
  File "D:\project\python\美多商城\web_app\meiduo_mall\apps\users\views.py", line 187, in put
    from apps.users.utils import generic_email_verify_token
ModuleNotFoundError: No module named 'apps.users.utils'
ERROR 2023-01-04 01:11:45,494 basehttp 161 "PUT /emails/ HTTP/1.1" 500 96613
INFO 2023-01-04 01:13:34,760 autoreload 637 Watching for file changes with StatReloader
WARNING 2023-01-04 01:13:49,785 log 224 Not Found: /browse_histories/
WARNING 2023-01-04 01:13:49,786 basehttp 161 "GET /browse_histories/ HTTP/1.1" 404 4038
INFO 2023-01-04 01:13:49,795 basehttp 161 "GET /info/ HTTP/1.1" 200 137
WARNING 2023-01-04 01:13:52,384 log 224 Not Found: /carts/simple/
WARNING 2023-01-04 01:13:52,385 basehttp 161 "GET /carts/simple/ HTTP/1.1" 404 4026
INFO 2023-01-04 01:14:17,024 basehttp 161 "OPTIONS /emails/ HTTP/1.1" 200 0
INFO 2023-01-04 01:14:17,568 basehttp 161 "PUT /emails/ HTTP/1.1" 200 27
INFO 2023-01-04 09:33:49,698 autoreload 251 D:\project\python\美多商城\web_app\meiduo_mall\meiduo_mall\settings.py changed, reloading.
INFO 2023-01-04 09:33:50,558 autoreload 637 Watching for file changes with StatReloader
INFO 2023-01-04 09:34:59,500 autoreload 251 D:\project\python\美多商城\web_app\meiduo_mall\meiduo_mall\settings.py changed, reloading.
INFO 2023-01-04 09:35:00,313 autoreload 637 Watching for file changes with StatReloader
INFO 2023-01-04 09:45:22,669 autoreload 251 D:\project\python\美多商城\web_app\meiduo_mall\apps\users\views.py changed, reloading.
INFO 2023-01-04 09:45:23,504 autoreload 637 Watching for file changes with StatReloader
INFO 2023-01-04 16:11:51,368 basehttp 161 "GET /image_codes/54dd01d9-06c0-45a5-8a15-6882e34f9234/ HTTP/1.1" 200 3242
INFO 2023-01-04 16:11:57,201 basehttp 161 "GET /usernames/alice/count/ HTTP/1.1" 200 39
INFO 2023-01-04 16:12:12,243 basehttp 161 "GET /mobiles/15360606636/count/ HTTP/1.1" 200 39
INFO 2023-01-04 16:12:18,914 basehttp 161 "GET /mobiles/15360606636/count/ HTTP/1.1" 200 39
INFO 2023-01-04 16:12:19,171 basehttp 161 "GET /sms_codes/15360606636/?image_code=pddy&image_code_id=54dd01d9-06c0-45a5-8a15-6882e34f9234 HTTP/1.1" 200 27
INFO 2023-01-04 16:12:30,645 basehttp 161 "OPTIONS /register/ HTTP/1.1" 200 0
INFO 2023-01-04 16:12:30,645 basehttp 161 "GET /usernames/alice/count/ HTTP/1.1" 200 39
INFO 2023-01-04 16:12:30,650 basehttp 161 "GET /mobiles/15360606636/count/ HTTP/1.1" 200 39
ERROR 2023-01-04 16:12:30,817 log 224 Internal Server Error: /register/
Traceback (most recent call last):
  File "C:\Users\alice\AppData\Local\Programs\Python\Python38\lib\site-packages\django\core\handlers\exception.py", line 47, in inner
    response = get_response(request)
  File "C:\Users\alice\AppData\Local\Programs\Python\Python38\lib\site-packages\django\core\handlers\base.py", line 181, in _get_response
    response = wrapped_callback(request, *callback_args, **callback_kwargs)
  File "C:\Users\alice\AppData\Local\Programs\Python\Python38\lib\site-packages\django\views\generic\base.py", line 70, in view
    return self.dispatch(request, *args, **kwargs)
  File "C:\Users\alice\AppData\Local\Programs\Python\Python38\lib\site-packages\django\views\generic\base.py", line 98, in dispatch
    return handler(request, *args, **kwargs)
  File "D:\project\python\美多商城\web_app\meiduo_mall\apps\users\views.py", line 57, in post
    login(request.user)
TypeError: login() missing 1 required positional argument: 'user'
ERROR 2023-01-04 16:12:30,820 basehttp 161 "POST /register/ HTTP/1.1" 500 92572
INFO 2023-01-04 16:12:33,952 basehttp 161 "GET /usernames/alice/count/ HTTP/1.1" 200 39
INFO 2023-01-04 16:12:33,952 basehttp 161 "GET /mobiles/15360606636/count/ HTTP/1.1" 200 39
ERROR 2023-01-04 16:12:34,114 log 224 Internal Server Error: /register/
Traceback (most recent call last):
  File "C:\Users\alice\AppData\Local\Programs\Python\Python38\lib\site-packages\django\db\backends\utils.py", line 84, in _execute
    return self.cursor.execute(sql, params)
  File "C:\Users\alice\AppData\Local\Programs\Python\Python38\lib\site-packages\django\db\backends\mysql\base.py", line 73, in execute
    return self.cursor.execute(query, args)
  File "C:\Users\alice\AppData\Local\Programs\Python\Python38\lib\site-packages\MySQLdb\cursors.py", line 206, in execute
    res = self._query(query)
  File "C:\Users\alice\AppData\Local\Programs\Python\Python38\lib\site-packages\MySQLdb\cursors.py", line 319, in _query
    db.query(q)
  File "C:\Users\alice\AppData\Local\Programs\Python\Python38\lib\site-packages\MySQLdb\connections.py", line 254, in query
    _mysql.connection.query(self, query)
MySQLdb.IntegrityError: (1062, "Duplicate entry 'alice' for key 'username'")

The above exception was the direct cause of the following exception:

Traceback (most recent call last):
  File "C:\Users\alice\AppData\Local\Programs\Python\Python38\lib\site-packages\django\core\handlers\exception.py", line 47, in inner
    response = get_response(request)
  File "C:\Users\alice\AppData\Local\Programs\Python\Python38\lib\site-packages\django\core\handlers\base.py", line 181, in _get_response
    response = wrapped_callback(request, *callback_args, **callback_kwargs)
  File "C:\Users\alice\AppData\Local\Programs\Python\Python38\lib\site-packages\django\views\generic\base.py", line 70, in view
    return self.dispatch(request, *args, **kwargs)
  File "C:\Users\alice\AppData\Local\Programs\Python\Python38\lib\site-packages\django\views\generic\base.py", line 98, in dispatch
    return handler(request, *args, **kwargs)
  File "D:\project\python\美多商城\web_app\meiduo_mall\apps\users\views.py", line 52, in post
    User.objects.create_user(username=username,password=password,mobile=mobile)
  File "C:\Users\alice\AppData\Local\Programs\Python\Python38\lib\site-packages\django\contrib\auth\models.py", line 152, in create_user
    return self._create_user(username, email, password, **extra_fields)
  File "C:\Users\alice\AppData\Local\Programs\Python\Python38\lib\site-packages\django\contrib\auth\models.py", line 146, in _create_user
    user.save(using=self._db)
  File "C:\Users\alice\AppData\Local\Programs\Python\Python38\lib\site-packages\django\contrib\auth\base_user.py", line 67, in save
    super().save(*args, **kwargs)
  File "C:\Users\alice\AppData\Local\Programs\Python\Python38\lib\site-packages\django\db\models\base.py", line 739, in save
    self.save_base(using=using, force_insert=force_insert,
  File "C:\Users\alice\AppData\Local\Programs\Python\Python38\lib\site-packages\django\db\models\base.py", line 776, in save_base
    updated = self._save_table(
  File "C:\Users\alice\AppData\Local\Programs\Python\Python38\lib\site-packages\django\db\models\base.py", line 881, in _save_table
    results = self._do_insert(cls._base_manager, using, fields, returning_fields, raw)
  File "C:\Users\alice\AppData\Local\Programs\Python\Python38\lib\site-packages\django\db\models\base.py", line 919, in _do_insert
    return manager._insert(
  File "C:\Users\alice\AppData\Local\Programs\Python\Python38\lib\site-packages\django\db\models\manager.py", line 85, in manager_method
    return getattr(self.get_queryset(), name)(*args, **kwargs)
  File "C:\Users\alice\AppData\Local\Programs\Python\Python38\lib\site-packages\django\db\models\query.py", line 1270, in _insert
    return query.get_compiler(using=using).execute_sql(returning_fields)
  File "C:\Users\alice\AppData\Local\Programs\Python\Python38\lib\site-packages\django\db\models\sql\compiler.py", line 1416, in execute_sql
    cursor.execute(sql, params)
  File "C:\Users\alice\AppData\Local\Programs\Python\Python38\lib\site-packages\django\db\backends\utils.py", line 98, in execute
    return super().execute(sql, params)
  File "C:\Users\alice\AppData\Local\Programs\Python\Python38\lib\site-packages\django\db\backends\utils.py", line 66, in execute
    return self._execute_with_wrappers(sql, params, many=False, executor=self._execute)
  File "C:\Users\alice\AppData\Local\Programs\Python\Python38\lib\site-packages\django\db\backends\utils.py", line 75, in _execute_with_wrappers
    return executor(sql, params, many, context)
  File "C:\Users\alice\AppData\Local\Programs\Python\Python38\lib\site-packages\django\db\backends\utils.py", line 84, in _execute
    return self.cursor.execute(sql, params)
  File "C:\Users\alice\AppData\Local\Programs\Python\Python38\lib\site-packages\django\db\utils.py", line 90, in __exit__
    raise dj_exc_value.with_traceback(traceback) from exc_value
  File "C:\Users\alice\AppData\Local\Programs\Python\Python38\lib\site-packages\django\db\backends\utils.py", line 84, in _execute
    return self.cursor.execute(sql, params)
  File "C:\Users\alice\AppData\Local\Programs\Python\Python38\lib\site-packages\django\db\backends\mysql\base.py", line 73, in execute
    return self.cursor.execute(query, args)
  File "C:\Users\alice\AppData\Local\Programs\Python\Python38\lib\site-packages\MySQLdb\cursors.py", line 206, in execute
    res = self._query(query)
  File "C:\Users\alice\AppData\Local\Programs\Python\Python38\lib\site-packages\MySQLdb\cursors.py", line 319, in _query
    db.query(q)
  File "C:\Users\alice\AppData\Local\Programs\Python\Python38\lib\site-packages\MySQLdb\connections.py", line 254, in query
    _mysql.connection.query(self, query)
django.db.utils.IntegrityError: (1062, "Duplicate entry 'alice' for key 'username'")
ERROR 2023-01-04 16:12:34,120 basehttp 161 "POST /register/ HTTP/1.1" 500 219151
INFO 2023-01-04 16:13:40,060 basehttp 161 "OPTIONS /login/ HTTP/1.1" 200 0
INFO 2023-01-04 16:13:40,137 basehttp 161 "POST /login/ HTTP/1.1" 200 27
WARNING 2023-01-04 16:13:40,543 log 224 Not Found: /carts/simple/
WARNING 2023-01-04 16:13:40,544 basehttp 161 "GET /carts/simple/ HTTP/1.1" 404 4026
WARNING 2023-01-04 16:13:50,136 log 224 Not Found: /browse_histories/
INFO 2023-01-04 16:13:50,138 basehttp 161 "GET /info/ HTTP/1.1" 200 124
WARNING 2023-01-04 16:13:50,138 basehttp 161 "GET /browse_histories/ HTTP/1.1" 404 4038
INFO 2023-01-04 16:14:07,441 basehttp 161 "OPTIONS /emails/ HTTP/1.1" 200 0
INFO 2023-01-04 16:14:07,458 basehttp 161 "PUT /emails/ HTTP/1.1" 200 27
INFO 2023-01-04 16:18:11,576 autoreload 251 D:\project\python\美多商城\web_app\meiduo_mall\apps\users\views.py changed, reloading.
INFO 2023-01-04 16:18:12,449 autoreload 637 Watching for file changes with StatReloader
INFO 2023-01-04 16:19:40,329 autoreload 251 D:\project\python\美多商城\web_app\meiduo_mall\apps\users\views.py changed, reloading.
INFO 2023-01-04 16:19:41,055 autoreload 637 Watching for file changes with StatReloader
INFO 2023-01-04 16:19:52,832 basehttp 161 "GET /info/ HTTP/1.1" 200 143
ERROR 2023-01-04 16:19:52,871 log 224 Internal Server Error: /browse_histories/
Traceback (most recent call last):
  File "C:\Users\alice\AppData\Local\Programs\Python\Python38\lib\site-packages\django\core\handlers\exception.py", line 47, in inner
    response = get_response(request)
  File "C:\Users\alice\AppData\Local\Programs\Python\Python38\lib\site-packages\django\core\handlers\base.py", line 181, in _get_response
    response = wrapped_callback(request, *callback_args, **callback_kwargs)
  File "C:\Users\alice\AppData\Local\Programs\Python\Python38\lib\site-packages\django\views\generic\base.py", line 70, in view
    return self.dispatch(request, *args, **kwargs)
  File "C:\Users\alice\AppData\Local\Programs\Python\Python38\lib\site-packages\django\contrib\auth\mixins.py", line 71, in dispatch
    return super().dispatch(request, *args, **kwargs)
  File "C:\Users\alice\AppData\Local\Programs\Python\Python38\lib\site-packages\django\views\generic\base.py", line 98, in dispatch
    return handler(request, *args, **kwargs)
  File "D:\project\python\美多商城\web_app\meiduo_mall\apps\users\views.py", line 476, in get
    redis_cli = get_redis_connection('history')
NameError: name 'get_redis_connection' is not defined
ERROR 2023-01-04 16:19:52,873 basehttp 161 "GET /browse_histories/ HTTP/1.1" 500 94974
INFO 2023-01-04 16:19:55,340 basehttp 161 "PUT /emails/ HTTP/1.1" 200 27
INFO 2023-01-04 16:31:05,981 basehttp 161 "GET /info/ HTTP/1.1" 200 143
ERROR 2023-01-04 16:31:06,002 log 224 Internal Server Error: /browse_histories/
Traceback (most recent call last):
  File "C:\Users\alice\AppData\Local\Programs\Python\Python38\lib\site-packages\django\core\handlers\exception.py", line 47, in inner
    response = get_response(request)
  File "C:\Users\alice\AppData\Local\Programs\Python\Python38\lib\site-packages\django\core\handlers\base.py", line 181, in _get_response
    response = wrapped_callback(request, *callback_args, **callback_kwargs)
  File "C:\Users\alice\AppData\Local\Programs\Python\Python38\lib\site-packages\django\views\generic\base.py", line 70, in view
    return self.dispatch(request, *args, **kwargs)
  File "C:\Users\alice\AppData\Local\Programs\Python\Python38\lib\site-packages\django\contrib\auth\mixins.py", line 71, in dispatch
    return super().dispatch(request, *args, **kwargs)
  File "C:\Users\alice\AppData\Local\Programs\Python\Python38\lib\site-packages\django\views\generic\base.py", line 98, in dispatch
    return handler(request, *args, **kwargs)
  File "D:\project\python\美多商城\web_app\meiduo_mall\apps\users\views.py", line 476, in get
    redis_cli = get_redis_connection('history')
NameError: name 'get_redis_connection' is not defined
ERROR 2023-01-04 16:31:06,004 basehttp 161 "GET /browse_histories/ HTTP/1.1" 500 95044
INFO 2023-01-04 16:31:44,067 basehttp 161 "PUT /emails/ HTTP/1.1" 200 27
INFO 2023-01-04 16:51:23,629 autoreload 251 D:\project\python\美多商城\web_app\meiduo_mall\apps\users\views.py changed, reloading.
INFO 2023-01-04 16:51:24,507 autoreload 637 Watching for file changes with StatReloader
INFO 2023-01-04 16:51:32,225 basehttp 161 "GET /info/ HTTP/1.1" 200 143
ERROR 2023-01-04 16:51:32,245 log 224 Internal Server Error: /browse_histories/
Traceback (most recent call last):
  File "C:\Users\alice\AppData\Local\Programs\Python\Python38\lib\site-packages\django\core\handlers\exception.py", line 47, in inner
    response = get_response(request)
  File "C:\Users\alice\AppData\Local\Programs\Python\Python38\lib\site-packages\django\core\handlers\base.py", line 181, in _get_response
    response = wrapped_callback(request, *callback_args, **callback_kwargs)
  File "C:\Users\alice\AppData\Local\Programs\Python\Python38\lib\site-packages\django\views\generic\base.py", line 70, in view
    return self.dispatch(request, *args, **kwargs)
  File "C:\Users\alice\AppData\Local\Programs\Python\Python38\lib\site-packages\django\contrib\auth\mixins.py", line 71, in dispatch
    return super().dispatch(request, *args, **kwargs)
  File "C:\Users\alice\AppData\Local\Programs\Python\Python38\lib\site-packages\django\views\generic\base.py", line 98, in dispatch
    return handler(request, *args, **kwargs)
  File "D:\project\python\美多商城\web_app\meiduo_mall\apps\users\views.py", line 476, in get
    redis_cli = get_redis_connection('history')
NameError: name 'get_redis_connection' is not defined
ERROR 2023-01-04 16:51:32,248 basehttp 161 "GET /browse_histories/ HTTP/1.1" 500 94974
INFO 2023-01-04 16:51:38,518 basehttp 161 "PUT /emails/ HTTP/1.1" 200 27
INFO 2023-01-04 17:01:45,639 autoreload 251 D:\project\python\美多商城\web_app\meiduo_mall\apps\users\views.py changed, reloading.
INFO 2023-01-04 17:01:46,413 autoreload 637 Watching for file changes with StatReloader
INFO 2023-01-04 17:01:57,843 autoreload 251 D:\project\python\美多商城\web_app\meiduo_mall\apps\users\views.py changed, reloading.
INFO 2023-01-04 17:01:58,590 autoreload 637 Watching for file changes with StatReloader
INFO 2023-01-04 17:49:06,446 basehttp 161 "GET /info/ HTTP/1.1" 200 143
ERROR 2023-01-04 17:49:06,490 log 224 Internal Server Error: /browse_histories/
Traceback (most recent call last):
  File "C:\Users\alice\AppData\Local\Programs\Python\Python38\lib\site-packages\django\utils\connection.py", line 58, in __getitem__
    return getattr(self._connections, alias)
  File "C:\Users\alice\AppData\Local\Programs\Python\Python38\lib\site-packages\asgiref\local.py", line 105, in __getattr__
    raise AttributeError(f"{self!r} object has no attribute {key!r}")
AttributeError: <asgiref.local.Local object at 0x000001D11C6A9580> object has no attribute 'history'

During handling of the above exception, another exception occurred:

Traceback (most recent call last):
  File "C:\Users\alice\AppData\Local\Programs\Python\Python38\lib\site-packages\django\core\handlers\exception.py", line 47, in inner
    response = get_response(request)
  File "C:\Users\alice\AppData\Local\Programs\Python\Python38\lib\site-packages\django\core\handlers\base.py", line 181, in _get_response
    response = wrapped_callback(request, *callback_args, **callback_kwargs)
  File "C:\Users\alice\AppData\Local\Programs\Python\Python38\lib\site-packages\django\views\generic\base.py", line 70, in view
    return self.dispatch(request, *args, **kwargs)
  File "C:\Users\alice\AppData\Local\Programs\Python\Python38\lib\site-packages\django\contrib\auth\mixins.py", line 71, in dispatch
    return super().dispatch(request, *args, **kwargs)
  File "C:\Users\alice\AppData\Local\Programs\Python\Python38\lib\site-packages\django\views\generic\base.py", line 98, in dispatch
    return handler(request, *args, **kwargs)
  File "D:\project\python\美多商城\web_app\meiduo_mall\apps\users\views.py", line 476, in get
    redis_cli = get_redis_connection('history')
  File "C:\Users\alice\AppData\Local\Programs\Python\Python38\lib\site-packages\django_redis\__init__.py", line 12, in get_redis_connection
    cache = caches[alias]
  File "C:\Users\alice\AppData\Local\Programs\Python\Python38\lib\site-packages\django\utils\connection.py", line 61, in __getitem__
    raise self.exception_class(f"The connection '{alias}' doesn't exist.")
django.core.cache.backends.base.InvalidCacheBackendError: The connection 'history' doesn't exist.
ERROR 2023-01-04 17:49:06,494 basehttp 161 "GET /browse_histories/ HTTP/1.1" 500 111770
INFO 2023-01-04 17:49:12,032 basehttp 161 "PUT /emails/ HTTP/1.1" 200 27
INFO 2023-01-04 17:50:06,440 autoreload 637 Watching for file changes with StatReloader
INFO 2023-01-04 17:50:14,616 basehttp 161 "GET /info/ HTTP/1.1" 200 143
ERROR 2023-01-04 17:50:14,645 log 224 Internal Server Error: /browse_histories/
Traceback (most recent call last):
  File "C:\Users\alice\AppData\Local\Programs\Python\Python38\lib\site-packages\django\utils\connection.py", line 58, in __getitem__
    return getattr(self._connections, alias)
  File "C:\Users\alice\AppData\Local\Programs\Python\Python38\lib\site-packages\asgiref\local.py", line 105, in __getattr__
    raise AttributeError(f"{self!r} object has no attribute {key!r}")
AttributeError: <asgiref.local.Local object at 0x00000201CA109580> object has no attribute 'history'

During handling of the above exception, another exception occurred:

Traceback (most recent call last):
  File "C:\Users\alice\AppData\Local\Programs\Python\Python38\lib\site-packages\django\core\handlers\exception.py", line 47, in inner
    response = get_response(request)
  File "C:\Users\alice\AppData\Local\Programs\Python\Python38\lib\site-packages\django\core\handlers\base.py", line 181, in _get_response
    response = wrapped_callback(request, *callback_args, **callback_kwargs)
  File "C:\Users\alice\AppData\Local\Programs\Python\Python38\lib\site-packages\django\views\generic\base.py", line 70, in view
    return self.dispatch(request, *args, **kwargs)
  File "C:\Users\alice\AppData\Local\Programs\Python\Python38\lib\site-packages\django\contrib\auth\mixins.py", line 71, in dispatch
    return super().dispatch(request, *args, **kwargs)
  File "C:\Users\alice\AppData\Local\Programs\Python\Python38\lib\site-packages\django\views\generic\base.py", line 98, in dispatch
    return handler(request, *args, **kwargs)
  File "D:\project\python\美多商城\web_app\meiduo_mall\apps\users\views.py", line 476, in get
    redis_cli = get_redis_connection('history')
  File "C:\Users\alice\AppData\Local\Programs\Python\Python38\lib\site-packages\django_redis\__init__.py", line 12, in get_redis_connection
    cache = caches[alias]
  File "C:\Users\alice\AppData\Local\Programs\Python\Python38\lib\site-packages\django\utils\connection.py", line 61, in __getitem__
    raise self.exception_class(f"The connection '{alias}' doesn't exist.")
django.core.cache.backends.base.InvalidCacheBackendError: The connection 'history' doesn't exist.
ERROR 2023-01-04 17:50:14,648 basehttp 161 "GET /browse_histories/ HTTP/1.1" 500 111770
INFO 2023-01-04 17:50:24,052 basehttp 161 "PUT /emails/ HTTP/1.1" 200 27
INFO 2023-01-04 18:02:08,736 autoreload 251 D:\project\python\美多商城\web_app\meiduo_mall\apps\users\views.py changed, reloading.
INFO 2023-01-04 18:02:09,563 autoreload 637 Watching for file changes with StatReloader
INFO 2023-01-04 18:02:16,471 basehttp 161 "GET /info/ HTTP/1.1" 200 143
ERROR 2023-01-04 18:02:16,568 log 224 Internal Server Error: /browse_histories/
Traceback (most recent call last):
  File "C:\Users\alice\AppData\Local\Programs\Python\Python38\lib\site-packages\django\utils\connection.py", line 58, in __getitem__
    return getattr(self._connections, alias)
  File "C:\Users\alice\AppData\Local\Programs\Python\Python38\lib\site-packages\asgiref\local.py", line 105, in __getattr__
    raise AttributeError(f"{self!r} object has no attribute {key!r}")
AttributeError: <asgiref.local.Local object at 0x000001C7B9C09580> object has no attribute 'history'

During handling of the above exception, another exception occurred:

Traceback (most recent call last):
  File "C:\Users\alice\AppData\Local\Programs\Python\Python38\lib\site-packages\django\core\handlers\exception.py", line 47, in inner
    response = get_response(request)
  File "C:\Users\alice\AppData\Local\Programs\Python\Python38\lib\site-packages\django\core\handlers\base.py", line 181, in _get_response
    response = wrapped_callback(request, *callback_args, **callback_kwargs)
  File "C:\Users\alice\AppData\Local\Programs\Python\Python38\lib\site-packages\django\views\generic\base.py", line 70, in view
    return self.dispatch(request, *args, **kwargs)
  File "C:\Users\alice\AppData\Local\Programs\Python\Python38\lib\site-packages\django\contrib\auth\mixins.py", line 71, in dispatch
    return super().dispatch(request, *args, **kwargs)
  File "C:\Users\alice\AppData\Local\Programs\Python\Python38\lib\site-packages\django\views\generic\base.py", line 98, in dispatch
    return handler(request, *args, **kwargs)
  File "D:\project\python\美多商城\web_app\meiduo_mall\apps\users\views.py", line 477, in get
    redis_cli = get_redis_connection('history')
  File "C:\Users\alice\AppData\Local\Programs\Python\Python38\lib\site-packages\django_redis\__init__.py", line 12, in get_redis_connection
    cache = caches[alias]
  File "C:\Users\alice\AppData\Local\Programs\Python\Python38\lib\site-packages\django\utils\connection.py", line 61, in __getitem__
    raise self.exception_class(f"The connection '{alias}' doesn't exist.")
django.core.cache.backends.base.InvalidCacheBackendError: The connection 'history' doesn't exist.
ERROR 2023-01-04 18:02:16,571 basehttp 161 "GET /browse_histories/ HTTP/1.1" 500 111770
INFO 2023-01-04 18:02:18,104 basehttp 161 "PUT /emails/ HTTP/1.1" 200 27
INFO 2023-01-04 18:03:01,117 autoreload 251 D:\project\python\美多商城\web_app\meiduo_mall\apps\users\views.py changed, reloading.
INFO 2023-01-04 18:03:01,890 autoreload 637 Watching for file changes with StatReloader
INFO 2023-01-04 18:03:07,423 basehttp 161 "GET /info/ HTTP/1.1" 200 143
ERROR 2023-01-04 18:03:07,455 log 224 Internal Server Error: /browse_histories/
Traceback (most recent call last):
  File "C:\Users\alice\AppData\Local\Programs\Python\Python38\lib\site-packages\django\utils\connection.py", line 58, in __getitem__
    return getattr(self._connections, alias)
  File "C:\Users\alice\AppData\Local\Programs\Python\Python38\lib\site-packages\asgiref\local.py", line 105, in __getattr__
    raise AttributeError(f"{self!r} object has no attribute {key!r}")
AttributeError: <asgiref.local.Local object at 0x0000015A43F59580> object has no attribute 'history'

During handling of the above exception, another exception occurred:

Traceback (most recent call last):
  File "C:\Users\alice\AppData\Local\Programs\Python\Python38\lib\site-packages\django\core\handlers\exception.py", line 47, in inner
    response = get_response(request)
  File "C:\Users\alice\AppData\Local\Programs\Python\Python38\lib\site-packages\django\core\handlers\base.py", line 181, in _get_response
    response = wrapped_callback(request, *callback_args, **callback_kwargs)
  File "C:\Users\alice\AppData\Local\Programs\Python\Python38\lib\site-packages\django\views\generic\base.py", line 70, in view
    return self.dispatch(request, *args, **kwargs)
  File "C:\Users\alice\AppData\Local\Programs\Python\Python38\lib\site-packages\django\contrib\auth\mixins.py", line 71, in dispatch
    return super().dispatch(request, *args, **kwargs)
  File "C:\Users\alice\AppData\Local\Programs\Python\Python38\lib\site-packages\django\views\generic\base.py", line 98, in dispatch
    return handler(request, *args, **kwargs)
  File "D:\project\python\美多商城\web_app\meiduo_mall\apps\users\views.py", line 477, in get
    redis_cli = get_redis_connection('history')
  File "C:\Users\alice\AppData\Local\Programs\Python\Python38\lib\site-packages\django_redis\__init__.py", line 12, in get_redis_connection
    cache = caches[alias]
  File "C:\Users\alice\AppData\Local\Programs\Python\Python38\lib\site-packages\django\utils\connection.py", line 61, in __getitem__
    raise self.exception_class(f"The connection '{alias}' doesn't exist.")
django.core.cache.backends.base.InvalidCacheBackendError: The connection 'history' doesn't exist.
ERROR 2023-01-04 18:03:07,458 basehttp 161 "GET /browse_histories/ HTTP/1.1" 500 111770
INFO 2023-01-04 18:03:10,078 basehttp 161 "PUT /emails/ HTTP/1.1" 200 27
INFO 2023-01-04 18:04:59,955 autoreload 251 D:\project\python\美多商城\web_app\meiduo_mall\celery_tasks\email\tasks.py changed, reloading.
INFO 2023-01-04 18:05:00,701 autoreload 637 Watching for file changes with StatReloader
INFO 2023-01-04 18:05:04,990 basehttp 161 "GET /info/ HTTP/1.1" 200 143
ERROR 2023-01-04 18:05:05,017 log 224 Internal Server Error: /browse_histories/
Traceback (most recent call last):
  File "C:\Users\alice\AppData\Local\Programs\Python\Python38\lib\site-packages\django\utils\connection.py", line 58, in __getitem__
    return getattr(self._connections, alias)
  File "C:\Users\alice\AppData\Local\Programs\Python\Python38\lib\site-packages\asgiref\local.py", line 105, in __getattr__
    raise AttributeError(f"{self!r} object has no attribute {key!r}")
AttributeError: <asgiref.local.Local object at 0x000001D9380D9580> object has no attribute 'history'

During handling of the above exception, another exception occurred:

Traceback (most recent call last):
  File "C:\Users\alice\AppData\Local\Programs\Python\Python38\lib\site-packages\django\core\handlers\exception.py", line 47, in inner
    response = get_response(request)
  File "C:\Users\alice\AppData\Local\Programs\Python\Python38\lib\site-packages\django\core\handlers\base.py", line 181, in _get_response
    response = wrapped_callback(request, *callback_args, **callback_kwargs)
  File "C:\Users\alice\AppData\Local\Programs\Python\Python38\lib\site-packages\django\views\generic\base.py", line 70, in view
    return self.dispatch(request, *args, **kwargs)
  File "C:\Users\alice\AppData\Local\Programs\Python\Python38\lib\site-packages\django\contrib\auth\mixins.py", line 71, in dispatch
    return super().dispatch(request, *args, **kwargs)
  File "C:\Users\alice\AppData\Local\Programs\Python\Python38\lib\site-packages\django\views\generic\base.py", line 98, in dispatch
    return handler(request, *args, **kwargs)
  File "D:\project\python\美多商城\web_app\meiduo_mall\apps\users\views.py", line 477, in get
    redis_cli = get_redis_connection('history')
  File "C:\Users\alice\AppData\Local\Programs\Python\Python38\lib\site-packages\django_redis\__init__.py", line 12, in get_redis_connection
    cache = caches[alias]
  File "C:\Users\alice\AppData\Local\Programs\Python\Python38\lib\site-packages\django\utils\connection.py", line 61, in __getitem__
    raise self.exception_class(f"The connection '{alias}' doesn't exist.")
django.core.cache.backends.base.InvalidCacheBackendError: The connection 'history' doesn't exist.
ERROR 2023-01-04 18:05:05,021 basehttp 161 "GET /browse_histories/ HTTP/1.1" 500 111770
INFO 2023-01-04 18:05:07,037 basehttp 161 "PUT /emails/ HTTP/1.1" 200 27
INFO 2023-01-04 18:05:41,823 autoreload 251 D:\project\python\美多商城\web_app\meiduo_mall\celery_tasks\email\tasks.py changed, reloading.
INFO 2023-01-04 18:05:42,527 autoreload 637 Watching for file changes with StatReloader
INFO 2023-01-04 18:05:47,958 basehttp 161 "GET /info/ HTTP/1.1" 200 143
ERROR 2023-01-04 18:05:47,995 log 224 Internal Server Error: /browse_histories/
Traceback (most recent call last):
  File "C:\Users\alice\AppData\Local\Programs\Python\Python38\lib\site-packages\django\utils\connection.py", line 58, in __getitem__
    return getattr(self._connections, alias)
  File "C:\Users\alice\AppData\Local\Programs\Python\Python38\lib\site-packages\asgiref\local.py", line 105, in __getattr__
    raise AttributeError(f"{self!r} object has no attribute {key!r}")
AttributeError: <asgiref.local.Local object at 0x0000026A3CB89580> object has no attribute 'history'

During handling of the above exception, another exception occurred:

Traceback (most recent call last):
  File "C:\Users\alice\AppData\Local\Programs\Python\Python38\lib\site-packages\django\core\handlers\exception.py", line 47, in inner
    response = get_response(request)
  File "C:\Users\alice\AppData\Local\Programs\Python\Python38\lib\site-packages\django\core\handlers\base.py", line 181, in _get_response
    response = wrapped_callback(request, *callback_args, **callback_kwargs)
  File "C:\Users\alice\AppData\Local\Programs\Python\Python38\lib\site-packages\django\views\generic\base.py", line 70, in view
    return self.dispatch(request, *args, **kwargs)
  File "C:\Users\alice\AppData\Local\Programs\Python\Python38\lib\site-packages\django\contrib\auth\mixins.py", line 71, in dispatch
    return super().dispatch(request, *args, **kwargs)
  File "C:\Users\alice\AppData\Local\Programs\Python\Python38\lib\site-packages\django\views\generic\base.py", line 98, in dispatch
    return handler(request, *args, **kwargs)
  File "D:\project\python\美多商城\web_app\meiduo_mall\apps\users\views.py", line 477, in get
    redis_cli = get_redis_connection('history')
  File "C:\Users\alice\AppData\Local\Programs\Python\Python38\lib\site-packages\django_redis\__init__.py", line 12, in get_redis_connection
    cache = caches[alias]
  File "C:\Users\alice\AppData\Local\Programs\Python\Python38\lib\site-packages\django\utils\connection.py", line 61, in __getitem__
    raise self.exception_class(f"The connection '{alias}' doesn't exist.")
django.core.cache.backends.base.InvalidCacheBackendError: The connection 'history' doesn't exist.
ERROR 2023-01-04 18:05:47,998 basehttp 161 "GET /browse_histories/ HTTP/1.1" 500 111770
INFO 2023-01-04 18:05:49,534 basehttp 161 "PUT /emails/ HTTP/1.1" 200 27
INFO 2023-01-04 18:08:23,318 autoreload 251 D:\project\python\美多商城\web_app\meiduo_mall\celery_tasks\email\tasks.py changed, reloading.
INFO 2023-01-04 18:08:24,237 autoreload 637 Watching for file changes with StatReloader
INFO 2023-01-04 18:37:54,205 basehttp 161 "GET /info/ HTTP/1.1" 200 143
ERROR 2023-01-04 18:37:54,237 log 224 Internal Server Error: /browse_histories/
Traceback (most recent call last):
  File "C:\Users\alice\AppData\Local\Programs\Python\Python38\lib\site-packages\django\utils\connection.py", line 58, in __getitem__
    return getattr(self._connections, alias)
  File "C:\Users\alice\AppData\Local\Programs\Python\Python38\lib\site-packages\asgiref\local.py", line 105, in __getattr__
    raise AttributeError(f"{self!r} object has no attribute {key!r}")
AttributeError: <asgiref.local.Local object at 0x000001C58F3C9580> object has no attribute 'history'

During handling of the above exception, another exception occurred:

Traceback (most recent call last):
  File "C:\Users\alice\AppData\Local\Programs\Python\Python38\lib\site-packages\django\core\handlers\exception.py", line 47, in inner
    response = get_response(request)
  File "C:\Users\alice\AppData\Local\Programs\Python\Python38\lib\site-packages\django\core\handlers\base.py", line 181, in _get_response
    response = wrapped_callback(request, *callback_args, **callback_kwargs)
  File "C:\Users\alice\AppData\Local\Programs\Python\Python38\lib\site-packages\django\views\generic\base.py", line 70, in view
    return self.dispatch(request, *args, **kwargs)
  File "C:\Users\alice\AppData\Local\Programs\Python\Python38\lib\site-packages\django\contrib\auth\mixins.py", line 71, in dispatch
    return super().dispatch(request, *args, **kwargs)
  File "C:\Users\alice\AppData\Local\Programs\Python\Python38\lib\site-packages\django\views\generic\base.py", line 98, in dispatch
    return handler(request, *args, **kwargs)
  File "D:\project\python\美多商城\web_app\meiduo_mall\apps\users\views.py", line 477, in get
    redis_cli = get_redis_connection('history')
  File "C:\Users\alice\AppData\Local\Programs\Python\Python38\lib\site-packages\django_redis\__init__.py", line 12, in get_redis_connection
    cache = caches[alias]
  File "C:\Users\alice\AppData\Local\Programs\Python\Python38\lib\site-packages\django\utils\connection.py", line 61, in __getitem__
    raise self.exception_class(f"The connection '{alias}' doesn't exist.")
django.core.cache.backends.base.InvalidCacheBackendError: The connection 'history' doesn't exist.
ERROR 2023-01-04 18:37:54,240 basehttp 161 "GET /browse_histories/ HTTP/1.1" 500 111770
INFO 2023-01-04 18:37:55,940 basehttp 161 "OPTIONS /emails/ HTTP/1.1" 200 0
INFO 2023-01-04 18:37:56,073 basehttp 161 "PUT /emails/ HTTP/1.1" 200 27
INFO 2023-01-04 18:42:41,477 autoreload 251 C:\Users\alice\AppData\Local\Programs\Python\Python38\Lib\site-packages\amqp\abstract_channel.py changed, reloading.
INFO 2023-01-04 18:42:42,309 autoreload 637 Watching for file changes with StatReloader
INFO 2023-01-04 18:45:08,961 basehttp 161 "GET /info/ HTTP/1.1" 200 143
ERROR 2023-01-04 18:45:08,990 log 224 Internal Server Error: /browse_histories/
Traceback (most recent call last):
  File "C:\Users\alice\AppData\Local\Programs\Python\Python38\lib\site-packages\django\utils\connection.py", line 58, in __getitem__
    return getattr(self._connections, alias)
  File "C:\Users\alice\AppData\Local\Programs\Python\Python38\lib\site-packages\asgiref\local.py", line 105, in __getattr__
    raise AttributeError(f"{self!r} object has no attribute {key!r}")
AttributeError: <asgiref.local.Local object at 0x0000020BCC459580> object has no attribute 'history'

During handling of the above exception, another exception occurred:

Traceback (most recent call last):
  File "C:\Users\alice\AppData\Local\Programs\Python\Python38\lib\site-packages\django\core\handlers\exception.py", line 47, in inner
    response = get_response(request)
  File "C:\Users\alice\AppData\Local\Programs\Python\Python38\lib\site-packages\django\core\handlers\base.py", line 181, in _get_response
    response = wrapped_callback(request, *callback_args, **callback_kwargs)
  File "C:\Users\alice\AppData\Local\Programs\Python\Python38\lib\site-packages\django\views\generic\base.py", line 70, in view
    return self.dispatch(request, *args, **kwargs)
  File "C:\Users\alice\AppData\Local\Programs\Python\Python38\lib\site-packages\django\contrib\auth\mixins.py", line 71, in dispatch
    return super().dispatch(request, *args, **kwargs)
  File "C:\Users\alice\AppData\Local\Programs\Python\Python38\lib\site-packages\django\views\generic\base.py", line 98, in dispatch
    return handler(request, *args, **kwargs)
  File "D:\project\python\美多商城\web_app\meiduo_mall\apps\users\views.py", line 477, in get
    redis_cli = get_redis_connection('history')
  File "C:\Users\alice\AppData\Local\Programs\Python\Python38\lib\site-packages\django_redis\__init__.py", line 12, in get_redis_connection
    cache = caches[alias]
  File "C:\Users\alice\AppData\Local\Programs\Python\Python38\lib\site-packages\django\utils\connection.py", line 61, in __getitem__
    raise self.exception_class(f"The connection '{alias}' doesn't exist.")
django.core.cache.backends.base.InvalidCacheBackendError: The connection 'history' doesn't exist.
ERROR 2023-01-04 18:45:08,992 basehttp 161 "GET /browse_histories/ HTTP/1.1" 500 111770
INFO 2023-01-04 18:45:10,789 basehttp 161 "PUT /emails/ HTTP/1.1" 200 27
INFO 2023-01-04 18:48:21,746 autoreload 251 D:\project\python\美多商城\web_app\meiduo_mall\meiduo_mall\settings.py changed, reloading.
INFO 2023-01-04 18:48:22,478 autoreload 637 Watching for file changes with StatReloader
INFO 2023-01-04 18:48:56,270 basehttp 161 "GET /info/ HTTP/1.1" 200 143
INFO 2023-01-04 18:48:56,272 basehttp 161 "GET /browse_histories/ HTTP/1.1" 200 39
INFO 2023-01-04 18:48:59,833 basehttp 161 "PUT /emails/ HTTP/1.1" 200 27
INFO 2023-01-04 19:27:06,356 autoreload 251 D:\project\python\美多商城\web_app\meiduo_mall\apps\users\views.py changed, reloading.
INFO 2023-01-04 19:27:07,162 autoreload 637 Watching for file changes with StatReloader
INFO 2023-01-04 19:30:15,927 autoreload 251 D:\project\python\美多商城\web_app\meiduo_mall\apps\users\views.py changed, reloading.
INFO 2023-01-04 19:30:16,691 autoreload 637 Watching for file changes with StatReloader
INFO 2023-01-04 19:30:52,354 autoreload 251 D:\project\python\美多商城\web_app\meiduo_mall\apps\users\views.py changed, reloading.
INFO 2023-01-04 19:30:53,155 autoreload 637 Watching for file changes with StatReloader
INFO 2023-01-04 19:31:01,547 basehttp 161 "GET /info/ HTTP/1.1" 200 143
INFO 2023-01-04 19:31:01,548 basehttp 161 "GET /browse_histories/ HTTP/1.1" 200 39
INFO 2023-01-04 19:31:03,390 basehttp 161 "PUT /emails/ HTTP/1.1" 200 27
INFO 2023-01-04 19:31:21,766 autoreload 251 D:\project\python\美多商城\web_app\meiduo_mall\celery_tasks\p.py changed, reloading.
INFO 2023-01-04 19:31:22,568 autoreload 637 Watching for file changes with StatReloader
INFO 2023-01-04 19:31:31,210 basehttp 161 "GET /info/ HTTP/1.1" 200 143
INFO 2023-01-04 19:31:31,211 basehttp 161 "GET /browse_histories/ HTTP/1.1" 200 39
INFO 2023-01-04 19:31:33,330 basehttp 161 "PUT /emails/ HTTP/1.1" 200 27
INFO 2023-01-04 19:38:22,951 autoreload 251 D:\project\python\美多商城\web_app\meiduo_mall\apps\users\views.py changed, reloading.
INFO 2023-01-04 19:38:23,911 autoreload 637 Watching for file changes with StatReloader
INFO 2023-01-04 19:53:00,151 basehttp 161 "GET /info/ HTTP/1.1" 200 143
INFO 2023-01-04 19:53:00,152 basehttp 161 "GET /browse_histories/ HTTP/1.1" 200 39
INFO 2023-01-04 19:53:01,954 basehttp 161 "PUT /emails/ HTTP/1.1" 200 27
INFO 2023-01-04 19:53:31,666 basehttp 161 "OPTIONS /emails/verification/?token=eyJhbGciOiJIUzUxMiIsImlhdCI6MTY3MjgzMzE4MSwiZXhwIjoxNjcyOTE5NTgxfQ.eyJ1c2VyX2lkIjoxNX0.9k5LfmGWYpeJ278xLNFqCP87ttANay8vWDhTmatKyZJn5BxmZfJKqxti8ZrUJPdlHIv3VJhyrIJpkqStw4ERqA HTTP/1.1" 200 0
INFO 2023-01-04 19:53:31,672 basehttp 161 "PUT /emails/verification/?token=eyJhbGciOiJIUzUxMiIsImlhdCI6MTY3MjgzMzE4MSwiZXhwIjoxNjcyOTE5NTgxfQ.eyJ1c2VyX2lkIjoxNX0.9k5LfmGWYpeJ278xLNFqCP87ttANay8vWDhTmatKyZJn5BxmZfJKqxti8ZrUJPdlHIv3VJhyrIJpkqStw4ERqA HTTP/1.1" 200 27
INFO 2023-01-04 19:54:49,612 basehttp 161 "GET /image_codes/00c05941-b313-4c5a-a69e-839e6704ed33/ HTTP/1.1" 200 3067
INFO 2023-01-04 19:55:24,119 basehttp 161 "GET /usernames/alice/count/ HTTP/1.1" 200 39
INFO 2023-01-04 19:55:42,632 basehttp 161 "GET /mobiles/15360606636/count/ HTTP/1.1" 200 39
INFO 2023-01-04 19:55:50,334 basehttp 161 "GET /mobiles/15360606636/count/ HTTP/1.1" 200 39
INFO 2023-01-04 19:55:50,354 basehttp 161 "GET /sms_codes/15360606636/?image_code=ZBIW&image_code_id=00c05941-b313-4c5a-a69e-839e6704ed33 HTTP/1.1" 200 27
INFO 2023-01-04 19:57:04,156 basehttp 161 "OPTIONS /register/ HTTP/1.1" 200 0
INFO 2023-01-04 19:57:04,157 basehttp 161 "GET /usernames/alice/count/ HTTP/1.1" 200 39
INFO 2023-01-04 19:57:04,158 basehttp 161 "GET /mobiles/15360606636/count/ HTTP/1.1" 200 39
ERROR 2023-01-04 19:57:04,254 log 224 Internal Server Error: /register/
Traceback (most recent call last):
  File "C:\Users\alice\AppData\Local\Programs\Python\Python38\lib\site-packages\django\core\handlers\exception.py", line 47, in inner
    response = get_response(request)
  File "C:\Users\alice\AppData\Local\Programs\Python\Python38\lib\site-packages\django\core\handlers\base.py", line 181, in _get_response
    response = wrapped_callback(request, *callback_args, **callback_kwargs)
  File "C:\Users\alice\AppData\Local\Programs\Python\Python38\lib\site-packages\django\views\generic\base.py", line 70, in view
    return self.dispatch(request, *args, **kwargs)
  File "C:\Users\alice\AppData\Local\Programs\Python\Python38\lib\site-packages\django\views\generic\base.py", line 98, in dispatch
    return handler(request, *args, **kwargs)
  File "D:\project\python\美多商城\web_app\meiduo_mall\apps\users\views.py", line 57, in post
    login(request.user)
TypeError: login() missing 1 required positional argument: 'user'
ERROR 2023-01-04 19:57:04,256 basehttp 161 "POST /register/ HTTP/1.1" 500 93106
INFO 2023-01-04 19:58:54,814 autoreload 251 D:\project\python\美多商城\web_app\meiduo_mall\apps\users\views.py changed, reloading.
INFO 2023-01-04 19:58:55,657 autoreload 637 Watching for file changes with StatReloader
INFO 2023-01-04 19:59:12,342 basehttp 161 "GET /usernames/alice/count/ HTTP/1.1" 200 39
INFO 2023-01-04 19:59:12,342 basehttp 161 "GET /mobiles/15360606636/count/ HTTP/1.1" 200 39
ERROR 2023-01-04 19:59:12,440 log 224 Internal Server Error: /register/
Traceback (most recent call last):
  File "C:\Users\alice\AppData\Local\Programs\Python\Python38\lib\site-packages\django\core\handlers\exception.py", line 47, in inner
    response = get_response(request)
  File "C:\Users\alice\AppData\Local\Programs\Python\Python38\lib\site-packages\django\core\handlers\base.py", line 181, in _get_response
    response = wrapped_callback(request, *callback_args, **callback_kwargs)
  File "C:\Users\alice\AppData\Local\Programs\Python\Python38\lib\site-packages\django\views\generic\base.py", line 70, in view
    return self.dispatch(request, *args, **kwargs)
  File "C:\Users\alice\AppData\Local\Programs\Python\Python38\lib\site-packages\django\views\generic\base.py", line 98, in dispatch
    return handler(request, *args, **kwargs)
  File "D:\project\python\美多商城\web_app\meiduo_mall\apps\users\views.py", line 57, in post
    login(request,user)
NameError: name 'user' is not defined
ERROR 2023-01-04 19:59:12,442 basehttp 161 "POST /register/ HTTP/1.1" 500 92924
INFO 2023-01-04 20:00:45,822 autoreload 251 D:\project\python\美多商城\web_app\meiduo_mall\apps\users\views.py changed, reloading.
INFO 2023-01-04 20:00:46,615 autoreload 637 Watching for file changes with StatReloader
